Workbook
Name CUMPLIO: #REF!
Name CUMPLIO: #REF!
Name CUMPLIO: #REF!
Name CUMPLIO: #REF!
Name CUMPLIO: #REF!
Name CUMPLIO: #REF!
Name CUMPLIO: #REF!
Name EQUIPO: #REF!
Name EQUIPO: #REF!
Name EQUIPO: #REF!
Name EQUIPO: #REF!
Name EQUIPO: #REF!
Name EQUIPO: #REF!
Name EQUIPO: #REF!
Name EQUIPOS: #REF!
Name EQUIPOS: #REF!
Name EQUIPOS: #REF!
Name EQUIPOS: #REF!
Name EQUIPOS: #REF!
Name EQUIPOS: #REF!
Name EQUIPOS: #REF!
Name LISTA: #REF!
Name LISTA: #REF!
Name LISTA: #REF!
Name LISTA: #REF!
Name LISTA: #REF!
Name LISTA: #REF!
Name LISTA: #REF!
Name MANTENIMIENTO: #REF!
Name MANTENIMIENTO: #REF!
Name MANTENIMIENTO: #REF!
Name MANTENIMIENTO: #REF!
Name MANTENIMIENTO: #REF!
Name MANTENIMIENTO: #REF!
Name MANTENIMIENTO: #REF!
Name NUMERACION: #REF!
Name NUMERACION: #REF!
Name NUMERACION: #REF!
Name NUMERACION: #REF!
Name NUMERACION: #REF!
Name NUMERACION: #REF!
Name NUMERACION: #REF!
Name SINO: #REF!
Name SINO: #REF!
Name SINO: #REF!
Name SINO: #REF!
Name SINO: #REF!
Name SINO: #REF!
Name SINO: #REF!
Name SUCURSALES: MAESTRO!$A$1:$A$21
Name TIENDAS: #REF!
Name TIENDAS: #REF!
Name TIENDAS: #REF!
Name TIENDAS: #REF!
Name TIENDAS: #REF!
Name TIENDAS: #REF!
Name TIENDAS: #REF!

Sheet CON
C1: CHECK LIST DE EXISTENCIA DE EQUIPOS EN TIENDAS | I1: Código: | J1: FO-MIS-03
I2: Revisión: | J2: 07 | K2: 42720
I3: Fecha: | J3: 42286
B5: SUCURSAL: | C5: INVERSIONES CAÑANDONGA,C.A (T. CONEJERO) | H5: FECHA: | I5: 46157
A7: EQUIPOS
A8: Nº | B8: EQUIPOS | D8: INVENTARIO IDEAL | E8: INVENTARIO REAL | F8: EQUIPOS OPERATIVOS | G8: EFECTIVIDAD | H8: OBSERVACIONES
A9: 1 | B9: CPU | D9: 4 | E9: 4 | F9: 4 | G9: =IF(D9="","",IF(D9=0,"-",IF(F9>D9,"ERROR",IF(E9>D9,"ERROR",IF(E9<D9,0,IF(E9>F9,0,IF(F9=D9,1,0))))))) -> 1
A10: 2 | B10: MOUSE | D10: 4 | E10: 4 | F10: 4 | G10: =IF(D10="","",IF(D10=0,"-",IF(F10>D10,"ERROR",IF(E10>D10,"ERROR",IF(E10<D10,0,IF(E10>F10,0,IF(F10=D10,1,0))))))) -> 1
A11: 3 | B11: TECLADOS | D11: 4 | E11: 4 | F11: 4 | G11: =IF(D11="","",IF(D11=0,"-",IF(F11>D11,"ERROR",IF(E11>D11,"ERROR",IF(E11<D11,0,IF(E11>F11,0,IF(F11=D11,1,0))))))) -> 1
A12: 4 | B12: MONITORES | D12: 4 | E12: 4 | F12: 4 | G12: =IF(D12="","",IF(D12=0,"-",IF(F12>D12,"ERROR",IF(E12>D12,"ERROR",IF(E12<D12,0,IF(E12>F12,0,IF(F12=D12,1,0))))))) -> 1
A13: 5 | B13: REGULADORES | D13: 4 | E13: 4 | F13: 4 | G13: =IF(D13="","",IF(D13=0,"-",IF(F13>D13,"ERROR",IF(E13>D13,"ERROR",IF(E13<D13,0,IF(E13>F13,0,IF(F13=D13,1,0))))))) -> 1 | T13: INVERSIONES CAÑANDONGA,C.A (T. CONEJERO)
A14: 6 | B14: IMPRESORA MULTIFUNCIONAL | D14: 1 | E14: 1 | F14: 1 | G14: =IF(D14="","",IF(D14=0,"-",IF(F14>D14,"ERROR",IF(E14>D14,"ERROR",IF(E14<D14,0,IF(E14>F14,0,IF(F14=D14,1,0))))))) -> 1 | T14: OPERADORA PLAZA DEL SOL 2015, C.A
A15: 7 | B15: IMPRESORAS FISCALES | D15: 3 | E15: 3 | F15: 3 | G15: =IF(D15="","",IF(D15=0,"-",IF(F15>D15,"ERROR",IF(E15>D15,"ERROR",IF(E15<D15,0,IF(E15>F15,0,IF(F15=D15,1,0))))))) -> 1 | H15: SERIAL 1: | J15: Nº ULT. REPORTE Z: | T15: TIENDA LOS ROBLES C.A
H16: SERIAL 2: | J16: Nº ULT. REPORTE Z: | T16: TIENDA LA FUENTE 2021 C.A
H17: SERIAL 3: | J17: Nº ULT. REPORTE Z: | T17: TIENDA PLAYA EL ANGEL C.A
H18: SERIAL 4: | J18: Nº ULT. REPORTE Z:
H19: SERIAL 5: | J19: Nº ULT. REPORTE Z:
H20: SERIAL 6: | J20: Nº ULT. REPORTE Z:
H21: SERIAL 7: | J21: Nº ULT. REPORTE Z:
A23: 8 | B23: ROUTER | D23: 1 | E23: 1 | F23: 1 | G23: =IF(D23="","",IF(D23=0,"-",IF(F23>D23,"ERROR",IF(E23>D23,"ERROR",IF(E23<D23,0,IF(E23>F23,0,IF(F23=D23,1,0))))))) -> 1
A24: 9 | B24: SUICHE | D24: 1 | E24: 1 | F24: 1 | G24: =IF(D24="","",IF(D24=0,"-",IF(F24>D24,"ERROR",IF(E24>D24,"ERROR",IF(E24<D24,0,IF(E24>F24,0,IF(F24=D24,1,0))))))) -> 1
A25: 10 | B25: ESCANER DE CODIGO DE BARRAS | D25: 4 | E25: 4 | F25: 4 | G25: =IF(D25="","",IF(D25=0,"-",IF(F25>D25,"ERROR",IF(E25>D25,"ERROR",IF(E25<D25,0,IF(E25>F25,0,IF(F25=D25,1,0))))))) -> 1
A26: 11 | B26: VISOR DE VENTAS | D26: 1 | E26: 1 | F26: 1 | G26: =IF(D26="","",IF(D26=0,"-",IF(F26>D26,"ERROR",IF(E26>D26,"ERROR",IF(E26<D26,0,IF(E26>F26,0,IF(F26=D26,1,0))))))) -> 1
A27: 12 | B27: DVR | D27: 1 | E27: 1 | F27: 1 | G27: =IF(D27="","",IF(D27=0,"-",IF(F27>D27,"ERROR",IF(E27>D27,"ERROR",IF(E27<D27,0,IF(E27>F27,0,IF(F27=D27,1,0))))))) -> 1
A28: 13 | B28: MODEM | D28: 1 | E28: 1 | F28: 1 | G28: =IF(D28="","",IF(D28=0,"-",IF(F28>D28,"ERROR",IF(E28>D28,"ERROR",IF(E28<D28,0,IF(E28>F28,0,IF(F28=D28,1,0))))))) -> 1
A29: 14 | B29: LIBROS DE IMPRESORAS FISCALES | D29: 3 | E29: 3 | F29: 3 | G29: =IF(D29="","",IF(D29=0,"-",IF(F29>D29,"ERROR",IF(E29>D29,"ERROR",IF(E29<D29,0,IF(E29>F29,0,IF(F29=D29,1,0))))))) -> 1
A30: TOTAL DE EFECTIVIDAD DE EQUIPOS | G30: =IFERROR(AVERAGE(G9:G28),"-") -> 1
A32: Realizado Por: | C32: Carolina Hernandez
A33: Cargo | C33: Ayudante Especial
A35: NOTA: El check list de Existencia de Equipos en Tiendas debe ser enviado entre los 5 primeros días del mes, vía correo electrónico al grupo Sistemas, con copia al Director de Servicios de Control.
L40: HOUSE TICKET | M40: INVENTARIO | N40: CABLEADO | O40: MES
L41: SI | M41: 0 | N41: SI | O41: ENERO
L42: NO | M42: 1 | N42: NO | O42: FEBRERO
M43: 2 | O43: MARZO
M44: 3 | O44: ABRIL
M45: 4 | O45: MAYO
M46: 5 | O46: JUNIO
M47: 6 | O47: JULIO
M48: 7 | O48: AGOSTO
M49: 8 | O49: SEPTIEMBRE
...

Sheet PLA
C1: CHECK LIST DE EXISTENCIA DE EQUIPOS EN TIENDAS | I1: Código: | J1: FO-MIS-03
I2: Revisión: | J2: 07 | K2: 42720
I3: Fecha: | J3: 42286
B5: SUCURSAL: | C5: OPERADORA PLAZA DEL SOL 2015, C.A | H5: FECHA: | I5: 46157
A7: EQUIPOS
A8: Nº | B8: EQUIPOS | D8: INVENTARIO IDEAL | E8: INVENTARIO REAL | F8: EQUIPOS OPERATIVOS | G8: EFECTIVIDAD | H8: OBSERVACIONES
A9: 1 | B9: CPU | D9: 5 | E9: 5 | F9: 5 | G9: =IF(D9="","",IF(D9=0,"-",IF(F9>D9,"ERROR",IF(E9>D9,"ERROR",IF(E9<D9,0,IF(E9>F9,0,IF(F9=D9,1,0))))))) -> 1
A10: 2 | B10: MOUSE | D10: 5 | E10: 5 | F10: 5 | G10: =IF(D10="","",IF(D10=0,"-",IF(F10>D10,"ERROR",IF(E10>D10,"ERROR",IF(E10<D10,0,IF(E10>F10,0,IF(F10=D10,1,0))))))) -> 1
A11: 3 | B11: TECLADOS | D11: 5 | E11: 5 | F11: 5 | G11: =IF(D11="","",IF(D11=0,"-",IF(F11>D11,"ERROR",IF(E11>D11,"ERROR",IF(E11<D11,0,IF(E11>F11,0,IF(F11=D11,1,0))))))) -> 1
A12: 4 | B12: MONITORES | D12: 5 | E12: 5 | F12: 5 | G12: =IF(D12="","",IF(D12=0,"-",IF(F12>D12,"ERROR",IF(E12>D12,"ERROR",IF(E12<D12,0,IF(E12>F12,0,IF(F12=D12,1,0))))))) -> 1
A13: 5 | B13: REGULADORES | D13: 5 | E13: 5 | F13: 5 | G13: =IF(D13="","",IF(D13=0,"-",IF(F13>D13,"ERROR",IF(E13>D13,"ERROR",IF(E13<D13,0,IF(E13>F13,0,IF(F13=D13,1,0))))))) -> 1 | S13: INVERSIONES CAÑANDONGA,C.A (T. CONEJERO)
A14: 6 | B14: IMPRESORA MULTIFUNCIONAL | D14: 1 | E14: 1 | F14: 1 | G14: =IF(D14="","",IF(D14=0,"-",IF(F14>D14,"ERROR",IF(E14>D14,"ERROR",IF(E14<D14,0,IF(E14>F14,0,IF(F14=D14,1,0))))))) -> 1 | S14: OPERADORA PLAZA DEL SOL 2015, C.A
A15: 7 | B15: IMPRESORAS FISCALES | D15: 4 | E15: 4 | F15: 4 | G15: =IF(D15="","",IF(D15=0,"-",IF(F15>D15,"ERROR",IF(E15>D15,"ERROR",IF(E15<D15,0,IF(E15>F15,0,IF(F15=D15,1,0))))))) -> 1 | H15: SERIAL 1: | J15: Nº ULT. REPORTE Z: | S15: TIENDA LOS ROBLES C.A
H16: SERIAL 2: | J16: Nº ULT. REPORTE Z: | S16: TIENDA LA FUENTE 2021 C.A
H17: SERIAL 3: | J17: Nº ULT. REPORTE Z: | S17: TIENDA PLAYA EL ANGEL C.A
H18: SERIAL 4: | J18: Nº ULT. REPORTE Z:
H19: SERIAL 5: | J19: Nº ULT. REPORTE Z:
H20: SERIAL 6: | J20: Nº ULT. REPORTE Z:
H21: SERIAL 7: | J21: Nº ULT. REPORTE Z:
A23: 8 | B23: ROUTER | D23: 2 | E23: 2 | F23: 2 | G23: =IF(D23="","",IF(D23=0,"-",IF(F23>D23,"ERROR",IF(E23>D23,"ERROR",IF(E23<D23,0,IF(E23>F23,0,IF(F23=D23,1,0))))))) -> 1
A24: 9 | B24: SUICHE | D24: 2 | E24: 2 | F24: 2 | G24: =IF(D24="","",IF(D24=0,"-",IF(F24>D24,"ERROR",IF(E24>D24,"ERROR",IF(E24<D24,0,IF(E24>F24,0,IF(F24=D24,1,0))))))) -> 1
A25: 10 | B25: ESCANER DE CODIGO DE BARRAS | D25: 6 | E25: 6 | F25: 6 | G25: =IF(D25="","",IF(D25=0,"-",IF(F25>D25,"ERROR",IF(E25>D25,"ERROR",IF(E25<D25,0,IF(E25>F25,0,IF(F25=D25,1,0))))))) -> 1
A26: 11 | B26: VISOR DE VENTAS | D26: 1 | E26: 1 | F26: 1 | G26: =IF(D26="","",IF(D26=0,"-",IF(F26>D26,"ERROR",IF(E26>D26,"ERROR",IF(E26<D26,0,IF(E26>F26,0,IF(F26=D26,1,0))))))) -> 1
A27: 12 | B27: DVR | D27: 1 | E27: 1 | F27: 1 | G27: =IF(D27="","",IF(D27=0,"-",IF(F27>D27,"ERROR",IF(E27>D27,"ERROR",IF(E27<D27,0,IF(E27>F27,0,IF(F27=D27,1,0))))))) -> 1
A28: 13 | B28: MODEM | D28: 1 | E28: 1 | F28: 1 | G28: =IF(D28="","",IF(D28=0,"-",IF(F28>D28,"ERROR",IF(E28>D28,"ERROR",IF(E28<D28,0,IF(E28>F28,0,IF(F28=D28,1,0))))))) -> 1
A29: 14 | B29: LIBROS DE IMPRESORAS FISCALES | D29: 5 | E29: 5 | F29: 5 | G29: =IF(D29="","",IF(D29=0,"-",IF(F29>D29,"ERROR",IF(E29>D29,"ERROR",IF(E29<D29,0,IF(E29>F29,0,IF(F29=D29,1,0))))))) -> 1
A30: TOTAL DE EFECTIVIDAD DE EQUIPOS | G30: =IFERROR(AVERAGE(G9:G28),"-") -> 1
A32: Realizado Por: | C32: Aderso Gutierrez
A33: Cargo | C33: Ayudante Especial
A35: NOTA: El check list de Existencia de Equipos en Tiendas debe ser enviado entre los 5 primeros días del mes, vía correo electrónico al grupo Sistemas, con copia al Director de Servicios de Control.
L39: HOUSE TICKET | M39: INVENTARIO | N39: CABLEADO | O39: MES
L40: SI | M40: 0 | N40: SI | O40: ENERO
L41: NO | M41: 1 | N41: NO | O41: FEBRERO
M42: 2 | O42: MARZO
M43: 3 | O43: ABRIL
M44: 4 | O44: MAYO
M45: 5 | O45: JUNIO
M46: 6 | O46: JULIO
M47: 7 | O47: AGOSTO
M48: 8 | O48: SEPTIEMBRE
...

Sheet ROB
C1: CHECK LIST DE EXISTENCIA DE EQUIPOS EN TIENDAS | I1: Código: | J1: FO-MIS-03
I2: Revisión: | J2: 07 | K2: 42720
I3: Fecha: | J3: 42286
B5: SUCURSAL: | C5: TIENDA LOS ROBLES C.A | H5: FECHA: | I5: 46157
A7: EQUIPOS
A8: Nº | B8: EQUIPOS | D8: INVENTARIO IDEAL | E8: INVENTARIO REAL | F8: EQUIPOS OPERATIVOS | G8: EFECTIVIDAD | H8: OBSERVACIONES
A9: 1 | B9: CPU | D9: 3 | E9: 3 | F9: 3 | G9: =IF(D9="","",IF(D9=0,"-",IF(F9>D9,"ERROR",IF(E9>D9,"ERROR",IF(E9<D9,0,IF(E9>F9,0,IF(F9=D9,1,0))))))) -> 1
A10: 2 | B10: MOUSE | D10: 3 | E10: 3 | F10: 3 | G10: =IF(D10="","",IF(D10=0,"-",IF(F10>D10,"ERROR",IF(E10>D10,"ERROR",IF(E10<D10,0,IF(E10>F10,0,IF(F10=D10,1,0))))))) -> 1
A11: 3 | B11: TECLADOS | D11: 3 | E11: 3 | F11: 3 | G11: =IF(D11="","",IF(D11=0,"-",IF(F11>D11,"ERROR",IF(E11>D11,"ERROR",IF(E11<D11,0,IF(E11>F11,0,IF(F11=D11,1,0))))))) -> 1
A12: 4 | B12: MONITORES | D12: 3 | E12: 3 | F12: 3 | G12: =IF(D12="","",IF(D12=0,"-",IF(F12>D12,"ERROR",IF(E12>D12,"ERROR",IF(E12<D12,0,IF(E12>F12,0,IF(F12=D12,1,0))))))) -> 1
A13: 5 | B13: REGULADORES | D13: 3 | E13: 3 | F13: 3 | G13: =IF(D13="","",IF(D13=0,"-",IF(F13>D13,"ERROR",IF(E13>D13,"ERROR",IF(E13<D13,0,IF(E13>F13,0,IF(F13=D13,1,0))))))) -> 1
A14: 6 | B14: IMPRESORA MULTIFUNCIONAL | D14: 1 | E14: 1 | F14: 1 | G14: =IF(D14="","",IF(D14=0,"-",IF(F14>D14,"ERROR",IF(E14>D14,"ERROR",IF(E14<D14,0,IF(E14>F14,0,IF(F14=D14,1,0))))))) -> 1 | N14: INVERSIONES CAÑANDONGA,C.A (T. CONEJERO)
A15: 7 | B15: IMPRESORAS FISCALES | D15: 3 | E15: 3 | F15: 3 | G15: =IF(D15="","",IF(D15=0,"-",IF(F15>D15,"ERROR",IF(E15>D15,"ERROR",IF(E15<D15,0,IF(E15>F15,0,IF(F15=D15,1,0))))))) -> 1 | H15: SERIAL 1: | J15: Nº ULT. REPORTE Z: | N15: TIENDA LOS ROBLES C.A
H16: SERIAL 2: | J16: Nº ULT. REPORTE Z: | N16: TIENDA LA FUENTE 2021 C.A
H17: SERIAL 3: | J17: Nº ULT. REPORTE Z: | N17: TIENDA PLAYA EL ANGEL C.A
H18: SERIAL 4: | J18: Nº ULT. REPORTE Z:
H19: SERIAL 5: | J19: Nº ULT. REPORTE Z:
H20: SERIAL 6: | J20: Nº ULT. REPORTE Z:
H21: SERIAL 7: | J21: Nº ULT. REPORTE Z:
A23: 8 | B23: ROUTER | D23: 1 | E23: 1 | F23: 1 | G23: =IF(D23="","",IF(D23=0,"-",IF(F23>D23,"ERROR",IF(E23>D23,"ERROR",IF(E23<D23,0,IF(E23>F23,0,IF(F23=D23,1,0))))))) -> 1
A24: 9 | B24: SUICHE | D24: 1 | E24: 1 | F24: 1 | G24: =IF(D24="","",IF(D24=0,"-",IF(F24>D24,"ERROR",IF(E24>D24,"ERROR",IF(E24<D24,0,IF(E24>F24,0,IF(F24=D24,1,0))))))) -> 1
A25: 10 | B25: ESCANER DE CODIGO DE BARRAS | D25: 3 | E25: 3 | F25: 3 | G25: =IF(D25="","",IF(D25=0,"-",IF(F25>D25,"ERROR",IF(E25>D25,"ERROR",IF(E25<D25,0,IF(E25>F25,0,IF(F25=D25,1,0))))))) -> 1
A26: 11 | B26: VISOR DE VENTAS | D26: 1 | E26: 1 | F26: 1 | G26: =IF(D26="","",IF(D26=0,"-",IF(F26>D26,"ERROR",IF(E26>D26,"ERROR",IF(E26<D26,0,IF(E26>F26,0,IF(F26=D26,1,0))))))) -> 1
A27: 12 | B27: DVR | D27: 1 | E27: 1 | F27: 1 | G27: =IF(D27="","",IF(D27=0,"-",IF(F27>D27,"ERROR",IF(E27>D27,"ERROR",IF(E27<D27,0,IF(E27>F27,0,IF(F27=D27,1,0))))))) -> 1
A28: 13 | B28: MODEM | D28: 1 | E28: 1 | F28: 1 | G28: =IF(D28="","",IF(D28=0,"-",IF(F28>D28,"ERROR",IF(E28>D28,"ERROR",IF(E28<D28,0,IF(E28>F28,0,IF(F28=D28,1,0))))))) -> 1
A29: 14 | B29: LIBROS DE IMPRESORAS FISCALES | D29: 3 | E29: 3 | F29: 3 | G29: =IF(D29="","",IF(D29=0,"-",IF(F29>D29,"ERROR",IF(E29>D29,"ERROR",IF(E29<D29,0,IF(E29>F29,0,IF(F29=D29,1,0))))))) -> 1
A30: TOTAL DE EFECTIVIDAD DE EQUIPOS | G30: =IFERROR(AVERAGE(G9:G28),"-") -> 1
A32: Realizado Por: | C32: Anthony Alfonso
A33: Cargo | C33: Ayudante Especial
A35: NOTA: El check list de Existencia de Equipos en Tiendas debe ser enviado entre los 5 primeros días del mes, vía correo electrónico al grupo Sistemas, con copia al Director de Servicios de Control.
A36: NOTA: El check list de Existencia de Equipos en Tiendas debe ser enviado entre los 5 primeros días del mes, vía correo electrónico al grupo Sistemas, con copia al Director de Servicios de Control.
K39: TIENDAS | L39: HOUSE TICKET | M39: INVENTARIO | N39: CABLEADO | O39: MES
K40: =IF(MAESTRO!A1="","",MAESTRO!A1) -> ******SUCURSALES | L40: SI | M40: 0 | N40: SI | O40: ENERO
K41: =IF(MAESTRO!A2="","",MAESTRO!A2) -> LA CASA DE LA CAÑA, C.A. (T. ALTERNA) | L41: NO | M41: 1 | N41: NO | O41: FEBRERO
K42: =IF(MAESTRO!A3="","",MAESTRO!A3) -> LA CASA DE LA CAÑA, C.A. (T. ANACO) | M42: 2 | O42: MARZO
K43: =IF(MAESTRO!A4="","",MAESTRO!A4) -> LA CASA DE LA CAÑA, C.A. (T. CUMANÁ) | M43: 3 | O43: ABRIL
K44: =IF(MAESTRO!A5="","",MAESTRO!A5) -> LA CASA DE LA CAÑA, C.A. (T. MATURÍN I) | M44: 4 | O44: MAYO
K45: =IF(MAESTRO!A6="","",MAESTRO!A6) -> LA CASA DE LA CAÑA, C.A. (T. MATURÍN II) | M45: 5 | O45: JUNIO
K46: =IF(MAESTRO!A7="","",MAESTRO!A7) -> LA CASA DE LA CAÑA, C.A. (T. NVA. BARCELONA) | M46: 6 | O46: JULIO
K47: =IF(MAESTRO!A8="","",MAESTRO!A8) -> INVERSIONES CAÑANDONGA,C.A (T. CONEJERO) | M47: 7 | O47: AGOSTO
...

Sheet FUE
C1: CHECK LIST DE EXISTENCIA DE EQUIPOS EN TIENDAS | I1: Código: | J1: FO-MIS-03
I2: Revisión: | J2: 07 | K2: 42720
I3: Fecha: | J3: 42286
B5: SUCURSAL: | C5: TIENDA LA FUENTE 2021 C.A | H5: FECHA: | I5: 46157
A7: EQUIPOS
A8: Nº | B8: EQUIPOS | D8: INVENTARIO IDEAL | E8: INVENTARIO REAL | F8: EQUIPOS OPERATIVOS | G8: EFECTIVIDAD | H8: OBSERVACIONES
A9: 1 | B9: CPU | D9: 3 | E9: 3 | F9: 3 | G9: =IF(D9="","",IF(D9=0,"-",IF(F9>D9,"ERROR",IF(E9>D9,"ERROR",IF(E9<D9,0,IF(E9>F9,0,IF(F9=D9,1,0))))))) -> 1
A10: 2 | B10: MOUSE | D10: 3 | E10: 3 | F10: 3 | G10: =IF(D10="","",IF(D10=0,"-",IF(F10>D10,"ERROR",IF(E10>D10,"ERROR",IF(E10<D10,0,IF(E10>F10,0,IF(F10=D10,1,0))))))) -> 1
A11: 3 | B11: TECLADOS | D11: 3 | E11: 3 | F11: 3 | G11: =IF(D11="","",IF(D11=0,"-",IF(F11>D11,"ERROR",IF(E11>D11,"ERROR",IF(E11<D11,0,IF(E11>F11,0,IF(F11=D11,1,0))))))) -> 1
A12: 4 | B12: MONITORES | D12: 3 | E12: 3 | F12: 3 | G12: =IF(D12="","",IF(D12=0,"-",IF(F12>D12,"ERROR",IF(E12>D12,"ERROR",IF(E12<D12,0,IF(E12>F12,0,IF(F12=D12,1,0))))))) -> 1
A13: 5 | B13: REGULADORES | D13: 3 | E13: 3 | F13: 3 | G13: =IF(D13="","",IF(D13=0,"-",IF(F13>D13,"ERROR",IF(E13>D13,"ERROR",IF(E13<D13,0,IF(E13>F13,0,IF(F13=D13,1,0))))))) -> 1
A14: 6 | B14: IMPRESORA MULTIFUNCIONAL | D14: 1 | E14: 1 | F14: 1 | G14: =IF(D14="","",IF(D14=0,"-",IF(F14>D14,"ERROR",IF(E14>D14,"ERROR",IF(E14<D14,0,IF(E14>F14,0,IF(F14=D14,1,0))))))) -> 1 | O14: INVERSIONES CAÑANDONGA,C.A (T. CONEJERO)
A15: 7 | B15: IMPRESORAS FISCALES | D15: 2 | E15: 2 | F15: 2 | G15: =IF(D15="","",IF(D15=0,"-",IF(F15>D15,"ERROR",IF(E15>D15,"ERROR",IF(E15<D15,0,IF(E15>F15,0,IF(F15=D15,1,0))))))) -> 1 | H15: SERIAL 1: | J15: Nº ULT. REPORTE Z: | O15: OPERADORA PLAZA DEL SOL 2015, C.A
H16: SERIAL 2: | J16: Nº ULT. REPORTE Z: | O16: TIENDA LOS ROBLES C.A
H17: SERIAL 3: | J17: Nº ULT. REPORTE Z: | O17: TIENDA LA FUENTE 2021 C.A
H18: SERIAL 4: | J18: Nº ULT. REPORTE Z: | O18: TIENDA PLAYA EL ANGEL C.A
H19: SERIAL 5: | J19: Nº ULT. REPORTE Z:
H20: SERIAL 6: | J20: Nº ULT. REPORTE Z:
H21: SERIAL 7: | J21: Nº ULT. REPORTE Z:
H22: 2 Impresora Con IGTF
A23: 8 | B23: ROUTER | D23: 1 | E23: 1 | F23: 1 | G23: =IF(D23="","",IF(D23=0,"-",IF(F23>D23,"ERROR",IF(E23>D23,"ERROR",IF(E23<D23,0,IF(E23>F23,0,IF(F23=D23,1,0))))))) -> 1
A24: 9 | B24: SUICHE | D24: 1 | E24: 1 | F24: 1 | G24: =IF(D24="","",IF(D24=0,"-",IF(F24>D24,"ERROR",IF(E24>D24,"ERROR",IF(E24<D24,0,IF(E24>F24,0,IF(F24=D24,1,0))))))) -> 1
A25: 10 | B25: ESCANER DE CODIGO DE BARRAS | D25: 3 | E25: 3 | F25: 3 | G25: =IF(D25="","",IF(D25=0,"-",IF(F25>D25,"ERROR",IF(E25>D25,"ERROR",IF(E25<D25,0,IF(E25>F25,0,IF(F25=D25,1,0))))))) -> 1
A26: 11 | B26: VISOR DE VENTAS | D26: 1 | E26: 1 | F26: 1 | G26: =IF(D26="","",IF(D26=0,"-",IF(F26>D26,"ERROR",IF(E26>D26,"ERROR",IF(E26<D26,0,IF(E26>F26,0,IF(F26=D26,1,0))))))) -> 1
A27: 12 | B27: DVR | D27: 1 | E27: 1 | F27: 1 | G27: =IF(D27="","",IF(D27=0,"-",IF(F27>D27,"ERROR",IF(E27>D27,"ERROR",IF(E27<D27,0,IF(E27>F27,0,IF(F27=D27,1,0))))))) -> 1
A28: 13 | B28: MODEM | D28: 1 | E28: 1 | F28: 1 | G28: =IF(D28="","",IF(D28=0,"-",IF(F28>D28,"ERROR",IF(E28>D28,"ERROR",IF(E28<D28,0,IF(E28>F28,0,IF(F28=D28,1,0))))))) -> 1
A29: 14 | B29: LIBROS DE IMPRESORAS FISCALES | D29: 2 | E29: 2 | F29: 2 | G29: =IF(D29="","",IF(D29=0,"-",IF(F29>D29,"ERROR",IF(E29>D29,"ERROR",IF(E29<D29,0,IF(E29>F29,0,IF(F29=D29,1,0))))))) -> 1
A30: TOTAL DE EFECTIVIDAD DE EQUIPOS | G30: =IFERROR(AVERAGE(G9:G28),"-") -> 1
A32: Realizado Por: | C32: Jesus Fuente
A33: Cargo | C33: Ayudante Especial
A35: NOTA: El check list de Existencia de Equipos en Tiendas debe ser enviado entre los 5 primeros días del mes, vía correo electrónico al grupo Sistemas, con copia al Director de Servicios de Control.
L39: HOUSE TICKET | M39: INVENTARIO | N39: CABLEADO | O39: MES
K40: TIENDAS | L40: SI | M40: 0 | N40: SI | O40: ENERO
K41: =IF(MAESTRO!A1="","",MAESTRO!A1) -> ******SUCURSALES | L41: NO | M41: 1 | N41: NO | O41: FEBRERO
K42: =IF(MAESTRO!A2="","",MAESTRO!A2) -> LA CASA DE LA CAÑA, C.A. (T. ALTERNA) | M42: 2 | O42: MARZO
K43: =IF(MAESTRO!A3="","",MAESTRO!A3) -> LA CASA DE LA CAÑA, C.A. (T. ANACO) | M43: 3 | O43: ABRIL
K44: =IF(MAESTRO!A4="","",MAESTRO!A4) -> LA CASA DE LA CAÑA, C.A. (T. CUMANÁ) | M44: 4 | O44: MAYO
K45: =IF(MAESTRO!A5="","",MAESTRO!A5) -> LA CASA DE LA CAÑA, C.A. (T. MATURÍN I) | M45: 5 | O45: JUNIO
K46: =IF(MAESTRO!A6="","",MAESTRO!A6) -> LA CASA DE LA CAÑA, C.A. (T. MATURÍN II) | M46: 6 | O46: JULIO
K47: =IF(MAESTRO!A7="","",MAESTRO!A7) -> LA CASA DE LA CAÑA, C.A. (T. NVA. BARCELONA) | M47: 7 | O47: AGOSTO
...

Sheet ANG
C1: CHECK LIST DE EXISTENCIA DE EQUIPOS EN TIENDAS | I1: Código: | J1: FO-MIS-03
I2: Revisión: | J2: 07 | K2: 42720
I3: Fecha: | J3: 42286
B5: SUCURSAL: | C5: TIENDA PLAYA EL ANGEL C.A | H5: FECHA: | I5: 46157
A7: EQUIPOS
A8: Nº | B8: EQUIPOS | D8: INVENTARIO IDEAL | E8: INVENTARIO REAL | F8: EQUIPOS OPERATIVOS | G8: EFECTIVIDAD | H8: OBSERVACIONES
A9: 1 | B9: CPU | D9: 4 | E9: 4 | F9: 4 | G9: =IF(D9="","",IF(D9=0,"-",IF(F9>D9,"ERROR",IF(E9>D9,"ERROR",IF(E9<D9,0,IF(E9>F9,0,IF(F9=D9,1,0))))))) -> 1 | H9: Se Formateo e instalo caja 3
A10: 2 | B10: MOUSE | D10: 4 | E10: 4 | F10: 4 | G10: =IF(D10="","",IF(D10=0,"-",IF(F10>D10,"ERROR",IF(E10>D10,"ERROR",IF(E10<D10,0,IF(E10>F10,0,IF(F10=D10,1,0))))))) -> 1
A11: 3 | B11: TECLADOS | D11: 4 | E11: 4 | F11: 4 | G11: =IF(D11="","",IF(D11=0,"-",IF(F11>D11,"ERROR",IF(E11>D11,"ERROR",IF(E11<D11,0,IF(E11>F11,0,IF(F11=D11,1,0))))))) -> 1
A12: 4 | B12: MONITORES | D12: 4 | E12: 4 | F12: 4 | G12: =IF(D12="","",IF(D12=0,"-",IF(F12>D12,"ERROR",IF(E12>D12,"ERROR",IF(E12<D12,0,IF(E12>F12,0,IF(F12=D12,1,0))))))) -> 1
A13: 5 | B13: REGULADORES | D13: 4 | E13: 4 | F13: 4 | G13: =IF(D13="","",IF(D13=0,"-",IF(F13>D13,"ERROR",IF(E13>D13,"ERROR",IF(E13<D13,0,IF(E13>F13,0,IF(F13=D13,1,0))))))) -> 1
A14: 6 | B14: IMPRESORA MULTIFUNCIONAL | D14: 1 | E14: 1 | F14: 1 | G14: =IF(D14="","",IF(D14=0,"-",IF(F14>D14,"ERROR",IF(E14>D14,"ERROR",IF(E14<D14,0,IF(E14>F14,0,IF(F14=D14,1,0))))))) -> 1 | O14: INVERSIONES CAÑANDONGA,C.A (T. CONEJERO)
A15: 7 | B15: IMPRESORAS FISCALES | D15: 3 | E15: 3 | F15: 3 | G15: =IF(D15="","",IF(D15=0,"-",IF(F15>D15,"ERROR",IF(E15>D15,"ERROR",IF(E15<D15,0,IF(E15>F15,0,IF(F15=D15,1,0))))))) -> 1 | H15: SERIAL 1: | J15: Nº ULT. REPORTE Z: | O15: OPERADORA PLAZA DEL SOL 2015, C.A
H16: SERIAL 2: | J16: Nº ULT. REPORTE Z: | O16: TIENDA LOS ROBLES C.A
H17: SERIAL 3: | J17: Nº ULT. REPORTE Z: | O17: TIENDA LA FUENTE 2021 C.A
H18: SERIAL 4: | J18: Nº ULT. REPORTE Z: | O18: TIENDA PLAYA EL ANGEL C.A
H19: SERIAL 5: | J19: Nº ULT. REPORTE Z:
H20: SERIAL 6: | J20: Nº ULT. REPORTE Z:
H21: SERIAL 7: | J21: Nº ULT. REPORTE Z:
A23: 8 | B23: ROUTER | D23: 1 | E23: 1 | F23: 1 | G23: =IF(D23="","",IF(D23=0,"-",IF(F23>D23,"ERROR",IF(E23>D23,"ERROR",IF(E23<D23,0,IF(E23>F23,0,IF(F23=D23,1,0))))))) -> 1
A24: 9 | B24: SUICHE | D24: 1 | E24: 1 | F24: 1 | G24: =IF(D24="","",IF(D24=0,"-",IF(F24>D24,"ERROR",IF(E24>D24,"ERROR",IF(E24<D24,0,IF(E24>F24,0,IF(F24=D24,1,0))))))) -> 1
A25: 10 | B25: ESCANER DE CODIGO DE BARRAS | D25: 4 | E25: 4 | F25: 4 | G25: =IF(D25="","",IF(D25=0,"-",IF(F25>D25,"ERROR",IF(E25>D25,"ERROR",IF(E25<D25,0,IF(E25>F25,0,IF(F25=D25,1,0))))))) -> 1
A26: 11 | B26: VISOR DE VENTAS | D26: 1 | E26: 1 | F26: 1 | G26: =IF(D26="","",IF(D26=0,"-",IF(F26>D26,"ERROR",IF(E26>D26,"ERROR",IF(E26<D26,0,IF(E26>F26,0,IF(F26=D26,1,0))))))) -> 1
A27: 12 | B27: DVR | D27: 1 | E27: 1 | F27: 1 | G27: =IF(D27="","",IF(D27=0,"-",IF(F27>D27,"ERROR",IF(E27>D27,"ERROR",IF(E27<D27,0,IF(E27>F27,0,IF(F27=D27,1,0))))))) -> 1
A28: 13 | B28: MODEM | D28: 1 | E28: 1 | F28: 1 | G28: =IF(D28="","",IF(D28=0,"-",IF(F28>D28,"ERROR",IF(E28>D28,"ERROR",IF(E28<D28,0,IF(E28>F28,0,IF(F28=D28,1,0))))))) -> 1
A29: 14 | B29: LIBROS DE IMPRESORAS FISCALES | D29: 3 | E29: 3 | F29: 3 | G29: =IF(D29="","",IF(D29=0,"-",IF(F29>D29,"ERROR",IF(E29>D29,"ERROR",IF(E29<D29,0,IF(E29>F29,0,IF(F29=D29,1,0))))))) -> 1
A30: TOTAL DE EFECTIVIDAD DE EQUIPOS | G30: =IFERROR(AVERAGE(G9:G28),"-") -> 1
A32: Realizado Por: | C32: Mariana Salazar
A33: Cargo | C33: Ayudante Especial
A35: NOTA: El check list de Existencia de Equipos en Tiendas debe ser enviado entre los 5 primeros días del mes, vía correo electrónico al grupo Sistemas, con copia al Director de Servicios de Control.
L39: HOUSE TICKET | M39: INVENTARIO | N39: CABLEADO | O39: MES
K40: TIENDAS | L40: SI | M40: 0 | N40: SI | O40: ENERO
K41: =IF(MAESTRO!A1="","",MAESTRO!A1) -> ******SUCURSALES | L41: NO | M41: 1 | N41: NO | O41: FEBRERO
K42: =IF(MAESTRO!A2="","",MAESTRO!A2) -> LA CASA DE LA CAÑA, C.A. (T. ALTERNA) | M42: 2 | O42: MARZO
K43: =IF(MAESTRO!A3="","",MAESTRO!A3) -> LA CASA DE LA CAÑA, C.A. (T. ANACO) | M43: 3 | O43: ABRIL
K44: =IF(MAESTRO!A4="","",MAESTRO!A4) -> LA CASA DE LA CAÑA, C.A. (T. CUMANÁ) | M44: 4 | O44: MAYO
K45: =IF(MAESTRO!A5="","",MAESTRO!A5) -> LA CASA DE LA CAÑA, C.A. (T. MATURÍN I) | M45: 5 | O45: JUNIO
K46: =IF(MAESTRO!A6="","",MAESTRO!A6) -> LA CASA DE LA CAÑA, C.A. (T. MATURÍN II) | M46: 6 | O46: JULIO
K47: =IF(MAESTRO!A7="","",MAESTRO!A7) -> LA CASA DE LA CAÑA, C.A. (T. NVA. BARCELONA) | M47: 7 | O47: AGOSTO
K48: =IF(MAESTRO!A8="","",MAESTRO!A8) -> INVERSIONES CAÑANDONGA,C.A (T. CONEJERO) | M48: 8 | O48: SEPTIEMBRE
...

Sheet AERO
C1: CHECK LIST DE EXISTENCIA DE EQUIPOS EN TIENDAS | I1: Código: | J1: FO-MIS-03
I2: Revisión: | J2: 07 | K2: 42720
I3: Fecha: | J3: 42286
B5: SUCURSAL: | C5: TIENDA AEROPUERTO | H5: FECHA: | I5: 46157
A7: EQUIPOS
A8: Nº | B8: EQUIPOS | D8: INVENTARIO IDEAL | E8: INVENTARIO REAL | F8: EQUIPOS OPERATIVOS | G8: EFECTIVIDAD | H8: OBSERVACIONES
A9: 1 | B9: CPU | D9: 3 | E9: 3 | F9: 3 | G9: =IF(D9="","",IF(D9=0,"-",IF(F9>D9,"ERROR",IF(E9>D9,"ERROR",IF(E9<D9,0,IF(E9>F9,0,IF(F9=D9,1,0))))))) -> 1
A10: 2 | B10: MOUSE | D10: 3 | E10: 3 | F10: 3 | G10: =IF(D10="","",IF(D10=0,"-",IF(F10>D10,"ERROR",IF(E10>D10,"ERROR",IF(E10<D10,0,IF(E10>F10,0,IF(F10=D10,1,0))))))) -> 1
A11: 3 | B11: TECLADOS | D11: 3 | E11: 3 | F11: 3 | G11: =IF(D11="","",IF(D11=0,"-",IF(F11>D11,"ERROR",IF(E11>D11,"ERROR",IF(E11<D11,0,IF(E11>F11,0,IF(F11=D11,1,0))))))) -> 1
A12: 4 | B12: MONITORES | D12: 3 | E12: 3 | F12: 3 | G12: =IF(D12="","",IF(D12=0,"-",IF(F12>D12,"ERROR",IF(E12>D12,"ERROR",IF(E12<D12,0,IF(E12>F12,0,IF(F12=D12,1,0))))))) -> 1
A13: 5 | B13: REGULADORES | D13: 3 | E13: 3 | F13: 3 | G13: =IF(D13="","",IF(D13=0,"-",IF(F13>D13,"ERROR",IF(E13>D13,"ERROR",IF(E13<D13,0,IF(E13>F13,0,IF(F13=D13,1,0))))))) -> 1
A14: 6 | B14: IMPRESORA MULTIFUNCIONAL | D14: 1 | E14: 1 | F14: 1 | G14: =IF(D14="","",IF(D14=0,"-",IF(F14>D14,"ERROR",IF(E14>D14,"ERROR",IF(E14<D14,0,IF(E14>F14,0,IF(F14=D14,1,0))))))) -> 1 | O14: INVERSIONES CAÑANDONGA,C.A (T. CONEJERO)
A15: 7 | B15: IMPRESORAS FISCALES | D15: 2 | E15: 2 | F15: 2 | G15: =IF(D15="","",IF(D15=0,"-",IF(F15>D15,"ERROR",IF(E15>D15,"ERROR",IF(E15<D15,0,IF(E15>F15,0,IF(F15=D15,1,0))))))) -> 1 | H15: SERIAL 1: | J15: Nº ULT. REPORTE Z: | O15: OPERADORA PLAZA DEL SOL 2015, C.A
H16: SERIAL 2: | J16: Nº ULT. REPORTE Z: | O16: TIENDA LOS ROBLES C.A
H17: SERIAL 3: | J17: Nº ULT. REPORTE Z: | O17: TIENDA LA FUENTE 2021 C.A
H18: SERIAL 4: | J18: Nº ULT. REPORTE Z: | O18: TIENDA AEROPUERTO
H19: SERIAL 5: | J19: Nº ULT. REPORTE Z: | O19: TIENDA PLAYA EL ANGEL
H20: SERIAL 6: | J20: Nº ULT. REPORTE Z:
H21: SERIAL 7: | J21: Nº ULT. REPORTE Z:
A23: 8 | B23: ROUTER | D23: 1 | E23: 1 | F23: 1 | G23: =IF(D23="","",IF(D23=0,"-",IF(F23>D23,"ERROR",IF(E23>D23,"ERROR",IF(E23<D23,0,IF(E23>F23,0,IF(F23=D23,1,0))))))) -> 1
A24: 9 | B24: SUICHE | D24: 1 | E24: 1 | F24: 1 | G24: =IF(D24="","",IF(D24=0,"-",IF(F24>D24,"ERROR",IF(E24>D24,"ERROR",IF(E24<D24,0,IF(E24>F24,0,IF(F24=D24,1,0))))))) -> 1
A25: 10 | B25: ESCANER DE CODIGO DE BARRAS | D25: 4 | E25: 4 | F25: 4 | G25: =IF(D25="","",IF(D25=0,"-",IF(F25>D25,"ERROR",IF(E25>D25,"ERROR",IF(E25<D25,0,IF(E25>F25,0,IF(F25=D25,1,0))))))) -> 1
A26: 11 | B26: VISOR DE VENTAS | D26: 1 | E26: 1 | F26: 1 | G26: =IF(D26="","",IF(D26=0,"-",IF(F26>D26,"ERROR",IF(E26>D26,"ERROR",IF(E26<D26,0,IF(E26>F26,0,IF(F26=D26,1,0))))))) -> 1
A27: 12 | B27: DVR | D27: 1 | E27: 1 | F27: 1 | G27: =IF(D27="","",IF(D27=0,"-",IF(F27>D27,"ERROR",IF(E27>D27,"ERROR",IF(E27<D27,0,IF(E27>F27,0,IF(F27=D27,1,0))))))) -> 1
A28: 13 | B28: MODEM | D28: 1 | E28: 1 | F28: 1 | G28: =IF(D28="","",IF(D28=0,"-",IF(F28>D28,"ERROR",IF(E28>D28,"ERROR",IF(E28<D28,0,IF(E28>F28,0,IF(F28=D28,1,0))))))) -> 1
A29: 14 | B29: LIBROS DE IMPRESORAS FISCALES | D29: 2 | E29: 2 | F29: 2 | G29: =IF(D29="","",IF(D29=0,"-",IF(F29>D29,"ERROR",IF(E29>D29,"ERROR",IF(E29<D29,0,IF(E29>F29,0,IF(F29=D29,1,0))))))) -> 1
A30: TOTAL DE EFECTIVIDAD DE EQUIPOS | G30: =IFERROR(AVERAGE(G9:G28),"-") -> 1
A32: Realizado Por: | C32: Humberto Malave
A33: Cargo | C33: Gerente De Base Margarita
A35: NOTA: El check list de Existencia de Equipos en Tiendas debe ser enviado entre los 5 primeros días del mes, vía correo electrónico al grupo Sistemas, con copia al Director de Servicios de Control.
L39: HOUSE TICKET | M39: INVENTARIO | N39: CABLEADO | O39: MES
K40: TIENDAS | L40: SI | M40: 0 | N40: SI | O40: ENERO
K41: =IF(MAESTRO!A1="","",MAESTRO!A1) -> ******SUCURSALES | L41: NO | M41: 1 | N41: NO | O41: FEBRERO
K42: =IF(MAESTRO!A2="","",MAESTRO!A2) -> LA CASA DE LA CAÑA, C.A. (T. ALTERNA) | M42: 2 | O42: MARZO
K43: =IF(MAESTRO!A3="","",MAESTRO!A3) -> LA CASA DE LA CAÑA, C.A. (T. ANACO) | M43: 3 | O43: ABRIL
K44: =IF(MAESTRO!A4="","",MAESTRO!A4) -> LA CASA DE LA CAÑA, C.A. (T. CUMANÁ) | M44: 4 | O44: MAYO
K45: =IF(MAESTRO!A5="","",MAESTRO!A5) -> LA CASA DE LA CAÑA, C.A. (T. MATURÍN I) | M45: 5 | O45: JUNIO
K46: =IF(MAESTRO!A6="","",MAESTRO!A6) -> LA CASA DE LA CAÑA, C.A. (T. MATURÍN II) | M46: 6 | O46: JULIO
K47: =IF(MAESTRO!A7="","",MAESTRO!A7) -> LA CASA DE LA CAÑA, C.A. (T. NVA. BARCELONA) | M47: 7 | O47: AGOSTO
K48: =IF(MAESTRO!A8="","",MAESTRO!A8) -> INVERSIONES CAÑANDONGA,C.A (T. CONEJERO) | M48: 8 | O48: SEPTIEMBRE
...

Sheet CONSOLIDADO
A1: EQUIPOS | C1: TIENDAS
C2: CON | D2: PLA | E2: ROB | F2: FUE | G2: ANG | H2: AERO | I2: TOTAL
A3: CPU | B3: Inv. Ideal | C3: =CON!D9 -> 4 | D3: =PLA!D9 -> 5 | E3: =ROB!D9 -> 3 | F3: =FUE!D9 -> 3 | G3: =ANG!D9 -> 4 | H3: =AERO!E9 -> 3 | I3: =SUM(C3:H3) -> 22
B4: Inv. Real | C4: =CON!E9 -> 4 | D4: =PLA!E9 -> 5 | E4: =ROB!E9 -> 3 | F4: =FUE!E9 -> 3 | G4: =ANG!E9 -> 4 | H4: =AERO!F9 -> 3 | I4: =SUM(C4:H4) -> 22
B5: Equi. Ope. | C5: =CON!F9 -> 4 | D5: =PLA!F9 -> 5 | E5: =ROB!F9 -> 3 | F5: =FUE!F9 -> 3 | G5: =ANG!F9 -> 4 | H5: =AERO!F9 -> 3 | I5: =SUM(C5:H5) -> 22
B6: Efect. | C6: =+C5/C4 -> 1 | D6: =+D5/D4 -> 1 | E6: =+E5/E4 -> 1 | F6: =+F5/F4 -> 1 | G6: =+G5/G4 -> 1 | H6: =+H5/H4 -> 1 | I6: =AVERAGE(C6:G6) -> 1
A7: MOUSE | B7: Inv. Ideal | C7: =CON!D10 -> 4 | D7: =PLA!D10 -> 5 | E7: =ROB!D10 -> 3 | F7: =FUE!D10 -> 3 | G7: =ANG!D10 -> 4 | H7: =AERO!E10 -> 3 | I7: =SUM(C7:H7) -> 22
B8: Inv. Real | C8: =CON!E10 -> 4 | D8: =PLA!E10 -> 5 | E8: =ROB!E10 -> 3 | F8: =FUE!E10 -> 3 | G8: =ANG!E10 -> 4 | H8: =AERO!F10 -> 3 | I8: =SUM(C8:H8) -> 22
B9: Equi. Ope. | C9: =CON!F10 -> 4 | D9: =PLA!F10 -> 5 | E9: =ROB!F10 -> 3 | F9: =FUE!F10 -> 3 | G9: =ANG!F10 -> 4 | H9: =AERO!F10 -> 3 | I9: =SUM(C9:H9) -> 22
B10: Efect. | C10: =+C9/C8 -> 1 | D10: =+D9/D8 -> 1 | E10: =+E9/E8 -> 1 | F10: =+F9/F8 -> 1 | G10: =+G9/G8 -> 1 | H10: =+H9/H8 -> 1 | I10: =AVERAGE(C10:G10) -> 1
A11: TECLADOS | B11: Inv. Ideal | C11: =CON!D11 -> 4 | D11: =PLA!D11 -> 5 | E11: =ROB!D11 -> 3 | F11: =FUE!D11 -> 3 | G11: =ANG!D11 -> 4 | H11: =AERO!E11 -> 3 | I11: =SUM(C11:H11) -> 22
B12: Inv. Real | C12: =CON!E11 -> 4 | D12: =PLA!E11 -> 5 | E12: =ROB!E11 -> 3 | F12: =FUE!E11 -> 3 | G12: =ANG!E11 -> 4 | H12: =AERO!F11 -> 3 | I12: =SUM(C12:H12) -> 22
B13: Equi. Ope. | C13: =CON!F11 -> 4 | D13: =PLA!F11 -> 5 | E13: =ROB!F11 -> 3 | F13: =FUE!F11 -> 3 | G13: =ANG!F11 -> 4 | H13: =AERO!F11 -> 3 | I13: =SUM(C13:H13) -> 22
B14: Efect. | C14: =+C13/C12 -> 1 | D14: =+D13/D12 -> 1 | E14: =+E13/E12 -> 1 | F14: =+F13/F12 -> 1 | G14: =+G13/G12 -> 1 | H14: =+H13/H12 -> 1 | I14: =AVERAGE(C14:G14) -> 1
A15: MONITORES | B15: Inv. Ideal | C15: =CON!D12 -> 4 | D15: =PLA!D12 -> 5 | E15: =ROB!D12 -> 3 | F15: =FUE!D12 -> 3 | G15: =ANG!D12 -> 4 | H15: =AERO!E12 -> 3 | I15: =SUM(C15:H15) -> 22
B16: Inv. Real | C16: =CON!E12 -> 4 | D16: =PLA!E12 -> 5 | E16: =ROB!E12 -> 3 | F16: =FUE!E12 -> 3 | G16: =ANG!E12 -> 4 | H16: =AERO!F12 -> 3 | I16: =SUM(C16:H16) -> 22
B17: Equi. Ope. | C17: =CON!F12 -> 4 | D17: =PLA!F12 -> 5 | E17: =ROB!F12 -> 3 | F17: =FUE!F12 -> 3 | G17: =ANG!F12 -> 4 | H17: =AERO!F12 -> 3 | I17: =SUM(C17:H17) -> 22
B18: Efect. | C18: =+C17/C16 -> 1 | D18: =+D17/D16 -> 1 | E18: =+E17/E16 -> 1 | F18: =+F17/F16 -> 1 | G18: =+G17/G16 -> 1 | H18: =+H17/H16 -> 1 | I18: =AVERAGE(C18:G18) -> 1
A19: REGULADORES | B19: Inv. Ideal | C19: =CON!D13 -> 4 | D19: =PLA!D13 -> 5 | E19: =ROB!D13 -> 3 | F19: =FUE!D13 -> 3 | G19: =ANG!D13 -> 4 | H19: =AERO!E13 -> 3 | I19: =SUM(C19:H19) -> 22
B20: Inv. Real | C20: =CON!E13 -> 4 | D20: =PLA!E13 -> 5 | E20: =ROB!E13 -> 3 | F20: =FUE!E13 -> 3 | G20: =ANG!E13 -> 4 | H20: =AERO!F13 -> 3 | I20: =SUM(C20:H20) -> 22
B21: Equi. Ope. | C21: =CON!F13 -> 4 | D21: =PLA!F13 -> 5 | E21: =ROB!F13 -> 3 | F21: =FUE!F13 -> 3 | G21: =ANG!F13 -> 4 | H21: =AERO!F13 -> 3 | I21: =SUM(C21:H21) -> 22
B22: Efect. | C22: =+C21/C20 -> 1 | D22: =+D21/D20 -> 1 | E22: =+E21/E20 -> 1 | F22: =+F21/F20 -> 1 | G22: =+G21/G20 -> 1 | H22: =+H21/H20 -> 1 | I22: =AVERAGE(C22:G22) -> 1
A23: IMPRESORA MULTIFUNCIONAL | B23: Inv. Ideal | C23: =CON!D14 -> 1 | D23: =PLA!D14 -> 1 | E23: =ROB!D14 -> 1 | F23: =FUE!D14 -> 1 | G23: =ANG!D14 -> 1 | H23: =AERO!E14 -> 1 | I23: =SUM(C23:H23) -> 6
B24: Inv. Real | C24: =CON!E14 -> 1 | D24: =PLA!E14 -> 1 | E24: =ROB!E14 -> 1 | F24: =FUE!E14 -> 1 | G24: =ANG!E14 -> 1 | H24: =AERO!F14 -> 1 | I24: =SUM(C24:H24) -> 6
B25: Equi. Ope. | C25: =CON!F14 -> 1 | D25: =PLA!F14 -> 1 | E25: =ROB!F14 -> 1 | F25: =FUE!F14 -> 1 | G25: =ANG!F14 -> 1 | H25: =AERO!F14 -> 1 | I25: =SUM(C25:H25) -> 6
B26: Efect. | C26: =+C25/C24 -> 1 | D26: =+D25/D24 -> 1 | E26: =+E25/E24 -> 1 | F26: =+F25/F24 -> 1 | G26: =+G25/G24 -> 1 | H26: =+H25/H24 -> 1 | I26: =AVERAGE(C26:G26) -> 1
A27: IMPRESORAS FISCALES | B27: Inv. Ideal | C27: =CON!D15 -> 3 | D27: =PLA!D15 -> 4 | E27: =ROB!D15 -> 3 | F27: =FUE!D15 -> 2 | G27: =ANG!D15 -> 3 | H27: =AERO!D15 -> 2 | I27: =SUM(C27:H27) -> 17
B28: Inv. Real | C28: =CON!E15 -> 3 | D28: =PLA!E15 -> 4 | E28: =ROB!E15 -> 3 | F28: =FUE!E15 -> 2 | G28: =ANG!E15 -> 3 | H28: =AERO!E15 -> 2 | I28: =SUM(C28:H28) -> 17
B29: Equi. Ope. | C29: =CON!F15 -> 3 | D29: =PLA!F15 -> 4 | E29: =ROB!F15 -> 3 | F29: =FUE!F15 -> 2 | G29: =ANG!F15 -> 3 | H29: =AERO!F15 -> 2 | I29: =SUM(C29:H29) -> 17
B30: Efect. | C30: =+C29/C28 -> 1 | D30: =+D29/D28 -> 1 | E30: =+E29/E28 -> 1 | F30: =+F29/F28 -> 1 | G30: =+G29/G27 -> 1 | H30: =+H29/H27 -> 1 | I30: =AVERAGE(C30:G30) -> 1
A31: ROUTER | B31: Inv. Ideal | C31: =CON!D23 -> 1 | D31: =PLA!D23 -> 2 | E31: =ROB!D23 -> 1 | F31: =FUE!D23 -> 1 | G31: =ANG!D23 -> 1 | H31: =AERO!D23 -> 1 | I31: =SUM(C31:H31) -> 7
B32: Inv. Real | C32: =CON!E23 -> 1 | D32: =PLA!E23 -> 2 | E32: =ROB!E23 -> 1 | F32: =FUE!E23 -> 1 | G32: =ANG!E23 -> 1 | H32: =AERO!E23 -> 1 | I32: =SUM(C32:H32) -> 7
B33: Equi. Ope. | C33: =CON!F23 -> 1 | D33: =PLA!F23 -> 2 | E33: =ROB!F23 -> 1 | F33: =FUE!F23 -> 1 | G33: =ANG!F23 -> 1 | H33: =AERO!F23 -> 1 | I33: =SUM(C33:H33) -> 7
B34: Efect. | C34: =+C33/C32 -> 1 | D34: =+D33/D32 -> 1 | E34: =+E33/E32 -> 1 | F34: =+F33/F32 -> 1 | G34: =+G33/G32 -> 1 | H34: =+H33/H32 -> 1 | I34: =+I33/I32 -> 1
A35: SUICHE | B35: Inv. Ideal | C35: =CON!D24 -> 1 | D35: =PLA!D24 -> 2 | E35: =ROB!D24 -> 1 | F35: =FUE!D24 -> 1 | G35: =ANG!D24 -> 1 | H35: =AERO!D24 -> 1 | I35: =SUM(C35:H35) -> 7
B36: Inv. Real | C36: =CON!E24 -> 1 | D36: =PLA!E24 -> 2 | E36: =ROB!E24 -> 1 | F36: =FUE!E24 -> 1 | G36: =ANG!E24 -> 1 | H36: =AERO!E24 -> 1 | I36: =SUM(C36:H36) -> 7
B37: Equi. Ope. | C37: =CON!F24 -> 1 | D37: =PLA!F24 -> 2 | E37: =ROB!F24 -> 1 | F37: =FUE!F24 -> 1 | G37: =ANG!F24 -> 1 | H37: =AERO!F24 -> 1 | I37: =SUM(C37:H37) -> 7
B38: Efect. | C38: =+C37/C36 -> 1 | D38: =+D37/D36 -> 1 | E38: =+E37/E36 -> 1 | F38: =+F37/F36 -> 1 | G38: =+G37/G36 -> 1 | H38: =+H37/H36 -> 1 | I38: =AVERAGE(C38:G38) -> 1
A39: ESCANER DE CODIGO DE BARRAS | B39: Inv. Ideal | C39: =CON!D25 -> 4 | D39: =PLA!D25 -> 6 | E39: =ROB!D25 -> 3 | F39: =FUE!D25 -> 3 | G39: =ANG!D25 -> 4 | H39: =AERO!D25 -> 4 | I39: =SUM(C39:H39) -> 24
B40: Inv. Real | C40: =CON!E25 -> 4 | D40: =PLA!E25 -> 6 | E40: =ROB!E25 -> 3 | F40: =FUE!E25 -> 3 | G40: =ANG!E25 -> 4 | H40: =AERO!F25 -> 4 | I40: =SUM(C40:H40) -> 24
...

Sheet MAESTRO
A1: ******SUCURSALES
A2: LA CASA DE LA CAÑA, C.A. (T. ALTERNA)
A3: LA CASA DE LA CAÑA, C.A. (T. ANACO)
A4: LA CASA DE LA CAÑA, C.A. (T. CUMANÁ)
A5: LA CASA DE LA CAÑA, C.A. (T. MATURÍN I)
A6: LA CASA DE LA CAÑA, C.A. (T. MATURÍN II)
A7: LA CASA DE LA CAÑA, C.A. (T. NVA. BARCELONA)
A8: INVERSIONES CAÑANDONGA,C.A (T. CONEJERO)
A9: OPERADORA EL MERCADO 2011, C.A. (T. MERCADO)
A10: OPERADORA EL PUENTE 2011, C.A. (T. PUENTE REAL)
A11: OPERADORA LECHERÍA 2011, C.A. (T. LECHERÍA)
A12: OPERADORA PUERTO LA CRUZ 2011, C.A. (T. PUERTO LA CRUZ)
... A19: RELIVE, C.A. (T. TIGRE III)

Sheet Hoja2

Sheet Hoja1
