Workbook
Name CUMPLIO: #REF!
Name CUMPLIO: #REF!
Name CUMPLIO: #REF!
Name CUMPLIO: #REF!
Name CUMPLIO: #REF!
Name CUMPLIO: #REF!
Name CUMPLIO: #REF!
Name CUMPLIO: #REF!
Name CUMPLIO: #REF!
Name CUMPLIO: #REF!
Name CUMPLIO: #REF!
Name CUMPLIO: #REF!
Name CUMPLIO: #REF!
Name CUMPLIO: #REF!
Name CUMPLIO: #REF!
Name CUMPLIO: #REF!
Name CUMPLIO: #REF!
Name CUMPLIO: #REF!
Name CUMPLIO: #REF!
Name CUMPLIO: #REF!
Name CUMPLIO: #REF!
Name EQUIPO: #REF!
Name EQUIPO: #REF!
Name EQUIPO: #REF!
Name EQUIPO: #REF!
Name EQUIPO: #REF!
Name EQUIPO: #REF!
Name EQUIPO: #REF!
Name EQUIPO: #REF!
Name EQUIPO: #REF!
Name EQUIPO: #REF!
Name EQUIPO: #REF!
Name EQUIPO: #REF!
Name EQUIPO: #REF!
Name EQUIPO: #REF!
Name EQUIPO: #REF!
Name EQUIPO: #REF!
Name EQUIPO: #REF!
Name EQUIPO: #REF!
Name EQUIPO: #REF!
Name EQUIPO: #REF!
Name EQUIPO: #REF!
Name EQUIPOS: #REF!
Name EQUIPOS: #REF!
Name EQUIPOS: #REF!
Name EQUIPOS: #REF!
Name EQUIPOS: #REF!
Name EQUIPOS: #REF!
Name EQUIPOS: #REF!
Name EQUIPOS: #REF!
Name EQUIPOS: #REF!
Name EQUIPOS: #REF!
Name EQUIPOS: #REF!
Name EQUIPOS: #REF!
Name EQUIPOS: #REF!
Name EQUIPOS: #REF!
Name EQUIPOS: #REF!
Name EQUIPOS: #REF!
Name EQUIPOS: #REF!
Name EQUIPOS: #REF!

Sheet ALT
C1: CHECK LIST DE EXISTENCIA DE EQUIPOS EN TIENDAS | I1: Código: | J1: FO-MIS-03
I2: Revisión: | J2: 07 | K2: 42720
I3: Fecha: | J3: 42286
B5: SUCURSAL: | C5: LA CASA DE LA CAÑA, C.A. (T. ALTERNA) | H5: FECHA: | I5: 46157
A7: EQUIPOS
A8: Nº | B8: EQUIPOS | D8: INVENTARIO IDEAL | E8: INVENTARIO REAL | F8: EQUIPOS OPERATIVOS | G8: EFECTIVIDAD | H8: OBSERVACIONES
A9: 1 | B9: CPU | D9: 5 | E9: 5 | F9: 5 | G9: =IF(D9="","",IF(D9=0,"-",IF(F9>D9,"ERROR",IF(E9>D9,"ERROR",IF(E9<D9,0,IF(E9>F9,0,IF(F9=D9,1,0))))))) -> 1 | V9: LA CASA DE LA CAÑA, C.A. (T. ALTERNA)
A10: 2 | B10: MOUSE | D10: 5 | E10: 5 | F10: 5 | G10: =IF(D10="","",IF(D10=0,"-",IF(F10>D10,"ERROR",IF(E10>D10,"ERROR",IF(E10<D10,0,IF(E10>F10,0,IF(F10=D10,1,0))))))) -> 1 | V10: LA CASA DE LA CAÑA, C.A. (T. ANACO)
A11: 3 | B11: TECLADOS | D11: 5 | E11: 5 | F11: 5 | G11: =IF(D11="","",IF(D11=0,"-",IF(F11>D11,"ERROR",IF(E11>D11,"ERROR",IF(E11<D11,0,IF(E11>F11,0,IF(F11=D11,1,0))))))) -> 1 | V11: LA CASA DE LA CAÑA, C.A. (T. NVA BARCELONA)
A12: 4 | B12: MONITORES | D12: 5 | E12: 5 | F12: 5 | G12: =IF(D12="","",IF(D12=0,"-",IF(F12>D12,"ERROR",IF(E12>D12,"ERROR",IF(E12<D12,0,IF(E12>F12,0,IF(F12=D12,1,0))))))) -> 1 | V12: LA CASA DE LA CAÑA, C.A. (T. CUMANA)
A13: 5 | B13: REGULADORES | D13: 5 | E13: 5 | F13: 5 | G13: =IF(D13="","",IF(D13=0,"-",IF(F13>D13,"ERROR",IF(E13>D13,"ERROR",IF(E13<D13,0,IF(E13>F13,0,IF(F13=D13,1,0))))))) -> 1 | V13: LA CASA DE LA CAÑA, C.A. (T. MATURIN I)
A14: 6 | B14: IMPRESORA MULTIFUNCIONAL | D14: 1 | E14: 1 | F14: 1 | G14: =IF(D14="","",IF(D14=0,"-",IF(F14>D14,"ERROR",IF(E14>D14,"ERROR",IF(E14<D14,0,IF(E14>F14,0,IF(F14=D14,1,0))))))) -> 1 | V14: LA CASA DE LA CAÑA, C.A. (T. MATURIN II)
A15: 7 | B15: IMPRESORAS FISCALES | D15: 3 | E15: 3 | F15: 3 | G15: =IF(D15="","",IF(D15=0,"-",IF(F15>D15,"ERROR",IF(E15>D15,"ERROR",IF(E15<D15,0,IF(E15>F15,0,IF(F15=D15,1,0))))))) -> 1 | H15: SERIAL 1: | J15: Nº ULT. REPORTE Z: | V15: LA CASA DE LA CAÑA, C.A. (T. FREITES)
H16: SERIAL 2: | J16: Nº ULT. REPORTE Z: | V16: LA CASA DE LA CAÑA, C.A. (T. PUENTE)
H17: SERIAL 3: | J17: Nº ULT. REPORTE Z: | V17: RELIVE, C.A. (T. CHUPARIN)
H18: SERIAL 4: | J18: Nº ULT. REPORTE Z: | V18: RELIVE, C.A. (T. TERRAZAS)
H19: SERIAL 5: | J19: Nº ULT. REPORTE Z: | V19: RELIVE, C.A. (T. TIGRE II)
H20: SERIAL 6: | J20: Nº ULT. REPORTE Z: | V20: RELIVE, C.A. (T. TIGRE III)
H21: SERIAL 7: | J21: Nº ULT. REPORTE Z: | V21: RELIVE, C.A. (T. PLC)
V22: RELIVE, C.A. (T. POZUELOS)
A23: 8 | B23: ROUTER | D23: 1 | E23: 1 | F23: 1 | G23: =IF(D23="","",IF(D23=0,"-",IF(F23>D23,"ERROR",IF(E23>D23,"ERROR",IF(E23<D23,0,IF(E23>F23,0,IF(F23=D23,1,0))))))) -> 1 | V23: OPERADORA VENECIA 2021, C.A (T. VENECIA)
A24: 9 | B24: SUICHE | D24: 2 | E24: 2 | F24: 2 | G24: =IF(D24="","",IF(D24=0,"-",IF(F24>D24,"ERROR",IF(E24>D24,"ERROR",IF(E24<D24,0,IF(E24>F24,0,IF(F24=D24,1,0))))))) -> 1 | V24: OPERADORA VENECIA 2021, C.A (T. BOLIVAR PLC)
A25: 10 | B25: ESCANER DE CODIGO DE BARRAS | D25: 5 | E25: 5 | F25: 5 | G25: =IF(D25="","",IF(D25=0,"-",IF(F25>D25,"ERROR",IF(E25>D25,"ERROR",IF(E25<D25,0,IF(E25>F25,0,IF(F25=D25,1,0))))))) -> 1 | V25: OPERADORA VENECIA 2021, C.A (T. CHURCHILL)
A26: 11 | B26: VISOR DE VENTAS | D26: 2 | E26: 2 | F26: 2 | G26: =IF(D26="","",IF(D26=0,"-",IF(F26>D26,"ERROR",IF(E26>D26,"ERROR",IF(E26<D26,0,IF(E26>F26,0,IF(F26=D26,1,0))))))) -> 1 | V26: OPERADORA VENECIA 2021, C.A (T. MANSION)
A27: 12 | B27: DVR | D27: 1 | E27: 1 | F27: 1 | G27: =IF(D27="","",IF(D27=0,"-",IF(F27>D27,"ERROR",IF(E27>D27,"ERROR",IF(E27<D27,0,IF(E27>F27,0,IF(F27=D27,1,0))))))) -> 1 | V27: OPERADORA LECHERIA 2011, C.A
A28: 13 | B28: MODEM | D28: 1 | E28: 1 | F28: 1 | G28: =IF(D28="","",IF(D28=0,"-",IF(F28>D28,"ERROR",IF(E28>D28,"ERROR",IF(E28<D28,0,IF(E28>F28,0,IF(F28=D28,1,0))))))) -> 1
A29: 14 | B29: LIBROS DE IMPRESORAS FISCALES | D29: 3 | E29: 3 | F29: 3 | G29: =IF(D29="","",IF(D29=0,"-",IF(F29>D29,"ERROR",IF(E29>D29,"ERROR",IF(E29<D29,0,IF(E29>F29,0,IF(F29=D29,1,0))))))) -> 1
A30: TOTAL DE EFECTIVIDAD DE EQUIPOS | G30: =IFERROR(AVERAGE(G10:G29),"-") -> 1
A31: Realizado Por: | C31: Orliannys Bello
A32: Cargo | C32: Lider de Tienda
A34: NOTA: El check list de Existencia de Equipos en Tiendas debe ser enviado entre los 5 primeros días del mes, vía correo electrónico al grupo Sistemas, con copia al Director de Servicios de Control.
L39: HOUSE TICKET | M39: INVENTARIO | N39: CABLEADO | O39: MES
L40: SI | M40: 0 | N40: SI | O40: ENERO
L41: NO | M41: 1 | N41: NO | O41: FEBRERO
M42: 2 | O42: MARZO
M43: 3 | O43: ABRIL
M44: 4 | O44: MAYO
M45: 5 | O45: JUNIO
M46: 6 | O46: JULIO
M47: 7 | O47: AGOSTO
...

Sheet ANA
C1: CHECK LIST DE EXISTENCIA DE EQUIPOS EN TIENDAS | I1: Código: | J1: FO-MIS-03
I2: Revisión: | J2: 07 | K2: 42720
I3: Fecha: | J3: 42286
B5: SUCURSAL: | C5: LA CASA DE LA CAÑA, C.A. (T. ANACO) | H5: FECHA: | I5: 46157
A7: EQUIPOS
A8: Nº | B8: EQUIPOS | D8: INVENTARIO IDEAL | E8: INVENTARIO REAL | F8: EQUIPOS OPERATIVOS | G8: EFECTIVIDAD | H8: OBSERVACIONES
A9: 1 | B9: CPU | D9: 4 | E9: 4 | F9: 4 | G9: =IF(D9="","",IF(D9=0,"-",IF(F9>D9,"ERROR",IF(E9>D9,"ERROR",IF(E9<D9,0,IF(E9>F9,0,IF(F9=D9,1,0))))))) -> 1 | U9: LA CASA DE LA CAÑA, C.A. (T. ALTERNA)
A10: 2 | B10: MOUSE | D10: 4 | E10: 4 | F10: 4 | G10: =IF(D10="","",IF(D10=0,"-",IF(F10>D10,"ERROR",IF(E10>D10,"ERROR",IF(E10<D10,0,IF(E10>F10,0,IF(F10=D10,1,0))))))) -> 1 | U10: LA CASA DE LA CAÑA, C.A. (T. ANACO)
A11: 3 | B11: TECLADOS | D11: 4 | E11: 4 | F11: 4 | G11: =IF(D11="","",IF(D11=0,"-",IF(F11>D11,"ERROR",IF(E11>D11,"ERROR",IF(E11<D11,0,IF(E11>F11,0,IF(F11=D11,1,0))))))) -> 1 | U11: LA CASA DE LA CAÑA, C.A. (T. NVA BARCELONA)
A12: 4 | B12: MONITORES | D12: 4 | E12: 4 | F12: 4 | G12: =IF(D12="","",IF(D12=0,"-",IF(F12>D12,"ERROR",IF(E12>D12,"ERROR",IF(E12<D12,0,IF(E12>F12,0,IF(F12=D12,1,0))))))) -> 1 | U12: LA CASA DE LA CAÑA, C.A. (T. CUMANA)
A13: 5 | B13: REGULADORES | D13: 4 | E13: 4 | F13: 4 | G13: =IF(D13="","",IF(D13=0,"-",IF(F13>D13,"ERROR",IF(E13>D13,"ERROR",IF(E13<D13,0,IF(E13>F13,0,IF(F13=D13,1,0))))))) -> 1 | U13: LA CASA DE LA CAÑA, C.A. (T. MATURIN I)
A14: 6 | B14: IMPRESORA MULTIFUNCIONAL | D14: 1 | E14: 1 | F14: 1 | G14: =IF(D14="","",IF(D14=0,"-",IF(F14>D14,"ERROR",IF(E14>D14,"ERROR",IF(E14<D14,0,IF(E14>F14,0,IF(F14=D14,1,0))))))) -> 1 | U14: LA CASA DE LA CAÑA, C.A. (T. MATURIN II)
A15: 7 | B15: IMPRESORAS FISCALES | D15: 3 | E15: 3 | F15: 3 | G15: =IF(D15="","",IF(D15=0,"-",IF(F15>D15,"ERROR",IF(E15>D15,"ERROR",IF(E15<D15,0,IF(E15>F15,0,IF(F15=D15,1,0))))))) -> 1 | H15: SERIAL 1: | J15: Nº ULT. REPORTE Z: | U15: LA CASA DE LA CAÑA, C.A. (T. FREITES)
H16: SERIAL 2: | J16: Nº ULT. REPORTE Z: | U16: LA CASA DE LA CAÑA, C.A. (T. PUENTE)
H17: SERIAL 3: | J17: Nº ULT. REPORTE Z: | U17: RELIVE, C.A. (T. CHUPARIN)
H18: SERIAL 4: | J18: Nº ULT. REPORTE Z: | U18: RELIVE, C.A. (T. TERRAZAS)
H19: SERIAL 5: | J19: Nº ULT. REPORTE Z: | U19: RELIVE, C.A. (T. TIGRE II)
H20: SERIAL 6: | J20: Nº ULT. REPORTE Z: | U20: RELIVE, C.A. (T. TIGRE III)
H21: SERIAL 7: | J21: Nº ULT. REPORTE Z: | U21: RELIVE, C.A. (T. PLC)
U22: RELIVE, C.A. (T. POZUELOS)
A23: 8 | B23: ROUTER | D23: 1 | E23: 1 | F23: 1 | G23: =IF(D23="","",IF(D23=0,"-",IF(F23>D23,"ERROR",IF(E23>D23,"ERROR",IF(E23<D23,0,IF(E23>F23,0,IF(F23=D23,1,0))))))) -> 1 | U23: OPERADORA VENECIA 2021, C.A (T. VENECIA)
A24: 9 | B24: SUICHE | D24: 1 | E24: 1 | F24: 1 | G24: =IF(D24="","",IF(D24=0,"-",IF(F24>D24,"ERROR",IF(E24>D24,"ERROR",IF(E24<D24,0,IF(E24>F24,0,IF(F24=D24,1,0))))))) -> 1 | U24: OPERADORA VENECIA 2021, C.A (T. BOLIVAR PLC)
A25: 10 | B25: ESCANER DE CODIGO DE BARRAS | D25: 4 | E25: 4 | F25: 4 | G25: =IF(D25="","",IF(D25=0,"-",IF(F25>D25,"ERROR",IF(E25>D25,"ERROR",IF(E25<D25,0,IF(E25>F25,0,IF(F25=D25,1,0))))))) -> 1 | U25: OPERADORA VENECIA 2021, C.A (T. CHURCHILL)
A26: 11 | B26: VISOR DE VENTA | D26: 2 | E26: 2 | F26: 2 | G26: =IF(D26="","",IF(D26=0,"-",IF(F26>D26,"ERROR",IF(E26>D26,"ERROR",IF(E26<D26,0,IF(E26>F26,0,IF(F26=D26,1,0))))))) -> 1 | U26: OPERADORA VENECIA 2021, C.A (T. MANSION)
A27: 12 | B27: DVR | D27: 1 | E27: 1 | F27: 1 | G27: =IF(D27="","",IF(D27=0,"-",IF(F27>D27,"ERROR",IF(E27>D27,"ERROR",IF(E27<D27,0,IF(E27>F27,0,IF(F27=D27,1,0))))))) -> 1 | U27: OPERADORA LECHERIA 2011, C.A
A28: 13 | B28: MODEM | D28: 1 | E28: 1 | F28: 1 | G28: =IF(D28="","",IF(D28=0,"-",IF(F28>D28,"ERROR",IF(E28>D28,"ERROR",IF(E28<D28,0,IF(E28>F28,0,IF(F28=D28,1,0))))))) -> 1
A29: 14 | B29: LIBROS DE IMPRESORAS FISCALES | D29: 3 | E29: 3 | F29: 3 | G29: =IF(D29="","",IF(D29=0,"-",IF(F29>D29,"ERROR",IF(E29>D29,"ERROR",IF(E29<D29,0,IF(E29>F29,0,IF(F29=D29,1,0))))))) -> 1
A30: TOTAL DE EFECTIVIDAD DE EQUIPOS | G30: =IFERROR(AVERAGE(G10:G29),"-") -> 1
A31: Realizado Por: | C31: Rudiannys Lopez
A32: Cargo | C32: Lider De Tienda
A34: NOTA: El check list de Existencia de Equipos en Tiendas debe ser enviado entre los 5 primeros días del mes, vía correo electrónico al grupo Sistemas, con copia al Director de Servicios de Control.
L38: HOUSE TICKET | M38: INVENTARIO | N38: CABLEADO | O38: MES
L39: SI | M39: 0 | N39: SI | O39: ENERO
L40: NO | M40: 1 | N40: NO | O40: FEBRERO
M41: 2 | O41: MARZO
M42: 3 | O42: ABRIL
M43: 4 | O43: MAYO
M44: 5 | O44: JUNIO
M45: 6 | O45: JULIO
M46: 7 | O46: AGOSTO
...

Sheet CUM
C1: CHECK LIST DE EXISTENCIA DE EQUIPOS EN TIENDAS | I1: Código: | J1: FO-MIS-03
I2: Revisión: | J2: 07 | K2: 42720
I3: Fecha: | J3: 42286
B5: SUCURSAL: | C5: LA CASA DE LA CAÑA, C.A. (T. CUMANA) | H5: FECHA: | I5: 46157
A7: EQUIPOS
A8: Nº | B8: EQUIPOS | D8: INVENTARIO IDEAL | E8: INVENTARIO REAL | F8: EQUIPOS OPERATIVOS | G8: EFECTIVIDAD | H8: OBSERVACIONES
A9: 1 | B9: CPU | D9: 5 | E9: 5 | F9: 5 | G9: =IF(D9="","",IF(D9=0,"-",IF(F9>D9,"ERROR",IF(E9>D9,"ERROR",IF(E9<D9,0,IF(E9>F9,0,IF(F9=D9,1,0))))))) -> 1 | O9: LA CASA DE LA CAÑA, C.A. (T. ALTERNA)
A10: 2 | B10: MOUSE | D10: 5 | E10: 5 | F10: 5 | G10: =IF(D10="","",IF(D10=0,"-",IF(F10>D10,"ERROR",IF(E10>D10,"ERROR",IF(E10<D10,0,IF(E10>F10,0,IF(F10=D10,1,0))))))) -> 1 | O10: LA CASA DE LA CAÑA, C.A. (T. ANACO)
A11: 3 | B11: TECLADOS | D11: 5 | E11: 5 | F11: 5 | G11: =IF(D11="","",IF(D11=0,"-",IF(F11>D11,"ERROR",IF(E11>D11,"ERROR",IF(E11<D11,0,IF(E11>F11,0,IF(F11=D11,1,0))))))) -> 1 | O11: LA CASA DE LA CAÑA, C.A. (T. NVA BARCELONA)
A12: 4 | B12: MONITORES | D12: 5 | E12: 5 | F12: 5 | G12: =IF(D12="","",IF(D12=0,"-",IF(F12>D12,"ERROR",IF(E12>D12,"ERROR",IF(E12<D12,0,IF(E12>F12,0,IF(F12=D12,1,0))))))) -> 1 | O12: LA CASA DE LA CAÑA, C.A. (T. CUMANA)
A13: 5 | B13: REGULADORES | D13: 5 | E13: 5 | F13: 5 | G13: =IF(D13="","",IF(D13=0,"-",IF(F13>D13,"ERROR",IF(E13>D13,"ERROR",IF(E13<D13,0,IF(E13>F13,0,IF(F13=D13,1,0))))))) -> 1 | O13: LA CASA DE LA CAÑA, C.A. (T. MATURIN I)
A14: 6 | B14: IMPRESORA MULTIFUNCIONAL | D14: 1 | E14: 1 | F14: 1 | G14: =IF(D14="","",IF(D14=0,"-",IF(F14>D14,"ERROR",IF(E14>D14,"ERROR",IF(E14<D14,0,IF(E14>F14,0,IF(F14=D14,1,0))))))) -> 1 | O14: LA CASA DE LA CAÑA, C.A. (T. MATURIN II)
A15: 7 | B15: IMPRESORAS FISCALES | D15: 4 | E15: 4 | F15: 4 | G15: =IF(D15="","",IF(D15=0,"-",IF(F15>D15,"ERROR",IF(E15>D15,"ERROR",IF(E15<D15,0,IF(E15>F15,0,IF(F15=D15,1,0))))))) -> 1 | H15: SERIAL 1: | J15: Nº ULT. REPORTE Z: | O15: LA CASA DE LA CAÑA, C.A. (T. FREITES)
H16: SERIAL 2: | J16: Nº ULT. REPORTE Z: | O16: LA CASA DE LA CAÑA, C.A. (T. PUENTE)
H17: SERIAL 3: | J17: Nº ULT. REPORTE Z: | O17: RELIVE, C.A. (T. CHUPARIN)
H18: SERIAL 4: | J18: Nº ULT. REPORTE Z: | O18: RELIVE, C.A. (T. TERRAZAS)
H19: SERIAL 5: | J19: Nº ULT. REPORTE Z: | O19: RELIVE, C.A. (T. TIGRE II)
H20: SERIAL 6: | J20: Nº ULT. REPORTE Z: | O20: RELIVE, C.A. (T. TIGRE III)
H21: SERIAL 7: | J21: Nº ULT. REPORTE Z: | O21: RELIVE, C.A. (T. PLC)
O22: RELIVE, C.A. (T. POZUELOS)
A23: 8 | B23: ROUTER | D23: 1 | E23: 1 | F23: 1 | G23: =IF(D23="","",IF(D23=0,"-",IF(F23>D23,"ERROR",IF(E23>D23,"ERROR",IF(E23<D23,0,IF(E23>F23,0,IF(F23=D23,1,0))))))) -> 1 | O23: OPERADORA VENECIA 2021, C.A (T. VENECIA)
A24: 9 | B24: SUICHE | D24: 1 | E24: 1 | F24: 1 | G24: =IF(D24="","",IF(D24=0,"-",IF(F24>D24,"ERROR",IF(E24>D24,"ERROR",IF(E24<D24,0,IF(E24>F24,0,IF(F24=D24,1,0))))))) -> 1 | O24: OPERADORA VENECIA 2021, C.A (T. BOLIVAR PLC)
A25: 10 | B25: ESCANER DE CODIGO DE BARRAS | D25: 5 | E25: 5 | F25: 5 | G25: =IF(D25="","",IF(D25=0,"-",IF(F25>D25,"ERROR",IF(E25>D25,"ERROR",IF(E25<D25,0,IF(E25>F25,0,IF(F25=D25,1,0))))))) -> 1 | O25: OPERADORA VENECIA 2021, C.A (T. CHURCHILL)
A26: 11 | B26: VISOR DE VENTA | D26: 2 | E26: 2 | F26: 2 | G26: =IF(D26="","",IF(D26=0,"-",IF(F26>D26,"ERROR",IF(E26>D26,"ERROR",IF(E26<D26,0,IF(E26>F26,0,IF(F26=D26,1,0))))))) -> 1 | O26: OPERADORA VENECIA 2021, C.A (T. MANSION)
A27: 12 | B27: DVR | D27: 1 | E27: 1 | F27: 1 | G27: =IF(D27="","",IF(D27=0,"-",IF(F27>D27,"ERROR",IF(E27>D27,"ERROR",IF(E27<D27,0,IF(E27>F27,0,IF(F27=D27,1,0))))))) -> 1 | O27: OPERADORA LECHERIA 2011, C.A
A28: 13 | B28: MODEM | D28: 1 | E28: 1 | F28: 1 | G28: =IF(D28="","",IF(D28=0,"-",IF(F28>D28,"ERROR",IF(E28>D28,"ERROR",IF(E28<D28,0,IF(E28>F28,0,IF(F28=D28,1,0))))))) -> 1
A29: 14 | B29: LIBROS DE IMPRESORAS FISCALES | D29: 4 | E29: 4 | F29: 4 | G29: =IF(D29="","",IF(D29=0,"-",IF(F29>D29,"ERROR",IF(E29>D29,"ERROR",IF(E29<D29,0,IF(E29>F29,0,IF(F29=D29,1,0))))))) -> 1
A30: TOTAL DE EFECTIVIDAD DE EQUIPOS | G30: =IFERROR(AVERAGE(G9:G28),"-") -> 1
A32: Realizado Por: | C32: Pablo Lunar
A33: Cargo | C33: Lider De Ttienda
A35: NOTA: El check list de Existencia de Equipos en Tiendas debe ser enviado entre los 5 primeros días del mes, vía correo electrónico al grupo Sistemas, con copia al Director de Servicios de Control.
L39: HOUSE TICKET | M39: INVENTARIO | N39: CABLEADO | O39: MES
K40: TIENDAS | L40: SI | M40: 0 | N40: SI | O40: ENERO
K41: =IF(MAESTRO!A1="","",MAESTRO!A1) -> ******SUCURSALES | L41: NO | M41: 1 | N41: NO | O41: FEBRERO
K42: =IF(MAESTRO!A2="","",MAESTRO!A2) -> LA CASA DE LA CAÑA, C.A. (T. ALTERNA) | M42: 2 | O42: MARZO
K43: =IF(MAESTRO!A3="","",MAESTRO!A3) -> LA CASA DE LA CAÑA, C.A. (T. ANACO) | M43: 3 | O43: ABRIL
K44: =IF(MAESTRO!A4="","",MAESTRO!A4) -> LA CASA DE LA CAÑA, C.A. (T. CUMANÁ) | M44: 4 | O44: MAYO
K45: =IF(MAESTRO!A5="","",MAESTRO!A5) -> LA CASA DE LA CAÑA, C.A. (T. MATURÍN I) | M45: 5 | O45: JUNIO
K46: =IF(MAESTRO!A6="","",MAESTRO!A6) -> LA CASA DE LA CAÑA, C.A. (T. MATURÍN II) | M46: 6 | O46: JULIO
K47: =IF(MAESTRO!A7="","",MAESTRO!A7) -> LA CASA DE LA CAÑA, C.A. (T. NVA. BARCELONA) | M47: 7 | O47: AGOSTO
...

Sheet MAT I
C1: CHECK LIST DE EXISTENCIA DE EQUIPOS EN TIENDAS | I1: Código: | J1: FO-MIS-03
I2: Revisión: | J2: 07 | K2: 42720
I3: Fecha: | J3: 42286
B5: SUCURSAL: | C5: LA CASA DE LA CAÑA, C.A. (T. MATURIN I) | H5: FECHA: | I5: 46157
A7: EQUIPOS
A8: Nº | B8: EQUIPOS | D8: INVENTARIO IDEAL | E8: INVENTARIO REAL | F8: EQUIPOS OPERATIVOS | G8: EFECTIVIDAD | H8: OBSERVACIONES
A9: 1 | B9: CPU | D9: 5 | E9: 5 | F9: 5 | G9: =IF(D9="","",IF(D9=0,"-",IF(F9>D9,"ERROR",IF(E9>D9,"ERROR",IF(E9<D9,0,IF(E9>F9,0,IF(F9=D9,1,0))))))) -> 1 | P9: LA CASA DE LA CAÑA, C.A. (T. ALTERNA)
A10: 2 | B10: MOUSE | D10: 5 | E10: 5 | F10: 5 | G10: =IF(D10="","",IF(D10=0,"-",IF(F10>D10,"ERROR",IF(E10>D10,"ERROR",IF(E10<D10,0,IF(E10>F10,0,IF(F10=D10,1,0))))))) -> 1 | P10: LA CASA DE LA CAÑA, C.A. (T. ANACO)
A11: 3 | B11: TECLADOS | D11: 5 | E11: 5 | F11: 5 | G11: =IF(D11="","",IF(D11=0,"-",IF(F11>D11,"ERROR",IF(E11>D11,"ERROR",IF(E11<D11,0,IF(E11>F11,0,IF(F11=D11,1,0))))))) -> 1 | P11: LA CASA DE LA CAÑA, C.A. (T. NVA BARCELONA)
A12: 4 | B12: MONITORES | D12: 5 | E12: 5 | F12: 5 | G12: =IF(D12="","",IF(D12=0,"-",IF(F12>D12,"ERROR",IF(E12>D12,"ERROR",IF(E12<D12,0,IF(E12>F12,0,IF(F12=D12,1,0))))))) -> 1 | P12: LA CASA DE LA CAÑA, C.A. (T. CUMANA)
A13: 5 | B13: REGULADORES | D13: 5 | E13: 5 | F13: 5 | G13: =IF(D13="","",IF(D13=0,"-",IF(F13>D13,"ERROR",IF(E13>D13,"ERROR",IF(E13<D13,0,IF(E13>F13,0,IF(F13=D13,1,0))))))) -> 1 | P13: LA CASA DE LA CAÑA, C.A. (T. MATURIN I)
A14: 6 | B14: IMPRESORA MULTIFUNCIONAL | D14: 1 | E14: 1 | F14: 1 | G14: =IF(D14="","",IF(D14=0,"-",IF(F14>D14,"ERROR",IF(E14>D14,"ERROR",IF(E14<D14,0,IF(E14>F14,0,IF(F14=D14,1,0))))))) -> 1 | P14: LA CASA DE LA CAÑA, C.A. (T. MATURIN II)
A15: 7 | B15: IMPRESORAS FISCALES | D15: 3 | E15: 3 | F15: 3 | G15: =IF(D15="","",IF(D15=0,"-",IF(F15>D15,"ERROR",IF(E15>D15,"ERROR",IF(E15<D15,0,IF(E15>F15,0,IF(F15=D15,1,0))))))) -> 1 | H15: SERIAL 1: | J15: Nº ULT. REPORTE Z: | P15: LA CASA DE LA CAÑA, C.A. (T. FREITES)
H16: SERIAL 2: | J16: Nº ULT. REPORTE Z: | P16: LA CASA DE LA CAÑA, C.A. (T. PUENTE)
H17: SERIAL 3: | J17: Nº ULT. REPORTE Z: | P17: RELIVE, C.A. (T. CHUPARIN)
H18: SERIAL 4: | J18: Nº ULT. REPORTE Z: | P18: RELIVE, C.A. (T. TERRAZAS)
H19: SERIAL 5: | J19: Nº ULT. REPORTE Z: | P19: RELIVE, C.A. (T. TIGRE II)
H20: SERIAL 6: | J20: Nº ULT. REPORTE Z: | P20: RELIVE, C.A. (T. TIGRE III)
H21: SERIAL 7: | J21: Nº ULT. REPORTE Z: | P21: RELIVE, C.A. (T. PLC)
P22: RELIVE, C.A. (T. POZUELOS)
A23: 8 | B23: ROUTER | D23: 1 | E23: 1 | F23: 1 | G23: =IF(D23="","",IF(D23=0,"-",IF(F23>D23,"ERROR",IF(E23>D23,"ERROR",IF(E23<D23,0,IF(E23>F23,0,IF(F23=D23,1,0))))))) -> 1 | P23: OPERADORA VENECIA 2021, C.A (T. VENECIA)
A24: 9 | B24: SUICHE | D24: 2 | E24: 2 | F24: 2 | G24: =IF(D24="","",IF(D24=0,"-",IF(F24>D24,"ERROR",IF(E24>D24,"ERROR",IF(E24<D24,0,IF(E24>F24,0,IF(F24=D24,1,0))))))) -> 1 | P24: OPERADORA VENECIA 2021, C.A (T. BOLIVAR PLC)
A25: 10 | B25: ESCANER DE CODIGO DE BARRAS | D25: 5 | E25: 5 | F25: 5 | G25: =IF(D25="","",IF(D25=0,"-",IF(F25>D25,"ERROR",IF(E25>D25,"ERROR",IF(E25<D25,0,IF(E25>F25,0,IF(F25=D25,1,0))))))) -> 1 | P25: OPERADORA VENECIA 2021, C.A (T. CHURCHILL)
A26: 11 | B26: VISOR DE VENTA | D26: 2 | E26: 2 | F26: 2 | G26: =IF(D26="","",IF(D26=0,"-",IF(F26>D26,"ERROR",IF(E26>D26,"ERROR",IF(E26<D26,0,IF(E26>F26,0,IF(F26=D26,1,0))))))) -> 1 | P26: OPERADORA VENECIA 2021, C.A (T. MANSION)
A27: 12 | B27: DVR | D27: 1 | E27: 1 | F27: 1 | G27: =IF(D27="","",IF(D27=0,"-",IF(F27>D27,"ERROR",IF(E27>D27,"ERROR",IF(E27<D27,0,IF(E27>F27,0,IF(F27=D27,1,0))))))) -> 1 | P27: OPERADORA LECHERIA 2011, C.A
A28: 13 | B28: MODEM | D28: 1 | E28: 1 | F28: 1 | G28: =IF(D28="","",IF(D28=0,"-",IF(F28>D28,"ERROR",IF(E28>D28,"ERROR",IF(E28<D28,0,IF(E28>F28,0,IF(F28=D28,1,0))))))) -> 1
A29: 14 | B29: LIBROS DE IMPRESORAS FISCALES | D29: 3 | E29: 3 | F29: 3 | G29: =IF(D29="","",IF(D29=0,"-",IF(F29>D29,"ERROR",IF(E29>D29,"ERROR",IF(E29<D29,0,IF(E29>F29,0,IF(F29=D29,1,0))))))) -> 1
A30: TOTAL DE EFECTIVIDAD DE EQUIPOS | G30: =IFERROR(AVERAGE(G9:G28),"-") -> 1
A32: Realizado Por: | C32: Aracelis Incerri
A33: Cargo | C33: Lider De Tienda
A35: NOTA: El check list de Existencia de Equipos en Tiendas debe ser enviado entre los 5 primeros días del mes, vía correo electrónico al grupo Sistemas, con copia al Director de Servicios de Control.
L39: HOUSE TICKET | M39: INVENTARIO | N39: CABLEADO | O39: MES
K40: TIENDAS | L40: SI | M40: 0 | N40: SI | O40: ENERO
K41: =IF(MAESTRO!A1="","",MAESTRO!A1) -> ******SUCURSALES | L41: NO | M41: 1 | N41: NO | O41: FEBRERO
K42: =IF(MAESTRO!A2="","",MAESTRO!A2) -> LA CASA DE LA CAÑA, C.A. (T. ALTERNA) | M42: 2 | O42: MARZO
K43: =IF(MAESTRO!A3="","",MAESTRO!A3) -> LA CASA DE LA CAÑA, C.A. (T. ANACO) | M43: 3 | O43: ABRIL
K44: =IF(MAESTRO!A4="","",MAESTRO!A4) -> LA CASA DE LA CAÑA, C.A. (T. CUMANÁ) | M44: 4 | O44: MAYO
K45: =IF(MAESTRO!A5="","",MAESTRO!A5) -> LA CASA DE LA CAÑA, C.A. (T. MATURÍN I) | M45: 5 | O45: JUNIO
K46: =IF(MAESTRO!A6="","",MAESTRO!A6) -> LA CASA DE LA CAÑA, C.A. (T. MATURÍN II) | M46: 6 | O46: JULIO
K47: =IF(MAESTRO!A7="","",MAESTRO!A7) -> LA CASA DE LA CAÑA, C.A. (T. NVA. BARCELONA) | M47: 7 | O47: AGOSTO
...

Sheet MAT II
C1: CHECK LIST DE EXISTENCIA DE EQUIPOS EN TIENDAS | I1: Código: | J1: FO-MIS-03
I2: Revisión: | J2: 07 | K2: 42720
I3: Fecha: | J3: 42286
B5: SUCURSAL: | C5: LA CASA DE LA CAÑA, C.A. (T. MATURIN II) | H5: FECHA: | I5: 46157
A7: EQUIPOS
A8: Nº | B8: EQUIPOS | D8: INVENTARIO IDEAL | E8: INVENTARIO REAL | F8: EQUIPOS OPERATIVOS | G8: EFECTIVIDAD | H8: OBSERVACIONES
A9: 1 | B9: CPU | D9: 5 | E9: 5 | F9: 5 | G9: =IF(D9="","",IF(D9=0,"-",IF(F9>D9,"ERROR",IF(E9>D9,"ERROR",IF(E9<D9,0,IF(E9>F9,0,IF(F9=D9,1,0))))))) -> 1 | O9: LA CASA DE LA CAÑA, C.A. (T. ALTERNA)
A10: 2 | B10: MOUSE | D10: 5 | E10: 5 | F10: 5 | G10: =IF(D10="","",IF(D10=0,"-",IF(F10>D10,"ERROR",IF(E10>D10,"ERROR",IF(E10<D10,0,IF(E10>F10,0,IF(F10=D10,1,0))))))) -> 1 | O10: LA CASA DE LA CAÑA, C.A. (T. ANACO)
A11: 3 | B11: TECLADOS | D11: 5 | E11: 5 | F11: 5 | G11: =IF(D11="","",IF(D11=0,"-",IF(F11>D11,"ERROR",IF(E11>D11,"ERROR",IF(E11<D11,0,IF(E11>F11,0,IF(F11=D11,1,0))))))) -> 1 | O11: LA CASA DE LA CAÑA, C.A. (T. NVA BARCELONA)
A12: 4 | B12: MONITORES | D12: 5 | E12: 5 | F12: 5 | G12: =IF(D12="","",IF(D12=0,"-",IF(F12>D12,"ERROR",IF(E12>D12,"ERROR",IF(E12<D12,0,IF(E12>F12,0,IF(F12=D12,1,0))))))) -> 1 | O12: LA CASA DE LA CAÑA, C.A. (T. CUMANA)
A13: 5 | B13: REGULADORES | D13: 5 | E13: 5 | F13: 5 | G13: =IF(D13="","",IF(D13=0,"-",IF(F13>D13,"ERROR",IF(E13>D13,"ERROR",IF(E13<D13,0,IF(E13>F13,0,IF(F13=D13,1,0))))))) -> 1 | O13: LA CASA DE LA CAÑA, C.A. (T. MATURIN I)
A14: 6 | B14: IMPRESORA MULTIFUNCIONAL | D14: 1 | E14: 1 | F14: 1 | G14: =IF(D14="","",IF(D14=0,"-",IF(F14>D14,"ERROR",IF(E14>D14,"ERROR",IF(E14<D14,0,IF(E14>F14,0,IF(F14=D14,1,0))))))) -> 1 | O14: LA CASA DE LA CAÑA, C.A. (T. MATURIN II)
A15: 7 | B15: IMPRESORAS FISCALES | D15: 3 | E15: 3 | F15: 3 | G15: =IF(D15="","",IF(D15=0,"-",IF(F15>D15,"ERROR",IF(E15>D15,"ERROR",IF(E15<D15,0,IF(E15>F15,0,IF(F15=D15,1,0))))))) -> 1 | H15: SERIAL 1: | J15: Nº ULT. REPORTE Z: | O15: LA CASA DE LA CAÑA, C.A. (T. FREITES)
H16: SERIAL 2: | J16: Nº ULT. REPORTE Z: | O16: LA CASA DE LA CAÑA, C.A. (T. PUENTE)
H17: SERIAL 3: | J17: Nº ULT. REPORTE Z: | O17: RELIVE, C.A. (T. CHUPARIN)
H18: SERIAL 4: | J18: Nº ULT. REPORTE Z: | O18: RELIVE, C.A. (T. TERRAZAS)
H19: SERIAL 5: | J19: Nº ULT. REPORTE Z: | O19: RELIVE, C.A. (T. TIGRE II)
H20: SERIAL 6: | J20: Nº ULT. REPORTE Z: | O20: RELIVE, C.A. (T. TIGRE III)
H21: SERIAL 7: | J21: Nº ULT. REPORTE Z: | O21: RELIVE, C.A. (T. PLC)
O22: RELIVE, C.A. (T. POZUELOS)
A23: 8 | B23: ROUTER | D23: 1 | E23: 1 | F23: 1 | G23: =IF(D23="","",IF(D23=0,"-",IF(F23>D23,"ERROR",IF(E23>D23,"ERROR",IF(E23<D23,0,IF(E23>F23,0,IF(F23=D23,1,0))))))) -> 1 | O23: OPERADORA VENECIA 2021, C.A (T. VENECIA)
A24: 9 | B24: SUICHE | D24: 2 | E24: 2 | F24: 2 | G24: =IF(D24="","",IF(D24=0,"-",IF(F24>D24,"ERROR",IF(E24>D24,"ERROR",IF(E24<D24,0,IF(E24>F24,0,IF(F24=D24,1,0))))))) -> 1 | O24: OPERADORA VENECIA 2021, C.A (T. BOLIVAR PLC)
A25: 10 | B25: ESCANER DE CODIGO DE BARRAS | D25: 5 | E25: 5 | F25: 5 | G25: =IF(D25="","",IF(D25=0,"-",IF(F25>D25,"ERROR",IF(E25>D25,"ERROR",IF(E25<D25,0,IF(E25>F25,0,IF(F25=D25,1,0))))))) -> 1 | O25: OPERADORA VENECIA 2021, C.A (T. CHURCHILL)
A26: 11 | B26: VISOR DE VENTA | D26: 2 | E26: 2 | F26: 2 | G26: =IF(D26="","",IF(D26=0,"-",IF(F26>D26,"ERROR",IF(E26>D26,"ERROR",IF(E26<D26,0,IF(E26>F26,0,IF(F26=D26,1,0))))))) -> 1 | O26: OPERADORA VENECIA 2021, C.A (T. MANSION)
A27: 12 | B27: DVR | D27: 1 | E27: 1 | F27: 1 | G27: =IF(D27="","",IF(D27=0,"-",IF(F27>D27,"ERROR",IF(E27>D27,"ERROR",IF(E27<D27,0,IF(E27>F27,0,IF(F27=D27,1,0))))))) -> 1 | O27: OPERADORA LECHERIA 2011, C.A
A28: 13 | B28: MODEM | D28: 1 | E28: 1 | F28: 1 | G28: =IF(D28="","",IF(D28=0,"-",IF(F28>D28,"ERROR",IF(E28>D28,"ERROR",IF(E28<D28,0,IF(E28>F28,0,IF(F28=D28,1,0))))))) -> 1
A29: 14 | B29: LIBROS DE IMPRESORAS FISCALES | D29: 3 | E29: 3 | F29: 3 | G29: =IF(D29="","",IF(D29=0,"-",IF(F29>D29,"ERROR",IF(E29>D29,"ERROR",IF(E29<D29,0,IF(E29>F29,0,IF(F29=D29,1,0))))))) -> 1
A30: TOTAL DE EFECTIVIDAD DE EQUIPOS | G30: =IFERROR(AVERAGE(G9:G28),"-") -> 1
A32: Realizado Por: | C32: Heidi Sanabria
A33: Cargo | C33: Lide Tienda
A35: NOTA: El check list de Existencia de Equipos en Tiendas debe ser enviado entre los 5 primeros días del mes, vía correo electrónico al grupo Sistemas, con copia al Director de Servicios de Control.
L39: HOUSE TICKET | M39: INVENTARIO | N39: CABLEADO | O39: MES
K40: TIENDAS | L40: SI | M40: 0 | N40: SI | O40: ENERO
K41: =IF(MAESTRO!A1="","",MAESTRO!A1) -> ******SUCURSALES | L41: NO | M41: 1 | N41: NO | O41: FEBRERO
K42: =IF(MAESTRO!A2="","",MAESTRO!A2) -> LA CASA DE LA CAÑA, C.A. (T. ALTERNA) | M42: 2 | O42: MARZO
K43: =IF(MAESTRO!A3="","",MAESTRO!A3) -> LA CASA DE LA CAÑA, C.A. (T. ANACO) | M43: 3 | O43: ABRIL
K44: =IF(MAESTRO!A4="","",MAESTRO!A4) -> LA CASA DE LA CAÑA, C.A. (T. CUMANÁ) | M44: 4 | O44: MAYO
K45: =IF(MAESTRO!A5="","",MAESTRO!A5) -> LA CASA DE LA CAÑA, C.A. (T. MATURÍN I) | M45: 5 | O45: JUNIO
K46: =IF(MAESTRO!A6="","",MAESTRO!A6) -> LA CASA DE LA CAÑA, C.A. (T. MATURÍN II) | M46: 6 | O46: JULIO
K47: =IF(MAESTRO!A7="","",MAESTRO!A7) -> LA CASA DE LA CAÑA, C.A. (T. NVA. BARCELONA) | M47: 7 | O47: AGOSTO
...

Sheet NVA BNA
C1: CHECK LIST DE EXISTENCIA DE EQUIPOS EN TIENDAS | I1: Código: | J1: FO-MIS-03
I2: Revisión: | J2: 07 | K2: 42720
I3: Fecha: | J3: 42286
B5: SUCURSAL: | C5: LA CASA DE LA CAÑA, C.A. (T. NVA. BARCELONA) | H5: FECHA: | I5: 46157
A7: EQUIPOS
A8: Nº | B8: EQUIPOS | D8: INVENTARIO IDEAL | E8: INVENTARIO REAL | F8: EQUIPOS OPERATIVOS | G8: EFECTIVIDAD | H8: OBSERVACIONES
A9: 1 | B9: CPU | D9: 4 | E9: 4 | F9: 4 | G9: =IF(D9="","",IF(D9=0,"-",IF(F9>D9,"ERROR",IF(E9>D9,"ERROR",IF(E9<D9,0,IF(E9>F9,0,IF(F9=D9,1,0))))))) -> 1 | P9: LA CASA DE LA CAÑA, C.A. (T. ALTERNA)
A10: 2 | B10: MOUSE | D10: 4 | E10: 4 | F10: 4 | G10: =IF(D10="","",IF(D10=0,"-",IF(F10>D10,"ERROR",IF(E10>D10,"ERROR",IF(E10<D10,0,IF(E10>F10,0,IF(F10=D10,1,0))))))) -> 1 | P10: LA CASA DE LA CAÑA, C.A. (T. ANACO)
A11: 3 | B11: TECLADOS | D11: 4 | E11: 4 | F11: 4 | G11: =IF(D11="","",IF(D11=0,"-",IF(F11>D11,"ERROR",IF(E11>D11,"ERROR",IF(E11<D11,0,IF(E11>F11,0,IF(F11=D11,1,0))))))) -> 1 | P11: LA CASA DE LA CAÑA, C.A. (T. NVA BARCELONA)
A12: 4 | B12: MONITORES | D12: 4 | E12: 4 | F12: 4 | G12: =IF(D12="","",IF(D12=0,"-",IF(F12>D12,"ERROR",IF(E12>D12,"ERROR",IF(E12<D12,0,IF(E12>F12,0,IF(F12=D12,1,0))))))) -> 1 | P12: LA CASA DE LA CAÑA, C.A. (T. CUMANA)
A13: 5 | B13: REGULADORES | D13: 4 | E13: 4 | F13: 4 | G13: =IF(D13="","",IF(D13=0,"-",IF(F13>D13,"ERROR",IF(E13>D13,"ERROR",IF(E13<D13,0,IF(E13>F13,0,IF(F13=D13,1,0))))))) -> 1 | P13: LA CASA DE LA CAÑA, C.A. (T. MATURIN I)
A14: 6 | B14: IMPRESORA MULTIFUNCIONAL | D14: 1 | E14: 1 | F14: 1 | G14: =IF(D14="","",IF(D14=0,"-",IF(F14>D14,"ERROR",IF(E14>D14,"ERROR",IF(E14<D14,0,IF(E14>F14,0,IF(F14=D14,1,0))))))) -> 1 | P14: LA CASA DE LA CAÑA, C.A. (T. MATURIN II)
A15: 7 | B15: IMPRESORAS FISCALES | D15: 2 | E15: 2 | F15: 2 | G15: =IF(D15="","",IF(D15=0,"-",IF(F15>D15,"ERROR",IF(E15>D15,"ERROR",IF(E15<D15,0,IF(E15>F15,0,IF(F15=D15,1,0))))))) -> 1 | H15: SERIAL 1: | J15: Nº ULT. REPORTE Z: | P15: LA CASA DE LA CAÑA, C.A. (T. FREITES)
H16: SERIAL 2: | J16: Nº ULT. REPORTE Z: | P16: LA CASA DE LA CAÑA, C.A. (T. PUENTE)
H17: SERIAL 3: | J17: Nº ULT. REPORTE Z: | P17: RELIVE, C.A. (T. CHUPARIN)
H18: SERIAL 4: | J18: Nº ULT. REPORTE Z: | P18: RELIVE, C.A. (T. TERRAZAS)
H19: SERIAL 5: | J19: Nº ULT. REPORTE Z: | P19: RELIVE, C.A. (T. TIGRE II)
H20: SERIAL 6: | J20: Nº ULT. REPORTE Z: | P20: RELIVE, C.A. (T. TIGRE III)
H21: SERIAL 7: | J21: Nº ULT. REPORTE Z: | P21: RELIVE, C.A. (T. PLC)
H22: una comandera caja 4 | P22: RELIVE, C.A. (T. POZUELOS)
A23: 8 | B23: ROUTER | D23: 1 | E23: 1 | F23: 1 | G23: =IF(D23="","",IF(D23=0,"-",IF(F23>D23,"ERROR",IF(E23>D23,"ERROR",IF(E23<D23,0,IF(E23>F23,0,IF(F23=D23,1,0))))))) -> 1 | P23: OPERADORA VENECIA 2021, C.A (T. VENECIA)
A24: 9 | B24: SUICHE | D24: 1 | E24: 1 | F24: 1 | G24: =IF(D24="","",IF(D24=0,"-",IF(F24>D24,"ERROR",IF(E24>D24,"ERROR",IF(E24<D24,0,IF(E24>F24,0,IF(F24=D24,1,0))))))) -> 1 | P24: OPERADORA VENECIA 2021, C.A (T. BOLIVAR PLC)
A25: 10 | B25: ESCANER DE CODIGO DE BARRAS | D25: 4 | E25: 4 | F25: 4 | G25: =IF(D25="","",IF(D25=0,"-",IF(F25>D25,"ERROR",IF(E25>D25,"ERROR",IF(E25<D25,0,IF(E25>F25,0,IF(F25=D25,1,0))))))) -> 1 | P25: OPERADORA VENECIA 2021, C.A (T. CHURCHILL)
A26: 11 | B26: VISOR DE VENTA | D26: 1 | E26: 1 | F26: 1 | G26: =IF(D26="","",IF(D26=0,"-",IF(F26>D26,"ERROR",IF(E26>D26,"ERROR",IF(E26<D26,0,IF(E26>F26,0,IF(F26=D26,1,0))))))) -> 1 | P26: OPERADORA VENECIA 2021, C.A (T. MANSION)
A27: 12 | B27: DVR | D27: 1 | E27: 1 | F27: 1 | G27: =IF(D27="","",IF(D27=0,"-",IF(F27>D27,"ERROR",IF(E27>D27,"ERROR",IF(E27<D27,0,IF(E27>F27,0,IF(F27=D27,1,0))))))) -> 1 | P27: OPERADORA LECHERIA 2011, C.A
A28: 13 | B28: MODEM | D28: 1 | E28: 1 | F28: 1 | G28: =IF(D28="","",IF(D28=0,"-",IF(F28>D28,"ERROR",IF(E28>D28,"ERROR",IF(E28<D28,0,IF(E28>F28,0,IF(F28=D28,1,0))))))) -> 1
A29: 14 | B29: LIBROS DE IMPRESORAS FISCALES | D29: 2 | E29: 2 | F29: 2 | G29: =IF(D29="","",IF(D29=0,"-",IF(F29>D29,"ERROR",IF(E29>D29,"ERROR",IF(E29<D29,0,IF(E29>F29,0,IF(F29=D29,1,0))))))) -> 1
A30: TOTAL DE EFECTIVIDAD DE EQUIPOS | G30: =IFERROR(AVERAGE(G9:G28),"-") -> 1
A32: Realizado Por: | C32: Jean Carlos Medina
A33: Cargo | C33: Lider de Tienda
A35: NOTA: El check list de Existencia de Equipos en Tiendas debe ser enviado entre los 5 primeros días del mes, vía correo electrónico al grupo Sistemas, con copia al Director de Servicios de Control.
L39: HOUSE TICKET | M39: INVENTARIO | N39: CABLEADO | O39: MES
K40: TIENDAS | L40: SI | M40: 0 | N40: SI | O40: ENERO
K41: =IF(MAESTRO!A1="","",MAESTRO!A1) -> ******SUCURSALES | L41: NO | M41: 1 | N41: NO | O41: FEBRERO
K42: =IF(MAESTRO!A2="","",MAESTRO!A2) -> LA CASA DE LA CAÑA, C.A. (T. ALTERNA) | M42: 2 | O42: MARZO
K43: =IF(MAESTRO!A3="","",MAESTRO!A3) -> LA CASA DE LA CAÑA, C.A. (T. ANACO) | M43: 3 | O43: ABRIL
K44: =IF(MAESTRO!A4="","",MAESTRO!A4) -> LA CASA DE LA CAÑA, C.A. (T. CUMANÁ) | M44: 4 | O44: MAYO
K45: =IF(MAESTRO!A5="","",MAESTRO!A5) -> LA CASA DE LA CAÑA, C.A. (T. MATURÍN I) | M45: 5 | O45: JUNIO
K46: =IF(MAESTRO!A6="","",MAESTRO!A6) -> LA CASA DE LA CAÑA, C.A. (T. MATURÍN II) | M46: 6 | O46: JULIO
K47: =IF(MAESTRO!A7="","",MAESTRO!A7) -> LA CASA DE LA CAÑA, C.A. (T. NVA. BARCELONA) | M47: 7 | O47: AGOSTO
...

Sheet TER
C1: CHECK LIST DE EXISTENCIA DE EQUIPOS EN TIENDAS | I1: Código: | J1: FO-MIS-03
I2: Revisión: | J2: 07 | K2: 42720
I3: Fecha: | J3: 42286
B5: SUCURSAL: | C5: RELIVE, C.A. (T. TERRAZAS) | H5: FECHA: | I5: 46157
A7: EQUIPOS
A8: Nº | B8: EQUIPOS | D8: INVENTARIO IDEAL | E8: INVENTARIO REAL | F8: EQUIPOS OPERATIVOS | G8: EFECTIVIDAD | H8: OBSERVACIONES
A9: 1 | B9: CPU | D9: 4 | E9: 4 | F9: 4 | G9: =IF(D9="","",IF(D9=0,"-",IF(F9>D9,"ERROR",IF(E9>D9,"ERROR",IF(E9<D9,0,IF(E9>F9,0,IF(F9=D9,1,0))))))) -> 1 | R9: LA CASA DE LA CAÑA, C.A. (T. ALTERNA)
A10: 2 | B10: MOUSE | D10: 4 | E10: 4 | F10: 4 | G10: =IF(D10="","",IF(D10=0,"-",IF(F10>D10,"ERROR",IF(E10>D10,"ERROR",IF(E10<D10,0,IF(E10>F10,0,IF(F10=D10,1,0))))))) -> 1 | R10: LA CASA DE LA CAÑA, C.A. (T. ANACO)
A11: 3 | B11: TECLADOS | D11: 4 | E11: 4 | F11: 4 | G11: =IF(D11="","",IF(D11=0,"-",IF(F11>D11,"ERROR",IF(E11>D11,"ERROR",IF(E11<D11,0,IF(E11>F11,0,IF(F11=D11,1,0))))))) -> 1 | R11: LA CASA DE LA CAÑA, C.A. (T. NVA BARCELONA)
A12: 4 | B12: MONITORES | D12: 4 | E12: 4 | F12: 4 | G12: =IF(D12="","",IF(D12=0,"-",IF(F12>D12,"ERROR",IF(E12>D12,"ERROR",IF(E12<D12,0,IF(E12>F12,0,IF(F12=D12,1,0))))))) -> 1 | R12: LA CASA DE LA CAÑA, C.A. (T. CUMANA)
A13: 5 | B13: REGULADORES | D13: 4 | E13: 4 | F13: 4 | G13: =IF(D13="","",IF(D13=0,"-",IF(F13>D13,"ERROR",IF(E13>D13,"ERROR",IF(E13<D13,0,IF(E13>F13,0,IF(F13=D13,1,0))))))) -> 1 | R13: LA CASA DE LA CAÑA, C.A. (T. MATURIN I)
A14: 6 | B14: IMPRESORA MULTIFUNCIONAL | D14: 1 | E14: 1 | F14: 1 | G14: =IF(D14="","",IF(D14=0,"-",IF(F14>D14,"ERROR",IF(E14>D14,"ERROR",IF(E14<D14,0,IF(E14>F14,0,IF(F14=D14,1,0))))))) -> 1 | R14: LA CASA DE LA CAÑA, C.A. (T. MATURIN II)
A15: 7 | B15: IMPRESORAS FISCALES | D15: 3 | E15: 3 | F15: 2 | G15: =IF(D15="","",IF(D15=0,"-",IF(F15>D15,"ERROR",IF(E15>D15,"ERROR",IF(E15<D15,0,IF(E15>F15,0,IF(F15=D15,1,0))))))) -> 0 | H15: SERIAL 1: | J15: Nº ULT. REPORTE Z: | R15: LA CASA DE LA CAÑA, C.A. (T. FREITES)
H16: SERIAL 2: | J16: Nº ULT. REPORTE Z: | R16: LA CASA DE LA CAÑA, C.A. (T. PUENTE)
H17: SERIAL 3: | J17: Nº ULT. REPORTE Z: | R17: RELIVE, C.A. (T. CHUPARIN)
H18: SERIAL 4: | J18: Nº ULT. REPORTE Z: | R18: RELIVE, C.A. (T. TERRAZAS)
H19: SERIAL 5: | J19: Nº ULT. REPORTE Z: | R19: RELIVE, C.A. (T. TIGRE II)
H20: SERIAL 6: | J20: Nº ULT. REPORTE Z: | R20: RELIVE, C.A. (T. TIGRE III)
H21: SERIAL 7: | J21: Nº ULT. REPORTE Z: | R21: RELIVE, C.A. (T. PLC)
R22: RELIVE, C.A. (T. POZUELOS)
A23: 8 | B23: ROUTER | D23: 1 | E23: 1 | F23: 1 | G23: =IF(D23="","",IF(D23=0,"-",IF(F23>D23,"ERROR",IF(E23>D23,"ERROR",IF(E23<D23,0,IF(E23>F23,0,IF(F23=D23,1,0))))))) -> 1 | R23: OPERADORA VENECIA 2021, C.A (T. VENECIA)
A24: 9 | B24: SUICHE | D24: 1 | E24: 1 | F24: 1 | G24: =IF(D24="","",IF(D24=0,"-",IF(F24>D24,"ERROR",IF(E24>D24,"ERROR",IF(E24<D24,0,IF(E24>F24,0,IF(F24=D24,1,0))))))) -> 1 | R24: OPERADORA VENECIA 2021, C.A (T. BOLIVAR PLC)
A25: 10 | B25: ESCANER DE CODIGO DE BARRAS | D25: 4 | E25: 4 | F25: 4 | G25: =IF(D25="","",IF(D25=0,"-",IF(F25>D25,"ERROR",IF(E25>D25,"ERROR",IF(E25<D25,0,IF(E25>F25,0,IF(F25=D25,1,0))))))) -> 1 | R25: OPERADORA VENECIA 2021, C.A (T. CHURCHILL)
A26: 11 | B26: VISOR DE VENTA | D26: 2 | E26: 2 | F26: 2 | G26: =IF(D26="","",IF(D26=0,"-",IF(F26>D26,"ERROR",IF(E26>D26,"ERROR",IF(E26<D26,0,IF(E26>F26,0,IF(F26=D26,1,0))))))) -> 1 | R26: OPERADORA VENECIA 2021, C.A (T. MANSION)
A27: 12 | B27: DVR | D27: 1 | E27: 1 | F27: 1 | G27: =IF(D27="","",IF(D27=0,"-",IF(F27>D27,"ERROR",IF(E27>D27,"ERROR",IF(E27<D27,0,IF(E27>F27,0,IF(F27=D27,1,0))))))) -> 1 | R27: OPERADORA LECHERIA 2011, C.A
A28: 13 | B28: MODEM | D28: 1 | E28: 1 | F28: 1 | G28: =IF(D28="","",IF(D28=0,"-",IF(F28>D28,"ERROR",IF(E28>D28,"ERROR",IF(E28<D28,0,IF(E28>F28,0,IF(F28=D28,1,0))))))) -> 1
A29: 14 | B29: LIBROS DE IMPRESORAS FISCALES | D29: 3 | E29: 3 | F29: 3 | G29: =IF(D29="","",IF(D29=0,"-",IF(F29>D29,"ERROR",IF(E29>D29,"ERROR",IF(E29<D29,0,IF(E29>F29,0,IF(F29=D29,1,0))))))) -> 1
A30: TOTAL DE EFECTIVIDAD DE EQUIPOS | G30: =IFERROR(AVERAGE(G9:G28),"-") -> 0.92307692
A32: Realizado Por: | C32: Alexander Buriel
A33: Cargo | C33: Lider de Tienda
A35: NOTA: El check list de Existencia de Equipos en Tiendas debe ser enviado entre los 5 primeros días del mes, vía correo electrónico al grupo Sistemas, con copia al Director de Servicios de Control.
L39: HOUSE TICKET | M39: INVENTARIO | N39: CABLEADO | O39: MES
K40: TIENDAS | L40: SI | M40: 0 | N40: SI | O40: ENERO
K41: =IF(MAESTRO!A1="","",MAESTRO!A1) -> ******SUCURSALES | L41: NO | M41: 1 | N41: NO | O41: FEBRERO
K42: =IF(MAESTRO!A2="","",MAESTRO!A2) -> LA CASA DE LA CAÑA, C.A. (T. ALTERNA) | M42: 2 | O42: MARZO
K43: =IF(MAESTRO!A3="","",MAESTRO!A3) -> LA CASA DE LA CAÑA, C.A. (T. ANACO) | M43: 3 | O43: ABRIL
K44: =IF(MAESTRO!A4="","",MAESTRO!A4) -> LA CASA DE LA CAÑA, C.A. (T. CUMANÁ) | M44: 4 | O44: MAYO
K45: =IF(MAESTRO!A5="","",MAESTRO!A5) -> LA CASA DE LA CAÑA, C.A. (T. MATURÍN I) | M45: 5 | O45: JUNIO
K46: =IF(MAESTRO!A6="","",MAESTRO!A6) -> LA CASA DE LA CAÑA, C.A. (T. MATURÍN II) | M46: 6 | O46: JULIO
K47: =IF(MAESTRO!A7="","",MAESTRO!A7) -> LA CASA DE LA CAÑA, C.A. (T. NVA. BARCELONA) | M47: 7 | O47: AGOSTO
...

Sheet CHU
C1: CHECK LIST DE EXISTENCIA DE EQUIPOS EN TIENDAS | I1: Código: | J1: FO-MIS-03
I2: Revisión: | J2: 07 | K2: 42720
I3: Fecha: | J3: 42286
B5: SUCURSAL: | C5: RELIVE, C.A. (T. CHUPARIN) | H5: FECHA: | I5: 46157
A7: EQUIPOS
A8: Nº | B8: EQUIPOS | D8: INVENTARIO IDEAL | E8: INVENTARIO REAL | F8: EQUIPOS OPERATIVOS | G8: EFECTIVIDAD | H8: OBSERVACIONES
A9: 1 | B9: CPU | D9: 5 | E9: 5 | F9: 5 | G9: =IF(D9="","",IF(D9=0,"-",IF(F9>D9,"ERROR",IF(E9>D9,"ERROR",IF(E9<D9,0,IF(E9>F9,0,IF(F9=D9,1,0))))))) -> 1
A10: 2 | B10: MOUSE | D10: 5 | E10: 5 | F10: 5 | G10: =IF(D10="","",IF(D10=0,"-",IF(F10>D10,"ERROR",IF(E10>D10,"ERROR",IF(E10<D10,0,IF(E10>F10,0,IF(F10=D10,1,0))))))) -> 1 | Q10: LA CASA DE LA CAÑA, C.A. (T. ALTERNA)
A11: 3 | B11: TECLADOS | D11: 5 | E11: 5 | F11: 5 | G11: =IF(D11="","",IF(D11=0,"-",IF(F11>D11,"ERROR",IF(E11>D11,"ERROR",IF(E11<D11,0,IF(E11>F11,0,IF(F11=D11,1,0))))))) -> 1 | Q11: LA CASA DE LA CAÑA, C.A. (T. ANACO)
A12: 4 | B12: MONITORES | D12: 5 | E12: 5 | F12: 5 | G12: =IF(D12="","",IF(D12=0,"-",IF(F12>D12,"ERROR",IF(E12>D12,"ERROR",IF(E12<D12,0,IF(E12>F12,0,IF(F12=D12,1,0))))))) -> 1 | Q12: LA CASA DE LA CAÑA, C.A. (T. NVA BARCELONA)
A13: 5 | B13: REGULADORES | D13: 5 | E13: 5 | F13: 5 | G13: =IF(D13="","",IF(D13=0,"-",IF(F13>D13,"ERROR",IF(E13>D13,"ERROR",IF(E13<D13,0,IF(E13>F13,0,IF(F13=D13,1,0))))))) -> 1 | Q13: LA CASA DE LA CAÑA, C.A. (T. CUMANA)
A14: 6 | B14: IMPRESORA MULTIFUNCIONAL | D14: 1 | E14: 1 | F14: 1 | G14: =IF(D14="","",IF(D14=0,"-",IF(F14>D14,"ERROR",IF(E14>D14,"ERROR",IF(E14<D14,0,IF(E14>F14,0,IF(F14=D14,1,0))))))) -> 1 | Q14: LA CASA DE LA CAÑA, C.A. (T. MATURIN I)
A15: 7 | B15: IMPRESORAS FISCALES | D15: 4 | E15: 4 | F15: 4 | G15: =IF(D15="","",IF(D15=0,"-",IF(F15>D15,"ERROR",IF(E15>D15,"ERROR",IF(E15<D15,0,IF(E15>F15,0,IF(F15=D15,1,0))))))) -> 1 | H15: SERIAL 1: | J15: Nº ULT. REPORTE Z: | Q15: LA CASA DE LA CAÑA, C.A. (T. MATURIN II)
H16: SERIAL 2: | J16: Nº ULT. REPORTE Z: | Q16: LA CASA DE LA CAÑA, C.A. (T. FREITES)
H17: SERIAL 3: | J17: Nº ULT. REPORTE Z: | Q17: LA CASA DE LA CAÑA, C.A. (T. PUENTE)
H18: SERIAL 4: | J18: Nº ULT. REPORTE Z: | Q18: RELIVE, C.A. (T. CHUPARIN)
H19: SERIAL 5: | J19: Nº ULT. REPORTE Z: | Q19: RELIVE, C.A. (T. TERRAZAS)
H20: SERIAL 6: | J20: Nº ULT. REPORTE Z: | Q20: RELIVE, C.A. (T. TIGRE II)
H21: SERIAL 7: | J21: Nº ULT. REPORTE Z: | Q21: RELIVE, C.A. (T. TIGRE III)
Q22: RELIVE, C.A. (T. PLC)
A23: 8 | B23: ROUTER | D23: 1 | E23: 1 | F23: 1 | G23: =IF(D23="","",IF(D23=0,"-",IF(F23>D23,"ERROR",IF(E23>D23,"ERROR",IF(E23<D23,0,IF(E23>F23,0,IF(F23=D23,1,0))))))) -> 1 | Q23: RELIVE, C.A. (T. POZUELOS)
A24: 9 | B24: SUICHE | D24: 2 | E24: 2 | F24: 2 | G24: =IF(D24="","",IF(D24=0,"-",IF(F24>D24,"ERROR",IF(E24>D24,"ERROR",IF(E24<D24,0,IF(E24>F24,0,IF(F24=D24,1,0))))))) -> 1 | Q24: OPERADORA VENECIA 2021, C.A (T. VENECIA)
A25: 10 | B25: ESCANER DE CODIGO DE BARRAS | D25: 5 | E25: 5 | F25: 5 | G25: =IF(D25="","",IF(D25=0,"-",IF(F25>D25,"ERROR",IF(E25>D25,"ERROR",IF(E25<D25,0,IF(E25>F25,0,IF(F25=D25,1,0))))))) -> 1 | Q25: OPERADORA VENECIA 2021, C.A (T. BOLIVAR PLC)
A26: 11 | B26: VISOR DE VENTA | D26: 2 | E26: 2 | F26: 2 | G26: =IF(D26="","",IF(D26=0,"-",IF(F26>D26,"ERROR",IF(E26>D26,"ERROR",IF(E26<D26,0,IF(E26>F26,0,IF(F26=D26,1,0))))))) -> 1 | Q26: OPERADORA VENECIA 2021, C.A (T. CHURCHILL)
A27: 12 | B27: DVR | D27: 1 | E27: 1 | F27: 1 | G27: =IF(D27="","",IF(D27=0,"-",IF(F27>D27,"ERROR",IF(E27>D27,"ERROR",IF(E27<D27,0,IF(E27>F27,0,IF(F27=D27,1,0))))))) -> 1 | Q27: OPERADORA VENECIA 2021, C.A (T. MANSION)
A28: 13 | B28: MODEM | D28: 1 | E28: 1 | F28: 1 | G28: =IF(D28="","",IF(D28=0,"-",IF(F28>D28,"ERROR",IF(E28>D28,"ERROR",IF(E28<D28,0,IF(E28>F28,0,IF(F28=D28,1,0))))))) -> 1 | Q28: OPERADORA LECHERIA 2011, C.A
A29: 14 | B29: LIBROS DE IMPRESORAS FISCALES | D29: 4 | E29: 4 | F29: 4 | G29: =IF(D29="","",IF(D29=0,"-",IF(F29>D29,"ERROR",IF(E29>D29,"ERROR",IF(E29<D29,0,IF(E29>F29,0,IF(F29=D29,1,0))))))) -> 1
A30: TOTAL DE EFECTIVIDAD DE EQUIPOS | G30: =IFERROR(AVERAGE(G9:G28),"-") -> 1
A32: Realizado Por: | C32: Jose Arias
A33: Cargo | C33: Lider de Tienda
A35: NOTA: El check list de Existencia de Equipos en Tiendas debe ser enviado entre los 5 primeros días del mes, vía correo electrónico al grupo Sistemas, con copia al Director de Servicios de Control.
L39: HOUSE TICKET | M39: INVENTARIO | N39: CABLEADO | O39: MES
K40: TIENDAS | L40: SI | M40: 0 | N40: SI | O40: ENERO
K41: =IF(MAESTRO!A1="","",MAESTRO!A1) -> ******SUCURSALES | L41: NO | M41: 1 | N41: NO | O41: FEBRERO
K42: =IF(MAESTRO!A2="","",MAESTRO!A2) -> LA CASA DE LA CAÑA, C.A. (T. ALTERNA) | M42: 2 | O42: MARZO
K43: =IF(MAESTRO!A3="","",MAESTRO!A3) -> LA CASA DE LA CAÑA, C.A. (T. ANACO) | M43: 3 | O43: ABRIL
K44: =IF(MAESTRO!A4="","",MAESTRO!A4) -> LA CASA DE LA CAÑA, C.A. (T. CUMANÁ) | M44: 4 | O44: MAYO
K45: =IF(MAESTRO!A5="","",MAESTRO!A5) -> LA CASA DE LA CAÑA, C.A. (T. MATURÍN I) | M45: 5 | O45: JUNIO
K46: =IF(MAESTRO!A6="","",MAESTRO!A6) -> LA CASA DE LA CAÑA, C.A. (T. MATURÍN II) | M46: 6 | O46: JULIO
K47: =IF(MAESTRO!A7="","",MAESTRO!A7) -> LA CASA DE LA CAÑA, C.A. (T. NVA. BARCELONA) | M47: 7 | O47: AGOSTO
...

Sheet TIG II
C1: CHECK LIST DE EXISTENCIA DE EQUIPOS EN TIENDAS | I1: Código: | J1: FO-MIS-03
I2: Revisión: | J2: 07 | K2: 42720
I3: Fecha: | J3: 42286
B5: SUCURSAL: | C5: RELIVE, C.A (T. TIGRE II) | H5: FECHA: | I5: 46157
A7: EQUIPOS
A8: Nº | B8: EQUIPOS | D8: INVENTARIO IDEAL | E8: INVENTARIO REAL | F8: EQUIPOS OPERATIVOS | G8: EFECTIVIDAD | H8: OBSERVACIONES
A9: 1 | B9: CPU | D9: 4 | E9: 4 | F9: 4 | G9: =IF(D9="","",IF(D9=0,"-",IF(F9>D9,"ERROR",IF(E9>D9,"ERROR",IF(E9<D9,0,IF(E9>F9,0,IF(F9=D9,1,0))))))) -> 1 | P9: LA CASA DE LA CAÑA, C.A. (T. ALTERNA)
A10: 2 | B10: MOUSE | D10: 4 | E10: 4 | F10: 4 | G10: =IF(D10="","",IF(D10=0,"-",IF(F10>D10,"ERROR",IF(E10>D10,"ERROR",IF(E10<D10,0,IF(E10>F10,0,IF(F10=D10,1,0))))))) -> 1 | P10: LA CASA DE LA CAÑA, C.A. (T. ANACO)
A11: 3 | B11: TECLADOS | D11: 4 | E11: 4 | F11: 4 | G11: =IF(D11="","",IF(D11=0,"-",IF(F11>D11,"ERROR",IF(E11>D11,"ERROR",IF(E11<D11,0,IF(E11>F11,0,IF(F11=D11,1,0))))))) -> 1 | P11: LA CASA DE LA CAÑA, C.A. (T. NVA BARCELONA)
A12: 4 | B12: MONITORES | D12: 4 | E12: 4 | F12: 4 | G12: =IF(D12="","",IF(D12=0,"-",IF(F12>D12,"ERROR",IF(E12>D12,"ERROR",IF(E12<D12,0,IF(E12>F12,0,IF(F12=D12,1,0))))))) -> 1 | P12: LA CASA DE LA CAÑA, C.A. (T. CUMANA)
A13: 5 | B13: REGULADORES | D13: 4 | E13: 4 | F13: 4 | G13: =IF(D13="","",IF(D13=0,"-",IF(F13>D13,"ERROR",IF(E13>D13,"ERROR",IF(E13<D13,0,IF(E13>F13,0,IF(F13=D13,1,0))))))) -> 1 | P13: LA CASA DE LA CAÑA, C.A. (T. MATURIN I)
A14: 6 | B14: IMPRESORA MULTIFUNCIONAL | D14: 1 | E14: 1 | F14: 1 | G14: =IF(D14="","",IF(D14=0,"-",IF(F14>D14,"ERROR",IF(E14>D14,"ERROR",IF(E14<D14,0,IF(E14>F14,0,IF(F14=D14,1,0))))))) -> 1 | P14: LA CASA DE LA CAÑA, C.A. (T. MATURIN II)
A15: 7 | B15: IMPRESORAS FISCALES | D15: 3 | E15: 3 | F15: 3 | G15: =IF(D15="","",IF(D15=0,"-",IF(F15>D15,"ERROR",IF(E15>D15,"ERROR",IF(E15<D15,0,IF(E15>F15,0,IF(F15=D15,1,0))))))) -> 1 | H15: SERIAL 1: | J15: Nº ULT. REPORTE Z: | P15: LA CASA DE LA CAÑA, C.A. (T. FREITES)
H16: SERIAL 2: | J16: Nº ULT. REPORTE Z: | P16: LA CASA DE LA CAÑA, C.A. (T. PUENTE)
H17: SERIAL 3: | J17: Nº ULT. REPORTE Z: | P17: RELIVE, C.A. (T. CHUPARIN)
H18: SERIAL 4: | J18: Nº ULT. REPORTE Z: | P18: RELIVE, C.A. (T. TERRAZAS)
H19: SERIAL 5: | J19: Nº ULT. REPORTE Z: | P19: RELIVE, C.A. (T. TIGRE II)
H20: SERIAL 6: | J20: Nº ULT. REPORTE Z: | P20: RELIVE, C.A. (T. TIGRE III)
H21: SERIAL 7: | J21: Nº ULT. REPORTE Z: | P21: RELIVE, C.A. (T. PLC)
P22: RELIVE, C.A. (T. POZUELOS)
A23: 8 | B23: ROUTER | D23: 1 | E23: 1 | F23: 1 | G23: =IF(D23="","",IF(D23=0,"-",IF(F23>D23,"ERROR",IF(E23>D23,"ERROR",IF(E23<D23,0,IF(E23>F23,0,IF(F23=D23,1,0))))))) -> 1 | P23: OPERADORA VENECIA 2021, C.A (T. VENECIA)
A24: 9 | B24: SUICHE | D24: 1 | E24: 1 | F24: 1 | G24: =IF(D24="","",IF(D24=0,"-",IF(F24>D24,"ERROR",IF(E24>D24,"ERROR",IF(E24<D24,0,IF(E24>F24,0,IF(F24=D24,1,0))))))) -> 1 | P24: OPERADORA VENECIA 2021, C.A (T. BOLIVAR PLC)
A25: 10 | B25: ESCANER DE CODIGO DE BARRAS | D25: 4 | E25: 4 | F25: 4 | G25: =IF(D25="","",IF(D25=0,"-",IF(F25>D25,"ERROR",IF(E25>D25,"ERROR",IF(E25<D25,0,IF(E25>F25,0,IF(F25=D25,1,0))))))) -> 1 | P25: OPERADORA VENECIA 2021, C.A (T. CHURCHILL)
A26: 11 | B26: VISOR DE VENTA | D26: 2 | E26: 2 | F26: 2 | G26: =IF(D26="","",IF(D26=0,"-",IF(F26>D26,"ERROR",IF(E26>D26,"ERROR",IF(E26<D26,0,IF(E26>F26,0,IF(F26=D26,1,0))))))) -> 1 | P26: OPERADORA VENECIA 2021, C.A (T. MANSION)
A27: 12 | B27: DVR | D27: 1 | E27: 1 | F27: 1 | G27: =IF(D27="","",IF(D27=0,"-",IF(F27>D27,"ERROR",IF(E27>D27,"ERROR",IF(E27<D27,0,IF(E27>F27,0,IF(F27=D27,1,0))))))) -> 1 | P27: OPERADORA LECHERIA 2011, C.A
A28: 13 | B28: MODEM | D28: 1 | E28: 1 | F28: 1 | G28: =IF(D28="","",IF(D28=0,"-",IF(F28>D28,"ERROR",IF(E28>D28,"ERROR",IF(E28<D28,0,IF(E28>F28,0,IF(F28=D28,1,0))))))) -> 1
A29: 14 | B29: LIBROS DE IMPRESORAS FISCALES | D29: 3 | E29: 3 | F29: 3 | G29: =IF(D29="","",IF(D29=0,"-",IF(F29>D29,"ERROR",IF(E29>D29,"ERROR",IF(E29<D29,0,IF(E29>F29,0,IF(F29=D29,1,0))))))) -> 1
A30: TOTAL DE EFECTIVIDAD DE EQUIPOS | G30: =IFERROR(AVERAGE(G9:G28),"-") -> 1
A32: Realizado Por: | C32: Jose Manuel Martinez
A33: Cargo | C33: Lider Tienda
A35: NOTA: El check list de Existencia de Equipos en Tiendas debe ser enviado entre los 5 primeros días del mes, vía correo electrónico al grupo Sistemas, con copia al Director de Servicios de Control.
L39: HOUSE TICKET | M39: INVENTARIO | N39: CABLEADO | O39: MES
K40: TIENDAS | L40: SI | M40: 0 | N40: SI | O40: ENERO
K41: =IF(MAESTRO!A1="","",MAESTRO!A1) -> ******SUCURSALES | L41: NO | M41: 1 | N41: NO | O41: FEBRERO
K42: =IF(MAESTRO!A2="","",MAESTRO!A2) -> LA CASA DE LA CAÑA, C.A. (T. ALTERNA) | M42: 2 | O42: MARZO
K43: =IF(MAESTRO!A3="","",MAESTRO!A3) -> LA CASA DE LA CAÑA, C.A. (T. ANACO) | M43: 3 | O43: ABRIL
K44: =IF(MAESTRO!A4="","",MAESTRO!A4) -> LA CASA DE LA CAÑA, C.A. (T. CUMANÁ) | M44: 4 | O44: MAYO
K45: =IF(MAESTRO!A5="","",MAESTRO!A5) -> LA CASA DE LA CAÑA, C.A. (T. MATURÍN I) | M45: 5 | O45: JUNIO
K46: =IF(MAESTRO!A6="","",MAESTRO!A6) -> LA CASA DE LA CAÑA, C.A. (T. MATURÍN II) | M46: 6 | O46: JULIO
K47: =IF(MAESTRO!A7="","",MAESTRO!A7) -> LA CASA DE LA CAÑA, C.A. (T. NVA. BARCELONA) | M47: 7 | O47: AGOSTO
...

Sheet POZ
C1: CHECK LIST DE EXISTENCIA DE EQUIPOS EN TIENDAS | I1: Código: | J1: FO-MIS-03
I2: Revisión: | J2: 07 | K2: 42720
I3: Fecha: | J3: 42286
B5: SUCURSAL: | C5: RELIVE, C.A. (T. POZUELOS) | H5: FECHA: | I5: 46157
A7: EQUIPOS
A8: Nº | B8: EQUIPOS | D8: INVENTARIO IDEAL | E8: INVENTARIO REAL | F8: EQUIPOS OPERATIVOS | G8: EFECTIVIDAD | H8: OBSERVACIONES
A9: 1 | B9: CPU | D9: 4 | E9: 4 | F9: 4 | G9: =IF(D9="","",IF(D9=0,"-",IF(F9>D9,"ERROR",IF(E9>D9,"ERROR",IF(E9<D9,0,IF(E9>F9,0,IF(F9=D9,1,0))))))) -> 1 | P9: LA CASA DE LA CAÑA, C.A. (T. ALTERNA)
A10: 2 | B10: MOUSE | D10: 4 | E10: 4 | F10: 4 | G10: =IF(D10="","",IF(D10=0,"-",IF(F10>D10,"ERROR",IF(E10>D10,"ERROR",IF(E10<D10,0,IF(E10>F10,0,IF(F10=D10,1,0))))))) -> 1 | P10: LA CASA DE LA CAÑA, C.A. (T. ANACO)
A11: 3 | B11: TECLADOS | D11: 4 | E11: 4 | F11: 4 | G11: =IF(D11="","",IF(D11=0,"-",IF(F11>D11,"ERROR",IF(E11>D11,"ERROR",IF(E11<D11,0,IF(E11>F11,0,IF(F11=D11,1,0))))))) -> 1 | P11: LA CASA DE LA CAÑA, C.A. (T. NVA BARCELONA)
A12: 4 | B12: MONITORES | D12: 4 | E12: 4 | F12: 4 | G12: =IF(D12="","",IF(D12=0,"-",IF(F12>D12,"ERROR",IF(E12>D12,"ERROR",IF(E12<D12,0,IF(E12>F12,0,IF(F12=D12,1,0))))))) -> 1 | P12: LA CASA DE LA CAÑA, C.A. (T. CUMANA)
A13: 5 | B13: REGULADORES | D13: 4 | E13: 4 | F13: 4 | G13: =IF(D13="","",IF(D13=0,"-",IF(F13>D13,"ERROR",IF(E13>D13,"ERROR",IF(E13<D13,0,IF(E13>F13,0,IF(F13=D13,1,0))))))) -> 1 | P13: LA CASA DE LA CAÑA, C.A. (T. MATURIN I)
A14: 6 | B14: IMPRESORA MULTIFUNCIONAL | D14: 1 | E14: 1 | F14: 1 | G14: =IF(D14="","",IF(D14=0,"-",IF(F14>D14,"ERROR",IF(E14>D14,"ERROR",IF(E14<D14,0,IF(E14>F14,0,IF(F14=D14,1,0))))))) -> 1 | P14: LA CASA DE LA CAÑA, C.A. (T. MATURIN II)
A15: 7 | B15: IMPRESORAS FISCALES | D15: 2 | E15: 2 | F15: 2 | G15: =IF(D15="","",IF(D15=0,"-",IF(F15>D15,"ERROR",IF(E15>D15,"ERROR",IF(E15<D15,0,IF(E15>F15,0,IF(F15=D15,1,0))))))) -> 1 | H15: SERIAL 1: | J15: Nº ULT. REPORTE Z: | P15: LA CASA DE LA CAÑA, C.A. (T. FREITES)
H16: SERIAL 2: | J16: Nº ULT. REPORTE Z: | P16: LA CASA DE LA CAÑA, C.A. (T. PUENTE)
H17: SERIAL 3: | J17: Nº ULT. REPORTE Z: | P17: RELIVE, C.A. (T. CHUPARIN)
H18: SERIAL 4: | J18: Nº ULT. REPORTE Z: | P18: RELIVE, C.A. (T. TERRAZAS)
H19: SERIAL 5: | J19: Nº ULT. REPORTE Z: | P19: RELIVE, C.A. (T. TIGRE II)
H20: SERIAL 6: | J20: Nº ULT. REPORTE Z: | P20: RELIVE, C.A. (T. TIGRE III)
H21: SERIAL 7: | J21: Nº ULT. REPORTE Z: | P21: RELIVE, C.A. (T. PLC)
P22: RELIVE, C.A. (T. POZUELOS)
A23: 8 | B23: ROUTER | D23: 1 | E23: 1 | F23: 1 | G23: =IF(D23="","",IF(D23=0,"-",IF(F23>D23,"ERROR",IF(E23>D23,"ERROR",IF(E23<D23,0,IF(E23>F23,0,IF(F23=D23,1,0))))))) -> 1 | P23: OPERADORA VENECIA 2021, C.A (T. VENECIA)
A24: 9 | B24: SUICHE | D24: 1 | E24: 1 | F24: 1 | G24: =IF(D24="","",IF(D24=0,"-",IF(F24>D24,"ERROR",IF(E24>D24,"ERROR",IF(E24<D24,0,IF(E24>F24,0,IF(F24=D24,1,0))))))) -> 1 | P24: OPERADORA VENECIA 2021, C.A (T. BOLIVAR PLC)
A25: 10 | B25: ESCANER DE CODIGO DE BARRAS | D25: 4 | E25: 4 | F25: 4 | G25: =IF(D25="","",IF(D25=0,"-",IF(F25>D25,"ERROR",IF(E25>D25,"ERROR",IF(E25<D25,0,IF(E25>F25,0,IF(F25=D25,1,0))))))) -> 1 | H25: se instala lector de barra nuevo el otro malo | P25: OPERADORA VENECIA 2021, C.A (T. CHURCHILL)
A26: 11 | B26: VISOR DE VENTA | D26: 2 | E26: 2 | F26: 2 | G26: =IF(D26="","",IF(D26=0,"-",IF(F26>D26,"ERROR",IF(E26>D26,"ERROR",IF(E26<D26,0,IF(E26>F26,0,IF(F26=D26,1,0))))))) -> 1 | P26: OPERADORA VENECIA 2021, C.A (T. MANSION)
A27: 12 | B27: DVR | D27: 1 | E27: 1 | F27: 1 | G27: =IF(D27="","",IF(D27=0,"-",IF(F27>D27,"ERROR",IF(E27>D27,"ERROR",IF(E27<D27,0,IF(E27>F27,0,IF(F27=D27,1,0))))))) -> 1 | P27: OPERADORA LECHERIA 2011, C.A
A28: 13 | B28: MODEM | D28: 1 | E28: 1 | F28: 1 | G28: =IF(D28="","",IF(D28=0,"-",IF(F28>D28,"ERROR",IF(E28>D28,"ERROR",IF(E28<D28,0,IF(E28>F28,0,IF(F28=D28,1,0))))))) -> 1
A29: 14 | B29: LIBROS DE IMPRESORAS FISCALES | D29: 2 | E29: 2 | F29: 2 | G29: =IF(D29="","",IF(D29=0,"-",IF(F29>D29,"ERROR",IF(E29>D29,"ERROR",IF(E29<D29,0,IF(E29>F29,0,IF(F29=D29,1,0))))))) -> 1
A30: TOTAL DE EFECTIVIDAD DE EQUIPOS | G30: =IFERROR(AVERAGE(G9:G28),"-") -> 1
A32: Realizado Por: | C32: Zara Campos
A33: Cargo | C33: Lider Tienda
A35: NOTA: El check list de Existencia de Equipos en Tiendas debe ser enviado entre los 5 primeros días del mes, vía correo electrónico al grupo Sistemas, con copia al Director de Servicios de Control.
L39: HOUSE TICKET | M39: INVENTARIO | N39: CABLEADO | O39: MES
K40: TIENDAS | L40: SI | M40: 0 | N40: SI | O40: ENERO
K41: =IF(MAESTRO!A1="","",MAESTRO!A1) -> ******SUCURSALES | L41: NO | M41: 1 | N41: NO | O41: FEBRERO
K42: =IF(MAESTRO!A2="","",MAESTRO!A2) -> LA CASA DE LA CAÑA, C.A. (T. ALTERNA) | M42: 2 | O42: MARZO
K43: =IF(MAESTRO!A3="","",MAESTRO!A3) -> LA CASA DE LA CAÑA, C.A. (T. ANACO) | M43: 3 | O43: ABRIL
K44: =IF(MAESTRO!A4="","",MAESTRO!A4) -> LA CASA DE LA CAÑA, C.A. (T. CUMANÁ) | M44: 4 | O44: MAYO
K45: =IF(MAESTRO!A5="","",MAESTRO!A5) -> LA CASA DE LA CAÑA, C.A. (T. MATURÍN I) | M45: 5 | O45: JUNIO
K46: =IF(MAESTRO!A6="","",MAESTRO!A6) -> LA CASA DE LA CAÑA, C.A. (T. MATURÍN II) | M46: 6 | O46: JULIO
K47: =IF(MAESTRO!A7="","",MAESTRO!A7) -> LA CASA DE LA CAÑA, C.A. (T. NVA. BARCELONA) | M47: 7 | O47: AGOSTO
...

Sheet TIG III
C1: CHECK LIST DE EXISTENCIA DE EQUIPOS EN TIENDAS | I1: Código: | J1: FO-MIS-03
I2: Revisión: | J2: 07 | K2: 42720
I3: Fecha: | J3: 42286
B5: SUCURSAL: | C5: RELIVE, C.A. (T. TIGRE III) | H5: FECHA: | I5: 46157
A7: EQUIPOS
A8: Nº | B8: EQUIPOS | D8: INVENTARIO IDEAL | E8: INVENTARIO REAL | F8: EQUIPOS OPERATIVOS | G8: EFECTIVIDAD | H8: OBSERVACIONES
A9: 1 | B9: CPU | D9: 3 | E9: 3 | F9: 3 | G9: =IF(D9="","",IF(D9=0,"-",IF(F9>D9,"ERROR",IF(E9>D9,"ERROR",IF(E9<D9,0,IF(E9>F9,0,IF(F9=D9,1,0))))))) -> 1 | Q9: LA CASA DE LA CAÑA, C.A. (T. ALTERNA)
A10: 2 | B10: MOUSE | D10: 3 | E10: 3 | F10: 3 | G10: =IF(D10="","",IF(D10=0,"-",IF(F10>D10,"ERROR",IF(E10>D10,"ERROR",IF(E10<D10,0,IF(E10>F10,0,IF(F10=D10,1,0))))))) -> 1 | Q10: LA CASA DE LA CAÑA, C.A. (T. ANACO)
A11: 3 | B11: TECLADOS | D11: 3 | E11: 3 | F11: 3 | G11: =IF(D11="","",IF(D11=0,"-",IF(F11>D11,"ERROR",IF(E11>D11,"ERROR",IF(E11<D11,0,IF(E11>F11,0,IF(F11=D11,1,0))))))) -> 1 | Q11: LA CASA DE LA CAÑA, C.A. (T. NVA BARCELONA)
A12: 4 | B12: MONITORES | D12: 3 | E12: 3 | F12: 3 | G12: =IF(D12="","",IF(D12=0,"-",IF(F12>D12,"ERROR",IF(E12>D12,"ERROR",IF(E12<D12,0,IF(E12>F12,0,IF(F12=D12,1,0))))))) -> 1 | Q12: LA CASA DE LA CAÑA, C.A. (T. CUMANA)
A13: 5 | B13: REGULADORES | D13: 3 | E13: 3 | F13: 3 | G13: =IF(D13="","",IF(D13=0,"-",IF(F13>D13,"ERROR",IF(E13>D13,"ERROR",IF(E13<D13,0,IF(E13>F13,0,IF(F13=D13,1,0))))))) -> 1 | Q13: LA CASA DE LA CAÑA, C.A. (T. MATURIN I)
A14: 6 | B14: IMPRESORA MULTIFUNCIONAL | D14: 1 | E14: 1 | F14: 1 | G14: =IF(D14="","",IF(D14=0,"-",IF(F14>D14,"ERROR",IF(E14>D14,"ERROR",IF(E14<D14,0,IF(E14>F14,0,IF(F14=D14,1,0))))))) -> 1 | Q14: LA CASA DE LA CAÑA, C.A. (T. MATURIN II)
A15: 7 | B15: IMPRESORAS FISCALES | D15: 2 | E15: 2 | F15: 2 | G15: =IF(D15="","",IF(D15=0,"-",IF(F15>D15,"ERROR",IF(E15>D15,"ERROR",IF(E15<D15,0,IF(E15>F15,0,IF(F15=D15,1,0))))))) -> 1 | H15: SERIAL 1: | J15: Nº ULT. REPORTE Z: | Q15: LA CASA DE LA CAÑA, C.A. (T. FREITES)
H16: SERIAL 2: | J16: Nº ULT. REPORTE Z: | Q16: LA CASA DE LA CAÑA, C.A. (T. PUENTE)
H17: SERIAL 3: | J17: Nº ULT. REPORTE Z: | Q17: RELIVE, C.A. (T. CHUPARIN)
H18: SERIAL 4: | J18: Nº ULT. REPORTE Z: | Q18: RELIVE, C.A. (T. TERRAZAS)
H19: SERIAL 5: | J19: Nº ULT. REPORTE Z: | Q19: RELIVE, C.A. (T. TIGRE II)
H20: SERIAL 6: | J20: Nº ULT. REPORTE Z: | Q20: RELIVE, C.A. (T. TIGRE III)
H21: SERIAL 7: | J21: Nº ULT. REPORTE Z: | Q21: RELIVE, C.A. (T. PLC)
Q22: RELIVE, C.A. (T. POZUELOS)
A23: 8 | B23: ROUTER | D23: 1 | E23: 1 | F23: 1 | G23: =IF(D23="","",IF(D23=0,"-",IF(F23>D23,"ERROR",IF(E23>D23,"ERROR",IF(E23<D23,0,IF(E23>F23,0,IF(F23=D23,1,0))))))) -> 1 | Q23: OPERADORA VENECIA 2021, C.A (T. VENECIA)
A24: 9 | B24: SUICHE | D24: 1 | E24: 1 | F24: 1 | G24: =IF(D24="","",IF(D24=0,"-",IF(F24>D24,"ERROR",IF(E24>D24,"ERROR",IF(E24<D24,0,IF(E24>F24,0,IF(F24=D24,1,0))))))) -> 1 | Q24: OPERADORA VENECIA 2021, C.A (T. BOLIVAR PLC)
A25: 10 | B25: ESCANER DE CODIGO DE BARRAS | D25: 3 | E25: 3 | F25: 3 | G25: =IF(D25="","",IF(D25=0,"-",IF(F25>D25,"ERROR",IF(E25>D25,"ERROR",IF(E25<D25,0,IF(E25>F25,0,IF(F25=D25,1,0))))))) -> 1 | Q25: OPERADORA VENECIA 2021, C.A (T. CHURCHILL)
A26: 11 | B26: VISOR DE VENTA | D26: 2 | E26: 2 | F26: 2 | G26: =IF(D26="","",IF(D26=0,"-",IF(F26>D26,"ERROR",IF(E26>D26,"ERROR",IF(E26<D26,0,IF(E26>F26,0,IF(F26=D26,1,0))))))) -> 1 | Q26: OPERADORA VENECIA 2021, C.A (T. MANSION)
A27: 12 | B27: DVR | D27: 1 | E27: 1 | F27: 1 | G27: =IF(D27="","",IF(D27=0,"-",IF(F27>D27,"ERROR",IF(E27>D27,"ERROR",IF(E27<D27,0,IF(E27>F27,0,IF(F27=D27,1,0))))))) -> 1 | Q27: OPERADORA LECHERIA 2011, C.A
A28: 13 | B28: MODEM | D28: 1 | E28: 1 | F28: 1 | G28: =IF(D28="","",IF(D28=0,"-",IF(F28>D28,"ERROR",IF(E28>D28,"ERROR",IF(E28<D28,0,IF(E28>F28,0,IF(F28=D28,1,0))))))) -> 1
A29: 14 | B29: LIBROS DE IMPRESORAS FISCALES | D29: 2 | E29: 2 | F29: 2 | G29: =IF(D29="","",IF(D29=0,"-",IF(F29>D29,"ERROR",IF(E29>D29,"ERROR",IF(E29<D29,0,IF(E29>F29,0,IF(F29=D29,1,0))))))) -> 1
A30: TOTAL DE EFECTIVIDAD DE EQUIPOS | G30: =IFERROR(AVERAGE(G9:G28),"-") -> 1
A32: Realizado Por: | C32: Yesenia Salazar
A33: Cargo | C33: Lider de Tienda
A35: NOTA: El check list de Existencia de Equipos en Tiendas debe ser enviado entre los 5 primeros días del mes, vía correo electrónico al grupo Sistemas, con copia al Director de Servicios de Control.
L39: HOUSE TICKET | M39: INVENTARIO | N39: CABLEADO | O39: MES
K40: TIENDAS | L40: SI | M40: 0 | N40: SI | O40: ENERO
K41: =IF(MAESTRO!A1="","",MAESTRO!A1) -> ******SUCURSALES | L41: NO | M41: 1 | N41: NO | O41: FEBRERO
K42: =IF(MAESTRO!A2="","",MAESTRO!A2) -> LA CASA DE LA CAÑA, C.A. (T. ALTERNA) | M42: 2 | O42: MARZO
K43: =IF(MAESTRO!A3="","",MAESTRO!A3) -> LA CASA DE LA CAÑA, C.A. (T. ANACO) | M43: 3 | O43: ABRIL
K44: =IF(MAESTRO!A4="","",MAESTRO!A4) -> LA CASA DE LA CAÑA, C.A. (T. CUMANÁ) | M44: 4 | O44: MAYO
K45: =IF(MAESTRO!A5="","",MAESTRO!A5) -> LA CASA DE LA CAÑA, C.A. (T. MATURÍN I) | M45: 5 | O45: JUNIO
K46: =IF(MAESTRO!A6="","",MAESTRO!A6) -> LA CASA DE LA CAÑA, C.A. (T. MATURÍN II) | M46: 6 | O46: JULIO
K47: =IF(MAESTRO!A7="","",MAESTRO!A7) -> LA CASA DE LA CAÑA, C.A. (T. NVA. BARCELONA) | M47: 7 | O47: AGOSTO
...

Sheet LEC
C1: CHECK LIST DE EXISTENCIA DE EQUIPOS EN TIENDAS | I1: Código: | J1: FO-MIS-03
I2: Revisión: | J2: 07 | K2: 42720
I3: Fecha: | J3: 42286
B5: SUCURSAL: | C5: OPERADORA LECHERIA 2011, C.A. (T. LECHERIA) | H5: FECHA: | I5: 46157
A7: EQUIPOS
A8: Nº | B8: EQUIPOS | D8: INVENTARIO IDEAL | E8: INVENTARIO REAL | F8: EQUIPOS OPERATIVOS | G8: EFECTIVIDAD | H8: OBSERVACIONES
A9: 1 | B9: CPU | D9: 8 | E9: 8 | F9: 8 | G9: =IF(D9="","",IF(D9=0,"-",IF(F9>D9,"ERROR",IF(E9>D9,"ERROR",IF(E9<D9,0,IF(E9>F9,0,IF(F9=D9,1,0))))))) -> 1 | Q9: LA CASA DE LA CAÑA, C.A. (T. ALTERNA)
A10: 2 | B10: MOUSE | D10: 8 | E10: 8 | F10: 8 | G10: =IF(D10="","",IF(D10=0,"-",IF(F10>D10,"ERROR",IF(E10>D10,"ERROR",IF(E10<D10,0,IF(E10>F10,0,IF(F10=D10,1,0))))))) -> 1 | Q10: LA CASA DE LA CAÑA, C.A. (T. ANACO)
A11: 3 | B11: TECLADOS | D11: 8 | E11: 8 | F11: 8 | G11: =IF(D11="","",IF(D11=0,"-",IF(F11>D11,"ERROR",IF(E11>D11,"ERROR",IF(E11<D11,0,IF(E11>F11,0,IF(F11=D11,1,0))))))) -> 1 | Q11: LA CASA DE LA CAÑA, C.A. (T. NVA BARCELONA)
A12: 4 | B12: MONITORES | D12: 8 | E12: 8 | F12: 8 | G12: =IF(D12="","",IF(D12=0,"-",IF(F12>D12,"ERROR",IF(E12>D12,"ERROR",IF(E12<D12,0,IF(E12>F12,0,IF(F12=D12,1,0))))))) -> 1 | Q12: LA CASA DE LA CAÑA, C.A. (T. CUMANA)
A13: 5 | B13: REGULADORES | D13: 8 | E13: 8 | F13: 8 | G13: =IF(D13="","",IF(D13=0,"-",IF(F13>D13,"ERROR",IF(E13>D13,"ERROR",IF(E13<D13,0,IF(E13>F13,0,IF(F13=D13,1,0))))))) -> 1 | Q13: LA CASA DE LA CAÑA, C.A. (T. MATURIN I)
A14: 6 | B14: IMPRESORA MULTIFUNCIONAL | D14: 1 | E14: 1 | F14: 1 | G14: =IF(D14="","",IF(D14=0,"-",IF(F14>D14,"ERROR",IF(E14>D14,"ERROR",IF(E14<D14,0,IF(E14>F14,0,IF(F14=D14,1,0))))))) -> 1 | Q14: LA CASA DE LA CAÑA, C.A. (T. MATURIN II)
A15: 7 | B15: IMPRESORAS FISCALES | D15: 6 | E15: 6 | F15: 6 | G15: =IF(D15="","",IF(D15=0,"-",IF(F15>D15,"ERROR",IF(E15>D15,"ERROR",IF(E15<D15,0,IF(E15>F15,0,IF(F15=D15,1,0))))))) -> 1 | H15: SERIAL 1: | J15: Nº ULT. REPORTE Z: | Q15: LA CASA DE LA CAÑA, C.A. (T. FREITES)
H16: SERIAL 2: | J16: Nº ULT. REPORTE Z: | Q16: LA CASA DE LA CAÑA, C.A. (T. PUENTE)
H17: SERIAL 3: | J17: Nº ULT. REPORTE Z: | Q17: RELIVE, C.A. (T. CHUPARIN)
H18: SERIAL 4: | J18: Nº ULT. REPORTE Z: | Q18: RELIVE, C.A. (T. TERRAZAS)
H19: SERIAL 5: | J19: Nº ULT. REPORTE Z: | Q19: RELIVE, C.A. (T. TIGRE II)
H20: SERIAL 6: | J20: Nº ULT. REPORTE Z: | Q20: RELIVE, C.A. (T. TIGRE III)
H21: SERIAL 7: | J21: Nº ULT. REPORTE Z: | Q21: RELIVE, C.A. (T. PLC)
H22: SERIAL 8: | J22: Nº ULT. REPORTE Z: | Q22: RELIVE, C.A. (T. POZUELOS)
H23: SERIAL 9: | J23: Nº ULT. REPORTE Z: | Q23: OPERADORA VENECIA 2021, C.A (T. VENECIA)
Q24: OPERADORA VENECIA 2021, C.A (T. BOLIVAR PLC)
A25: 8 | B25: ROUTER | D25: 3 | E25: 3 | F25: 3 | G25: =IF(D25="","",IF(D25=0,"-",IF(F25>D25,"ERROR",IF(E25>D25,"ERROR",IF(E25<D25,0,IF(E25>F25,0,IF(F25=D25,1,0))))))) -> 1 | Q25: OPERADORA VENECIA 2021, C.A (T. CHURCHILL)
A26: 9 | B26: SUICHE | D26: 4 | E26: 4 | F26: 4 | G26: =IF(D26="","",IF(D26=0,"-",IF(F26>D26,"ERROR",IF(E26>D26,"ERROR",IF(E26<D26,0,IF(E26>F26,0,IF(F26=D26,1,0))))))) -> 1 | Q26: OPERADORA VENECIA 2021, C.A (T. MANSION)
