Workbook
Name CUMPLIO: #REF!
Name CUMPLIO: #REF!
Name CUMPLIO: #REF!
Name CUMPLIO: #REF!
Name CUMPLIO: #REF!
Name CUMPLIO: #REF!
Name CUMPLIO: #REF!
Name CUMPLIO: #REF!
Name CUMPLIO: #REF!
Name CUMPLIO: #REF!
Name CUMPLIO: #REF!
Name CUMPLIO: #REF!
Name CUMPLIO: #REF!
Name CUMPLIO: #REF!
Name CUMPLIO: #REF!
Name CUMPLIO: #REF!
Name CUMPLIO: #REF!
Name EQUIPO: #REF!
Name EQUIPO: #REF!
Name EQUIPO: #REF!
Name EQUIPO: #REF!
Name EQUIPO: #REF!
Name EQUIPO: #REF!
Name EQUIPO: #REF!
Name EQUIPO: #REF!
Name EQUIPO: #REF!
Name EQUIPO: #REF!
Name EQUIPO: #REF!
Name EQUIPO: #REF!
Name EQUIPO: #REF!
Name EQUIPO: #REF!
Name EQUIPO: #REF!
Name EQUIPO: #REF!
Name EQUIPO: #REF!
Name EQUIPOS: #REF!
Name EQUIPOS: #REF!
Name EQUIPOS: #REF!
Name EQUIPOS: #REF!
Name EQUIPOS: #REF!
Name EQUIPOS: #REF!
Name EQUIPOS: #REF!
Name EQUIPOS: #REF!
Name EQUIPOS: #REF!
Name EQUIPOS: #REF!
Name EQUIPOS: #REF!
Name EQUIPOS: #REF!
Name EQUIPOS: #REF!
Name EQUIPOS: #REF!
Name EQUIPOS: #REF!
Name EQUIPOS: #REF!
Name EQUIPOS: #REF!
Name LISTA: #REF!
Name LISTA: #REF!
Name LISTA: #REF!
Name LISTA: #REF!
Name LISTA: #REF!
Name LISTA: #REF!
Name LISTA: #REF!
Name LISTA: #REF!
Name LISTA: #REF!

Sheet BERNARDINO
C1: CHECK LIST DE EXISTENCIA DE EQUIPOS EN TIENDAS | I1: Código: | J1: FO-MIS-03
I2: Revisión: | J2: 07 | K2: 42720
I3: Fecha: | J3: 42286 | Q3: Operadora Lecheria 2025, C.A San Bernandino
Q4: Operadora Lecheria 2025, C.A Drop Shop El Paraiso
B5: SUCURSAL: | C5: Operadora Lecheria 2025, C.A San Bernandino | H5: FECHA: | I5: 46157 | Q5: Operadora Lecheria 2025, C.A El Paraiso
Q6: Operadora Lecheria 2025, C.A Presidente Medina
A7: EQUIPOS | Q7: Operadora Lecheria 2025, C.A Los Flores
A8: Nº | B8: EQUIPOS | D8: INVENTARIO IDEAL | E8: INVENTARIO REAL | F8: EQUIPOS OPERATIVOS | G8: EFECTIVIDAD | H8: OBSERVACIONES | Q8: Operadora Lecheria 2025, C.A San Antonio
A9: 1 | B9: CPU | D9: 4 | E9: 4 | F9: 4 | G9: =IF(D9="","",IF(D9=0,"-",IF(F9>D9,"ERROR",IF(E9>D9,"ERROR",IF(E9<D9,0,IF(E9>F9,0,IF(F9=D9,1,0))))))) -> 1 | Q9: Operadora Lecheria 2025, C.A CCCT | V9: LA CASA DE LA CAÑA, C.A. (T. ALTERNA)
A10: 2 | B10: MOUSE | D10: 4 | E10: 4 | F10: 3 | G10: =IF(D10="","",IF(D10=0,"-",IF(F10>D10,"ERROR",IF(E10>D10,"ERROR",IF(E10<D10,0,IF(E10>F10,0,IF(F10=D10,1,0))))))) -> 0 | Q10: Operadora Lecheria 2025, C.A Guarenas Centro | V10: LA CASA DE LA CAÑA, C.A. (T. ANACO)
A11: 3 | B11: TECLADOS | D11: 4 | E11: 3 | F11: 4 | G11: =IF(D11="","",IF(D11=0,"-",IF(F11>D11,"ERROR",IF(E11>D11,"ERROR",IF(E11<D11,0,IF(E11>F11,0,IF(F11=D11,1,0))))))) -> 0 | Q11: Operadora Lecheria 2025, C.A Guarenas 27 De Febrero | V11: LA CASA DE LA CAÑA, C.A. (T. NVA BARCELONA)
A12: 4 | B12: MONITORES | D12: 4 | E12: 3 | F12: 4 | G12: =IF(D12="","",IF(D12=0,"-",IF(F12>D12,"ERROR",IF(E12>D12,"ERROR",IF(E12<D12,0,IF(E12>F12,0,IF(F12=D12,1,0))))))) -> 0 | Q12: Operadora Lecheria 2025, C.A Guatire Las Rosas | V12: LA CASA DE LA CAÑA, C.A. (T. CUMANA)
A13: 5 | B13: REGULADORES | D13: 4 | E13: 4 | F13: 4 | G13: =IF(D13="","",IF(D13=0,"-",IF(F13>D13,"ERROR",IF(E13>D13,"ERROR",IF(E13<D13,0,IF(E13>F13,0,IF(F13=D13,1,0))))))) -> 1 | Q13: Operadora Lecheria 2025, C.A Guatire Centro | V13: LA CASA DE LA CAÑA, C.A. (T. MATURIN I)
A14: 6 | B14: IMPRESORA MULTIFUNCIONAL | D14: 1 | E14: 1 | F14: 1 | G14: =IF(D14="","",IF(D14=0,"-",IF(F14>D14,"ERROR",IF(E14>D14,"ERROR",IF(E14<D14,0,IF(E14>F14,0,IF(F14=D14,1,0))))))) -> 1 | Q14: Operadora Lecheria 2025, C.A Guatire El Palmar | V14: LA CASA DE LA CAÑA, C.A. (T. MATURIN II)
A15: 7 | B15: IMPRESORAS FISCALES | D15: 4 | E15: 4 | F15: 4 | G15: =IF(D15="","",IF(D15=0,"-",IF(F15>D15,"ERROR",IF(E15>D15,"ERROR",IF(E15<D15,0,IF(E15>F15,0,IF(F15=D15,1,0))))))) -> 1 | H15: SERIAL 1: | J15: Nº ULT. REPORTE Z: | Q15: Operadora Lecheria 2025, C.A Caucagua | V15: LA CASA DE LA CAÑA, C.A. (T. FREITES)
H16: SERIAL 2: | J16: Nº ULT. REPORTE Z: | Q16: Operadora Lecheria 2025, C.A Higuerote | V16: LA CASA DE LA CAÑA, C.A. (T. PUENTE)
H17: SERIAL 3: | J17: Nº ULT. REPORTE Z: | Q17: Operadora Lecheria 2025, C.A Las Mercedes | V17: RELIVE, C.A. (T. CHUPARIN)
H18: SERIAL 4: | J18: Nº ULT. REPORTE Z: | Q18: Operadora Lecheria 2025, C.A San Martin | U18: =W23&" "&T23 | V18: RELIVE, C.A. (T. TERRAZAS)
H19: SERIAL 5: | J19: Nº ULT. REPORTE Z: | Q19: Operadora Lecheria 2025, C.A Baruta | U19: =W24&" "&T24 | V19: RELIVE, C.A. (T. TIGRE II)
H20: SERIAL 6: | J20: Nº ULT. REPORTE Z: | Q20: Operadora Lecheria 2025, C.A Nuevo Circo | U20: =W25&" "&T25 | V20: RELIVE, C.A. (T. TIGRE III)
H21: SERIAL 7: | J21: Nº ULT. REPORTE Z: | Q21: Operadora Lecheria 2025, C.A El Silencio | V21: RELIVE, C.A. (T. PLC)
Q22: Operadora Lecheria 2025, C.A Drop Shop Castellana | V22: RELIVE, C.A. (T. POZUELOS)
A23: 8 | B23: ROUTER | D23: 1 | E23: 1 | F23: 1 | G23: =IF(D23="","",IF(D23=0,"-",IF(F23>D23,"ERROR",IF(E23>D23,"ERROR",IF(E23<D23,0,IF(E23>F23,0,IF(F23=D23,1,0))))))) -> 1 | V23: OPERADORA VENECIA 2021, C.A (T. VENECIA)
A24: 9 | B24: SUICHE | D24: 1 | E24: 1 | F24: 1 | G24: =IF(D24="","",IF(D24=0,"-",IF(F24>D24,"ERROR",IF(E24>D24,"ERROR",IF(E24<D24,0,IF(E24>F24,0,IF(F24=D24,1,0))))))) -> 1 | V24: OPERADORA VENECIA 2021, C.A (T. BOLIVAR PLC)
A25: 10 | B25: ESCANER DE CODIGO DE BARRAS | D25: 4 | E25: 4 | F25: 4 | G25: =IF(D25="","",IF(D25=0,"-",IF(F25>D25,"ERROR",IF(E25>D25,"ERROR",IF(E25<D25,0,IF(E25>F25,0,IF(F25=D25,1,0))))))) -> 1 | V25: OPERADORA VENECIA 2021, C.A (T. CHURCHILL)
A26: 11 | B26: VISOR DE VENTAS | D26: 0 | E26: 1 | F26: 1 | G26: =IF(D26="","",IF(D26=0,"-",IF(F26>D26,"ERROR",IF(E26>D26,"ERROR",IF(E26<D26,0,IF(E26>F26,0,IF(F26=D26,1,0))))))) -> - | V26: OPERADORA VENECIA 2021, C.A (T. MANSION)
A27: 12 | B27: DVR | D27: 1 | E27: 1 | F27: 1 | G27: =IF(D27="","",IF(D27=0,"-",IF(F27>D27,"ERROR",IF(E27>D27,"ERROR",IF(E27<D27,0,IF(E27>F27,0,IF(F27=D27,1,0))))))) -> 1 | V27: OPERADORA LECHERIA 2011, C.A
A28: 13 | B28: MODEM | D28: 0 | E28: 1 | F28: 1 | G28: =IF(D28="","",IF(D28=0,"-",IF(F28>D28,"ERROR",IF(E28>D28,"ERROR",IF(E28<D28,0,IF(E28>F28,0,IF(F28=D28,1,0))))))) -> -
A29: 14 | B29: LIBROS DE IMPRESORAS FISCALES | D29: 4 | E29: 4 | F29: 4 | G29: =IF(D29="","",IF(D29=0,"-",IF(F29>D29,"ERROR",IF(E29>D29,"ERROR",IF(E29<D29,0,IF(E29>F29,0,IF(F29=D29,1,0))))))) -> 1
A30: TOTAL DE EFECTIVIDAD DE EQUIPOS | G30: =IFERROR(AVERAGE(G10:G29),"-") -> 0.72727273
A31: Realizado Por: | C31: David Tayupo
A32: Cargo | C32: Lider De Tienda
A34: NOTA: El check list de Existencia de Equipos en Tiendas debe ser enviado entre los 5 primeros días del mes, vía correo electrónico al grupo Sistemas, con copia al Director de Servicios de Control.
L39: HOUSE TICKET | M39: INVENTARIO | N39: CABLEADO | O39: MES
L40: SI | M40: 0 | N40: SI | O40: ENERO
L41: NO | M41: 1 | N41: NO | O41: FEBRERO
M42: 2 | O42: MARZO
M43: 3 | O43: ABRIL
M44: 4 | O44: MAYO
M45: 5 | O45: JUNIO
...

Sheet DSPARAISO
C1: CHECK LIST DE EXISTENCIA DE EQUIPOS EN TIENDAS | I1: Código: | J1: FO-MIS-03 | P1: Operadora Lecheria 2025, C.A San Bernandino
I2: Revisión: | J2: 07 | K2: 42720 | P2: Operadora Lecheria 2025, C.A Drop Shop El Paraiso
I3: Fecha: | J3: 42286 | P3: Operadora Lecheria 2025, C.A El Paraiso
P4: Operadora Lecheria 2025, C.A Presidente Medina
B5: SUCURSAL: | C5: Operadora Lecheria 2025, C.A El Paraiso | H5: FECHA: | I5: 46157 | P5: Operadora Lecheria 2025, C.A Los Flores
P6: Operadora Lecheria 2025, C.A San Antonio
A7: EQUIPOS | P7: Operadora Lecheria 2025, C.A CCCT
A8: Nº | B8: EQUIPOS | D8: INVENTARIO IDEAL | E8: INVENTARIO REAL | F8: EQUIPOS OPERATIVOS | G8: EFECTIVIDAD | H8: OBSERVACIONES | P8: Operadora Lecheria 2025, C.A Guarenas Centro
A9: 1 | B9: CPU | D9: 4 | E9: 4 | F9: 4 | G9: =IF(D9="","",IF(D9=0,"-",IF(F9>D9,"ERROR",IF(E9>D9,"ERROR",IF(E9<D9,0,IF(E9>F9,0,IF(F9=D9,1,0))))))) -> 1 | P9: Operadora Lecheria 2025, C.A Guarenas 27 De Febrero | U9: LA CASA DE LA CAÑA, C.A. (T. ALTERNA)
A10: 2 | B10: MOUSE | D10: 4 | E10: 4 | F10: 4 | G10: =IF(D10="","",IF(D10=0,"-",IF(F10>D10,"ERROR",IF(E10>D10,"ERROR",IF(E10<D10,0,IF(E10>F10,0,IF(F10=D10,1,0))))))) -> 1 | P10: Operadora Lecheria 2025, C.A Guatire Las Rosas | U10: LA CASA DE LA CAÑA, C.A. (T. ANACO)
A11: 3 | B11: TECLADOS | D11: 4 | E11: 4 | F11: 4 | G11: =IF(D11="","",IF(D11=0,"-",IF(F11>D11,"ERROR",IF(E11>D11,"ERROR",IF(E11<D11,0,IF(E11>F11,0,IF(F11=D11,1,0))))))) -> 1 | P11: Operadora Lecheria 2025, C.A Guatire Centro | U11: LA CASA DE LA CAÑA, C.A. (T. NVA BARCELONA)
A12: 4 | B12: MONITORES | D12: 4 | E12: 4 | F12: 4 | G12: =IF(D12="","",IF(D12=0,"-",IF(F12>D12,"ERROR",IF(E12>D12,"ERROR",IF(E12<D12,0,IF(E12>F12,0,IF(F12=D12,1,0))))))) -> 1 | P12: Operadora Lecheria 2025, C.A Guatire El Palmar | U12: LA CASA DE LA CAÑA, C.A. (T. CUMANA)
A13: 5 | B13: REGULADORES | D13: 4 | E13: 4 | F13: 4 | G13: =IF(D13="","",IF(D13=0,"-",IF(F13>D13,"ERROR",IF(E13>D13,"ERROR",IF(E13<D13,0,IF(E13>F13,0,IF(F13=D13,1,0))))))) -> 1 | P13: Operadora Lecheria 2025, C.A Caucagua | U13: LA CASA DE LA CAÑA, C.A. (T. MATURIN I)
A14: 6 | B14: IMPRESORA MULTIFUNCIONAL | D14: 1 | E14: 1 | F14: 1 | G14: =IF(D14="","",IF(D14=0,"-",IF(F14>D14,"ERROR",IF(E14>D14,"ERROR",IF(E14<D14,0,IF(E14>F14,0,IF(F14=D14,1,0))))))) -> 1 | P14: Operadora Lecheria 2025, C.A Higuerote | U14: LA CASA DE LA CAÑA, C.A. (T. MATURIN II)
A15: 7 | B15: IMPRESORAS FISCALES | D15: 4 | E15: 4 | F15: 4 | G15: =IF(D15="","",IF(D15=0,"-",IF(F15>D15,"ERROR",IF(E15>D15,"ERROR",IF(E15<D15,0,IF(E15>F15,0,IF(F15=D15,1,0))))))) -> 1 | H15: SERIAL 1: | J15: Nº ULT. REPORTE Z: | P15: Operadora Lecheria 2025, C.A Las Mercedes | U15: LA CASA DE LA CAÑA, C.A. (T. FREITES)
H16: SERIAL 2: | J16: Nº ULT. REPORTE Z: | P16: Operadora Lecheria 2025, C.A San Martin | U16: LA CASA DE LA CAÑA, C.A. (T. PUENTE)
H17: SERIAL 3: | J17: Nº ULT. REPORTE Z: | P17: Operadora Lecheria 2025, C.A Baruta | U17: RELIVE, C.A. (T. CHUPARIN)
H18: SERIAL 4: | J18: Nº ULT. REPORTE Z: | P18: Operadora Lecheria 2025, C.A Nuevo Circo | U18: RELIVE, C.A. (T. TERRAZAS)
H19: SERIAL 5: | J19: Nº ULT. REPORTE Z: | P19: Operadora Lecheria 2025, C.A El Silencio | U19: RELIVE, C.A. (T. TIGRE II)
H20: SERIAL 6: | J20: Nº ULT. REPORTE Z: | P20: Operadora Lecheria 2025, C.A Drop Shop Castellana | U20: RELIVE, C.A. (T. TIGRE III)
H21: SERIAL 7: | J21: Nº ULT. REPORTE Z: | U21: RELIVE, C.A. (T. PLC)
U22: RELIVE, C.A. (T. POZUELOS)
A23: 8 | B23: ROUTER | D23: 1 | E23: 1 | F23: 1 | G23: =IF(D23="","",IF(D23=0,"-",IF(F23>D23,"ERROR",IF(E23>D23,"ERROR",IF(E23<D23,0,IF(E23>F23,0,IF(F23=D23,1,0))))))) -> 1 | U23: OPERADORA VENECIA 2021, C.A (T. VENECIA)
A24: 9 | B24: SUICHE | D24: 1 | E24: 1 | F24: 1 | G24: =IF(D24="","",IF(D24=0,"-",IF(F24>D24,"ERROR",IF(E24>D24,"ERROR",IF(E24<D24,0,IF(E24>F24,0,IF(F24=D24,1,0))))))) -> 1 | U24: OPERADORA VENECIA 2021, C.A (T. BOLIVAR PLC)
A25: 10 | B25: ESCANER DE CODIGO DE BARRAS | D25: 4 | E25: 4 | F25: 4 | G25: =IF(D25="","",IF(D25=0,"-",IF(F25>D25,"ERROR",IF(E25>D25,"ERROR",IF(E25<D25,0,IF(E25>F25,0,IF(F25=D25,1,0))))))) -> 1 | U25: OPERADORA VENECIA 2021, C.A (T. CHURCHILL)
A26: 11 | B26: VISOR DE VENTA | D26: 0 | E26: 1 | F26: 1 | G26: =IF(D26="","",IF(D26=0,"-",IF(F26>D26,"ERROR",IF(E26>D26,"ERROR",IF(E26<D26,0,IF(E26>F26,0,IF(F26=D26,1,0))))))) -> - | U26: OPERADORA VENECIA 2021, C.A (T. MANSION)
A27: 12 | B27: DVR | D27: 1 | E27: 1 | F27: 1 | G27: =IF(D27="","",IF(D27=0,"-",IF(F27>D27,"ERROR",IF(E27>D27,"ERROR",IF(E27<D27,0,IF(E27>F27,0,IF(F27=D27,1,0))))))) -> 1 | U27: OPERADORA LECHERIA 2011, C.A
A28: 13 | B28: MODEM | D28: 0 | E28: 1 | F28: 1 | G28: =IF(D28="","",IF(D28=0,"-",IF(F28>D28,"ERROR",IF(E28>D28,"ERROR",IF(E28<D28,0,IF(E28>F28,0,IF(F28=D28,1,0))))))) -> -
A29: 14 | B29: LIBROS DE IMPRESORAS FISCALES | D29: 4 | E29: 4 | F29: 4 | G29: =IF(D29="","",IF(D29=0,"-",IF(F29>D29,"ERROR",IF(E29>D29,"ERROR",IF(E29<D29,0,IF(E29>F29,0,IF(F29=D29,1,0))))))) -> 1
A30: TOTAL DE EFECTIVIDAD DE EQUIPOS | G30: =IFERROR(AVERAGE(G10:G29),"-") -> 1
A31: Realizado Por:
A32: Cargo
A34: NOTA: El check list de Existencia de Equipos en Tiendas debe ser enviado entre los 5 primeros días del mes, vía correo electrónico al grupo Sistemas, con copia al Director de Servicios de Control.
L38: HOUSE TICKET | M38: INVENTARIO | N38: CABLEADO | O38: MES
L39: SI | M39: 0 | N39: SI | O39: ENERO
L40: NO | M40: 1 | N40: NO | O40: FEBRERO
M41: 2 | O41: MARZO
M42: 3 | O42: ABRIL
M43: 4 | O43: MAYO
M44: 5 | O44: JUNIO
...

Sheet PARAISO
C1: CHECK LIST DE EXISTENCIA DE EQUIPOS EN TIENDAS | I1: Código: | J1: FO-MIS-03
I2: Revisión: | J2: 07 | K2: 42720
I3: Fecha: | J3: 42286
B5: SUCURSAL: | C5: Operadora Lecheria 2025, C.A Drop Shop El Paraiso | H5: FECHA: | I5: 46157
A7: EQUIPOS
A8: Nº | B8: EQUIPOS | D8: INVENTARIO IDEAL | E8: INVENTARIO REAL | F8: EQUIPOS OPERATIVOS | G8: EFECTIVIDAD | H8: OBSERVACIONES
A9: 1 | B9: CPU | D9: 3 | E9: 3 | F9: 3 | G9: =IF(D9="","",IF(D9=0,"-",IF(F9>D9,"ERROR",IF(E9>D9,"ERROR",IF(E9<D9,0,IF(E9>F9,0,IF(F9=D9,1,0))))))) -> 1 | O9: Operadora Lecheria 2025, C.A San Bernandino
A10: 2 | B10: MOUSE | D10: 3 | E10: 3 | F10: 3 | G10: =IF(D10="","",IF(D10=0,"-",IF(F10>D10,"ERROR",IF(E10>D10,"ERROR",IF(E10<D10,0,IF(E10>F10,0,IF(F10=D10,1,0))))))) -> 1 | O10: Operadora Lecheria 2025, C.A Drop Shop El Paraiso
A11: 3 | B11: TECLADOS | D11: 3 | E11: 3 | F11: 3 | G11: =IF(D11="","",IF(D11=0,"-",IF(F11>D11,"ERROR",IF(E11>D11,"ERROR",IF(E11<D11,0,IF(E11>F11,0,IF(F11=D11,1,0))))))) -> 1 | O11: Operadora Lecheria 2025, C.A El Paraiso
A12: 4 | B12: MONITORES | D12: 3 | E12: 3 | F12: 3 | G12: =IF(D12="","",IF(D12=0,"-",IF(F12>D12,"ERROR",IF(E12>D12,"ERROR",IF(E12<D12,0,IF(E12>F12,0,IF(F12=D12,1,0))))))) -> 1 | O12: Operadora Lecheria 2025, C.A Presidente Medina
A13: 5 | B13: REGULADORES | D13: 3 | E13: 3 | F13: 3 | G13: =IF(D13="","",IF(D13=0,"-",IF(F13>D13,"ERROR",IF(E13>D13,"ERROR",IF(E13<D13,0,IF(E13>F13,0,IF(F13=D13,1,0))))))) -> 1 | O13: Operadora Lecheria 2025, C.A Los Flores
A14: 6 | B14: IMPRESORA MULTIFUNCIONAL | D14: 1 | E14: 1 | F14: 1 | G14: =IF(D14="","",IF(D14=0,"-",IF(F14>D14,"ERROR",IF(E14>D14,"ERROR",IF(E14<D14,0,IF(E14>F14,0,IF(F14=D14,1,0))))))) -> 1 | O14: Operadora Lecheria 2025, C.A San Antonio
A15: 7 | B15: IMPRESORAS FISCALES | D15: 3 | E15: 3 | F15: 3 | G15: =IF(D15="","",IF(D15=0,"-",IF(F15>D15,"ERROR",IF(E15>D15,"ERROR",IF(E15<D15,0,IF(E15>F15,0,IF(F15=D15,1,0))))))) -> 1 | H15: SERIAL 1: | J15: Nº ULT. REPORTE Z: | O15: Operadora Lecheria 2025, C.A CCCT
H16: SERIAL 2: | J16: Nº ULT. REPORTE Z: | O16: Operadora Lecheria 2025, C.A Guarenas Centro
H17: SERIAL 3: | J17: Nº ULT. REPORTE Z: | O17: Operadora Lecheria 2025, C.A Guarenas 27 De Febrero
H18: SERIAL 4: | J18: Nº ULT. REPORTE Z: | O18: Operadora Lecheria 2025, C.A Guatire Las Rosas
H19: SERIAL 5: | J19: Nº ULT. REPORTE Z: | O19: Operadora Lecheria 2025, C.A Guatire Centro
H20: SERIAL 6: | J20: Nº ULT. REPORTE Z: | O20: Operadora Lecheria 2025, C.A Guatire El Palmar
H21: SERIAL 7: | J21: Nº ULT. REPORTE Z: | O21: Operadora Lecheria 2025, C.A Caucagua
O22: Operadora Lecheria 2025, C.A Higuerote
A23: 8 | B23: ROUTER | D23: 1 | E23: 1 | F23: 1 | G23: =IF(D23="","",IF(D23=0,"-",IF(F23>D23,"ERROR",IF(E23>D23,"ERROR",IF(E23<D23,0,IF(E23>F23,0,IF(F23=D23,1,0))))))) -> 1 | O23: Operadora Lecheria 2025, C.A Las Mercedes
A24: 9 | B24: SUICHE | D24: 1 | E24: 1 | F24: 1 | G24: =IF(D24="","",IF(D24=0,"-",IF(F24>D24,"ERROR",IF(E24>D24,"ERROR",IF(E24<D24,0,IF(E24>F24,0,IF(F24=D24,1,0))))))) -> 1 | O24: Operadora Lecheria 2025, C.A San Martin
A25: 10 | B25: ESCANER DE CODIGO DE BARRAS | D25: 3 | E25: 3 | F25: 3 | G25: =IF(D25="","",IF(D25=0,"-",IF(F25>D25,"ERROR",IF(E25>D25,"ERROR",IF(E25<D25,0,IF(E25>F25,0,IF(F25=D25,1,0))))))) -> 1 | O25: Operadora Lecheria 2025, C.A Baruta
A26: 11 | B26: VISOR DE VENTA | D26: 0 | E26: 1 | F26: 1 | G26: =IF(D26="","",IF(D26=0,"-",IF(F26>D26,"ERROR",IF(E26>D26,"ERROR",IF(E26<D26,0,IF(E26>F26,0,IF(F26=D26,1,0))))))) -> - | O26: Operadora Lecheria 2025, C.A Nuevo Circo
A27: 12 | B27: DVR | D27: 1 | E27: 1 | F27: 1 | G27: =IF(D27="","",IF(D27=0,"-",IF(F27>D27,"ERROR",IF(E27>D27,"ERROR",IF(E27<D27,0,IF(E27>F27,0,IF(F27=D27,1,0))))))) -> 1 | O27: Operadora Lecheria 2025, C.A El Silencio
A28: 13 | B28: MODEM | D28: 0 | E28: 1 | F28: 1 | G28: =IF(D28="","",IF(D28=0,"-",IF(F28>D28,"ERROR",IF(E28>D28,"ERROR",IF(E28<D28,0,IF(E28>F28,0,IF(F28=D28,1,0))))))) -> - | O28: Operadora Lecheria 2025, C.A Drop Shop Castellana
A29: 14 | B29: LIBROS DE IMPRESORAS FISCALES | D29: 3 | E29: 3 | F29: 3 | G29: =IF(D29="","",IF(D29=0,"-",IF(F29>D29,"ERROR",IF(E29>D29,"ERROR",IF(E29<D29,0,IF(E29>F29,0,IF(F29=D29,1,0))))))) -> 1
A30: TOTAL DE EFECTIVIDAD DE EQUIPOS | G30: =IFERROR(AVERAGE(G9:G28),"-") -> 1
A32: Realizado Por:
A33: Cargo
A35: NOTA: El check list de Existencia de Equipos en Tiendas debe ser enviado entre los 5 primeros días del mes, vía correo electrónico al grupo Sistemas, con copia al Director de Servicios de Control.
L39: HOUSE TICKET | M39: INVENTARIO | N39: CABLEADO | O39: MES
K40: TIENDAS | L40: SI | M40: 0 | N40: SI | O40: ENERO
K41: =IF(MAESTRO!A1="","",MAESTRO!A1) -> ******SUCURSALES | L41: NO | M41: 1 | N41: NO | O41: FEBRERO
K42: =IF(MAESTRO!A2="","",MAESTRO!A2) -> LA CASA DE LA CAÑA, C.A. (T. ALTERNA) | M42: 2 | O42: MARZO
K43: =IF(MAESTRO!A3="","",MAESTRO!A3) -> LA CASA DE LA CAÑA, C.A. (T. ANACO) | M43: 3 | O43: ABRIL
K44: =IF(MAESTRO!A4="","",MAESTRO!A4) -> LA CASA DE LA CAÑA, C.A. (T. CUMANÁ) | M44: 4 | O44: MAYO
K45: =IF(MAESTRO!A5="","",MAESTRO!A5) -> LA CASA DE LA CAÑA, C.A. (T. MATURÍN I) | M45: 5 | O45: JUNIO
K46: =IF(MAESTRO!A6="","",MAESTRO!A6) -> LA CASA DE LA CAÑA, C.A. (T. MATURÍN II) | M46: 6 | O46: JULIO
K47: =IF(MAESTRO!A7="","",MAESTRO!A7) -> LA CASA DE LA CAÑA, C.A. (T. NVA. BARCELONA) | M47: 7 | O47: AGOSTO
...

Sheet PRESIDENTE
C1: CHECK LIST DE EXISTENCIA DE EQUIPOS EN TIENDAS | I1: Código: | J1: FO-MIS-03 | L1: Operadora Lecheria 2025, C.A San Bernandino
I2: Revisión: | J2: 07 | K2: 42720 | L2: Operadora Lecheria 2025, C.A Drop Shop El Paraiso
I3: Fecha: | J3: 42286 | L3: Operadora Lecheria 2025, C.A El Paraiso
L4: Operadora Lecheria 2025, C.A Presidente Medina
B5: SUCURSAL: | C5: Operadora Lecheria 2025, C.A Presidente Medina | H5: FECHA: | I5: 46157 | L5: Operadora Lecheria 2025, C.A Los Flores
L6: Operadora Lecheria 2025, C.A San Antonio
A7: EQUIPOS | L7: Operadora Lecheria 2025, C.A CCCT
A8: Nº | B8: EQUIPOS | D8: INVENTARIO IDEAL | E8: INVENTARIO REAL | F8: EQUIPOS OPERATIVOS | G8: EFECTIVIDAD | H8: OBSERVACIONES | L8: Operadora Lecheria 2025, C.A Guarenas Centro
A9: 1 | B9: CPU | D9: 2 | E9: 2 | F9: 2 | G9: =IF(D9="","",IF(D9=0,"-",IF(F9>D9,"ERROR",IF(E9>D9,"ERROR",IF(E9<D9,0,IF(E9>F9,0,IF(F9=D9,1,0))))))) -> 1 | L9: Operadora Lecheria 2025, C.A Guarenas 27 De Febrero | P9: LA CASA DE LA CAÑA, C.A. (T. ALTERNA)
A10: 2 | B10: MOUSE | D10: 2 | E10: 2 | F10: 2 | G10: =IF(D10="","",IF(D10=0,"-",IF(F10>D10,"ERROR",IF(E10>D10,"ERROR",IF(E10<D10,0,IF(E10>F10,0,IF(F10=D10,1,0))))))) -> 1 | L10: Operadora Lecheria 2025, C.A Guatire Las Rosas | P10: LA CASA DE LA CAÑA, C.A. (T. ANACO)
A11: 3 | B11: TECLADOS | D11: 2 | E11: 2 | F11: 2 | G11: =IF(D11="","",IF(D11=0,"-",IF(F11>D11,"ERROR",IF(E11>D11,"ERROR",IF(E11<D11,0,IF(E11>F11,0,IF(F11=D11,1,0))))))) -> 1 | L11: Operadora Lecheria 2025, C.A Guatire Centro | P11: LA CASA DE LA CAÑA, C.A. (T. NVA BARCELONA)
A12: 4 | B12: MONITORES | D12: 2 | E12: 2 | F12: 2 | G12: =IF(D12="","",IF(D12=0,"-",IF(F12>D12,"ERROR",IF(E12>D12,"ERROR",IF(E12<D12,0,IF(E12>F12,0,IF(F12=D12,1,0))))))) -> 1 | L12: Operadora Lecheria 2025, C.A Guatire El Palmar | P12: LA CASA DE LA CAÑA, C.A. (T. CUMANA)
A13: 5 | B13: REGULADORES | D13: 2 | E13: 2 | F13: 2 | G13: =IF(D13="","",IF(D13=0,"-",IF(F13>D13,"ERROR",IF(E13>D13,"ERROR",IF(E13<D13,0,IF(E13>F13,0,IF(F13=D13,1,0))))))) -> 1 | L13: Operadora Lecheria 2025, C.A Caucagua | P13: LA CASA DE LA CAÑA, C.A. (T. MATURIN I)
A14: 6 | B14: IMPRESORA MULTIFUNCIONAL | D14: 1 | E14: 1 | F14: 1 | G14: =IF(D14="","",IF(D14=0,"-",IF(F14>D14,"ERROR",IF(E14>D14,"ERROR",IF(E14<D14,0,IF(E14>F14,0,IF(F14=D14,1,0))))))) -> 1 | L14: Operadora Lecheria 2025, C.A Higuerote | P14: LA CASA DE LA CAÑA, C.A. (T. MATURIN II)
A15: 7 | B15: IMPRESORAS FISCALES | D15: 2 | E15: 2 | F15: 2 | G15: =IF(D15="","",IF(D15=0,"-",IF(F15>D15,"ERROR",IF(E15>D15,"ERROR",IF(E15<D15,0,IF(E15>F15,0,IF(F15=D15,1,0))))))) -> 1 | H15: SERIAL 1: | J15: Nº ULT. REPORTE Z: | L15: Operadora Lecheria 2025, C.A Las Mercedes | P15: LA CASA DE LA CAÑA, C.A. (T. FREITES)
H16: SERIAL 2: | J16: Nº ULT. REPORTE Z: | L16: Operadora Lecheria 2025, C.A San Martin | P16: LA CASA DE LA CAÑA, C.A. (T. PUENTE)
H17: SERIAL 3: | J17: Nº ULT. REPORTE Z: | L17: Operadora Lecheria 2025, C.A Baruta | P17: RELIVE, C.A. (T. CHUPARIN)
H18: SERIAL 4: | J18: Nº ULT. REPORTE Z: | L18: Operadora Lecheria 2025, C.A Nuevo Circo | P18: RELIVE, C.A. (T. TERRAZAS)
H19: SERIAL 5: | J19: Nº ULT. REPORTE Z: | L19: Operadora Lecheria 2025, C.A El Silencio | P19: RELIVE, C.A. (T. TIGRE II)
H20: SERIAL 6: | J20: Nº ULT. REPORTE Z: | L20: Operadora Lecheria 2025, C.A Drop Shop Castellana | P20: RELIVE, C.A. (T. TIGRE III)
H21: SERIAL 7: | J21: Nº ULT. REPORTE Z: | P21: RELIVE, C.A. (T. PLC)
P22: RELIVE, C.A. (T. POZUELOS)
A23: 8 | B23: ROUTER | D23: 1 | E23: 1 | F23: 1 | G23: =IF(D23="","",IF(D23=0,"-",IF(F23>D23,"ERROR",IF(E23>D23,"ERROR",IF(E23<D23,0,IF(E23>F23,0,IF(F23=D23,1,0))))))) -> 1 | P23: OPERADORA VENECIA 2021, C.A (T. VENECIA)
A24: 9 | B24: SUICHE | D24: 1 | E24: 1 | F24: 1 | G24: =IF(D24="","",IF(D24=0,"-",IF(F24>D24,"ERROR",IF(E24>D24,"ERROR",IF(E24<D24,0,IF(E24>F24,0,IF(F24=D24,1,0))))))) -> 1 | P24: OPERADORA VENECIA 2021, C.A (T. BOLIVAR PLC)
A25: 10 | B25: ESCANER DE CODIGO DE BARRAS | D25: 2 | E25: 2 | F25: 2 | G25: =IF(D25="","",IF(D25=0,"-",IF(F25>D25,"ERROR",IF(E25>D25,"ERROR",IF(E25<D25,0,IF(E25>F25,0,IF(F25=D25,1,0))))))) -> 1 | P25: OPERADORA VENECIA 2021, C.A (T. CHURCHILL)
A26: 11 | B26: VISOR DE VENTA | D26: 0 | E26: 2 | F26: 2 | G26: =IF(D26="","",IF(D26=0,"-",IF(F26>D26,"ERROR",IF(E26>D26,"ERROR",IF(E26<D26,0,IF(E26>F26,0,IF(F26=D26,1,0))))))) -> - | P26: OPERADORA VENECIA 2021, C.A (T. MANSION)
A27: 12 | B27: DVR | D27: 1 | E27: 1 | F27: 1 | G27: =IF(D27="","",IF(D27=0,"-",IF(F27>D27,"ERROR",IF(E27>D27,"ERROR",IF(E27<D27,0,IF(E27>F27,0,IF(F27=D27,1,0))))))) -> 1 | P27: OPERADORA LECHERIA 2011, C.A
A28: 13 | B28: MODEM | D28: 0 | E28: 1 | F28: 1 | G28: =IF(D28="","",IF(D28=0,"-",IF(F28>D28,"ERROR",IF(E28>D28,"ERROR",IF(E28<D28,0,IF(E28>F28,0,IF(F28=D28,1,0))))))) -> -
A29: 14 | B29: LIBROS DE IMPRESORAS FISCALES | D29: 2 | E29: 2 | F29: 2 | G29: =IF(D29="","",IF(D29=0,"-",IF(F29>D29,"ERROR",IF(E29>D29,"ERROR",IF(E29<D29,0,IF(E29>F29,0,IF(F29=D29,1,0))))))) -> 1
A30: TOTAL DE EFECTIVIDAD DE EQUIPOS | G30: =IFERROR(AVERAGE(G9:G28),"-") -> 1
A32: Realizado Por:
A33: Cargo
A35: NOTA: El check list de Existencia de Equipos en Tiendas debe ser enviado entre los 5 primeros días del mes, vía correo electrónico al grupo Sistemas, con copia al Director de Servicios de Control.
L39: HOUSE TICKET | M39: INVENTARIO | N39: CABLEADO | O39: MES
K40: TIENDAS | L40: SI | M40: 0 | N40: SI | O40: ENERO
K41: =IF(MAESTRO!A1="","",MAESTRO!A1) -> ******SUCURSALES | L41: NO | M41: 1 | N41: NO | O41: FEBRERO
K42: =IF(MAESTRO!A2="","",MAESTRO!A2) -> LA CASA DE LA CAÑA, C.A. (T. ALTERNA) | M42: 2 | O42: MARZO
K43: =IF(MAESTRO!A3="","",MAESTRO!A3) -> LA CASA DE LA CAÑA, C.A. (T. ANACO) | M43: 3 | O43: ABRIL
K44: =IF(MAESTRO!A4="","",MAESTRO!A4) -> LA CASA DE LA CAÑA, C.A. (T. CUMANÁ) | M44: 4 | O44: MAYO
K45: =IF(MAESTRO!A5="","",MAESTRO!A5) -> LA CASA DE LA CAÑA, C.A. (T. MATURÍN I) | M45: 5 | O45: JUNIO
...

Sheet FLORES
C1: CHECK LIST DE EXISTENCIA DE EQUIPOS EN TIENDAS | I1: Código: | J1: FO-MIS-03 | L1: Operadora Lecheria 2025, C.A San Bernandino
I2: Revisión: | J2: 07 | K2: 42720 | L2: Operadora Lecheria 2025, C.A Drop Shop El Paraiso
I3: Fecha: | J3: 42286 | L3: Operadora Lecheria 2025, C.A El Paraiso
L4: Operadora Lecheria 2025, C.A Presidente Medina
B5: SUCURSAL: | C5: Operadora Lecheria 2025, C.A Los Flores | H5: FECHA: | I5: 46157 | L5: Operadora Lecheria 2025, C.A Los Flores
L6: Operadora Lecheria 2025, C.A San Antonio
A7: EQUIPOS | L7: Operadora Lecheria 2025, C.A CCCT
A8: Nº | B8: EQUIPOS | D8: INVENTARIO IDEAL | E8: INVENTARIO REAL | F8: EQUIPOS OPERATIVOS | G8: EFECTIVIDAD | H8: OBSERVACIONES | L8: Operadora Lecheria 2025, C.A Guarenas Centro
A9: 1 | B9: CPU | D9: 3 | E9: 3 | F9: 3 | G9: =IF(D9="","",IF(D9=0,"-",IF(F9>D9,"ERROR",IF(E9>D9,"ERROR",IF(E9<D9,0,IF(E9>F9,0,IF(F9=D9,1,0))))))) -> 1 | L9: Operadora Lecheria 2025, C.A Guarenas 27 De Febrero | O9: LA CASA DE LA CAÑA, C.A. (T. ALTERNA)
A10: 2 | B10: MOUSE | D10: 3 | E10: 3 | F10: 3 | G10: =IF(D10="","",IF(D10=0,"-",IF(F10>D10,"ERROR",IF(E10>D10,"ERROR",IF(E10<D10,0,IF(E10>F10,0,IF(F10=D10,1,0))))))) -> 1 | L10: Operadora Lecheria 2025, C.A Guatire Las Rosas | O10: LA CASA DE LA CAÑA, C.A. (T. ANACO)
A11: 3 | B11: TECLADOS | D11: 3 | E11: 3 | F11: 3 | G11: =IF(D11="","",IF(D11=0,"-",IF(F11>D11,"ERROR",IF(E11>D11,"ERROR",IF(E11<D11,0,IF(E11>F11,0,IF(F11=D11,1,0))))))) -> 1 | L11: Operadora Lecheria 2025, C.A Guatire Centro | O11: LA CASA DE LA CAÑA, C.A. (T. NVA BARCELONA)
A12: 4 | B12: MONITORES | D12: 3 | E12: 3 | F12: 3 | G12: =IF(D12="","",IF(D12=0,"-",IF(F12>D12,"ERROR",IF(E12>D12,"ERROR",IF(E12<D12,0,IF(E12>F12,0,IF(F12=D12,1,0))))))) -> 1 | L12: Operadora Lecheria 2025, C.A Guatire El Palmar | O12: LA CASA DE LA CAÑA, C.A. (T. CUMANA)
A13: 5 | B13: REGULADORES | D13: 3 | E13: 3 | F13: 3 | G13: =IF(D13="","",IF(D13=0,"-",IF(F13>D13,"ERROR",IF(E13>D13,"ERROR",IF(E13<D13,0,IF(E13>F13,0,IF(F13=D13,1,0))))))) -> 1 | L13: Operadora Lecheria 2025, C.A Caucagua | O13: LA CASA DE LA CAÑA, C.A. (T. MATURIN I)
A14: 6 | B14: IMPRESORA MULTIFUNCIONAL | D14: 1 | E14: 1 | F14: 1 | G14: =IF(D14="","",IF(D14=0,"-",IF(F14>D14,"ERROR",IF(E14>D14,"ERROR",IF(E14<D14,0,IF(E14>F14,0,IF(F14=D14,1,0))))))) -> 1 | L14: Operadora Lecheria 2025, C.A Higuerote | O14: LA CASA DE LA CAÑA, C.A. (T. MATURIN II)
A15: 7 | B15: IMPRESORAS FISCALES | D15: 3 | E15: 3 | F15: 3 | G15: =IF(D15="","",IF(D15=0,"-",IF(F15>D15,"ERROR",IF(E15>D15,"ERROR",IF(E15<D15,0,IF(E15>F15,0,IF(F15=D15,1,0))))))) -> 1 | H15: SERIAL 1: | J15: Nº ULT. REPORTE Z: | L15: Operadora Lecheria 2025, C.A Las Mercedes | O15: LA CASA DE LA CAÑA, C.A. (T. FREITES)
H16: SERIAL 2: | J16: Nº ULT. REPORTE Z: | L16: Operadora Lecheria 2025, C.A San Martin | O16: LA CASA DE LA CAÑA, C.A. (T. PUENTE)
H17: SERIAL 3: | J17: Nº ULT. REPORTE Z: | L17: Operadora Lecheria 2025, C.A Baruta | O17: RELIVE, C.A. (T. CHUPARIN)
H18: SERIAL 4: | J18: Nº ULT. REPORTE Z: | L18: Operadora Lecheria 2025, C.A Nuevo Circo | O18: RELIVE, C.A. (T. TERRAZAS)
H19: SERIAL 5: | J19: Nº ULT. REPORTE Z: | L19: Operadora Lecheria 2025, C.A El Silencio | O19: RELIVE, C.A. (T. TIGRE II)
H20: SERIAL 6: | J20: Nº ULT. REPORTE Z: | L20: Operadora Lecheria 2025, C.A Drop Shop Castellana | O20: RELIVE, C.A. (T. TIGRE III)
H21: SERIAL 7: | J21: Nº ULT. REPORTE Z: | O21: RELIVE, C.A. (T. PLC)
O22: RELIVE, C.A. (T. POZUELOS)
A23: 8 | B23: ROUTER | D23: 1 | E23: 1 | F23: 1 | G23: =IF(D23="","",IF(D23=0,"-",IF(F23>D23,"ERROR",IF(E23>D23,"ERROR",IF(E23<D23,0,IF(E23>F23,0,IF(F23=D23,1,0))))))) -> 1 | O23: OPERADORA VENECIA 2021, C.A (T. VENECIA)
A24: 9 | B24: SUICHE | D24: 1 | E24: 1 | F24: 1 | G24: =IF(D24="","",IF(D24=0,"-",IF(F24>D24,"ERROR",IF(E24>D24,"ERROR",IF(E24<D24,0,IF(E24>F24,0,IF(F24=D24,1,0))))))) -> 1 | O24: OPERADORA VENECIA 2021, C.A (T. BOLIVAR PLC)
A25: 10 | B25: ESCANER DE CODIGO DE BARRAS | D25: 3 | E25: 3 | F25: 3 | G25: =IF(D25="","",IF(D25=0,"-",IF(F25>D25,"ERROR",IF(E25>D25,"ERROR",IF(E25<D25,0,IF(E25>F25,0,IF(F25=D25,1,0))))))) -> 1 | O25: OPERADORA VENECIA 2021, C.A (T. CHURCHILL)
A26: 11 | B26: VISOR DE VENTA | D26: 0 | E26: 2 | F26: 2 | G26: =IF(D26="","",IF(D26=0,"-",IF(F26>D26,"ERROR",IF(E26>D26,"ERROR",IF(E26<D26,0,IF(E26>F26,0,IF(F26=D26,1,0))))))) -> - | O26: OPERADORA VENECIA 2021, C.A (T. MANSION)
A27: 12 | B27: DVR | D27: 1 | E27: 1 | F27: 1 | G27: =IF(D27="","",IF(D27=0,"-",IF(F27>D27,"ERROR",IF(E27>D27,"ERROR",IF(E27<D27,0,IF(E27>F27,0,IF(F27=D27,1,0))))))) -> 1 | O27: OPERADORA LECHERIA 2011, C.A
A28: 13 | B28: MODEM | D28: 0 | E28: 1 | F28: 1 | G28: =IF(D28="","",IF(D28=0,"-",IF(F28>D28,"ERROR",IF(E28>D28,"ERROR",IF(E28<D28,0,IF(E28>F28,0,IF(F28=D28,1,0))))))) -> -
A29: 14 | B29: LIBROS DE IMPRESORAS FISCALES | D29: 3 | E29: 3 | F29: 3 | G29: =IF(D29="","",IF(D29=0,"-",IF(F29>D29,"ERROR",IF(E29>D29,"ERROR",IF(E29<D29,0,IF(E29>F29,0,IF(F29=D29,1,0))))))) -> 1
A30: TOTAL DE EFECTIVIDAD DE EQUIPOS | G30: =IFERROR(AVERAGE(G9:G28),"-") -> 1
A32: Realizado Por:
A33: Cargo
A35: NOTA: El check list de Existencia de Equipos en Tiendas debe ser enviado entre los 5 primeros días del mes, vía correo electrónico al grupo Sistemas, con copia al Director de Servicios de Control.
L39: HOUSE TICKET | M39: INVENTARIO | N39: CABLEADO | O39: MES
K40: TIENDAS | L40: SI | M40: 0 | N40: SI | O40: ENERO
K41: =IF(MAESTRO!A1="","",MAESTRO!A1) -> ******SUCURSALES | L41: NO | M41: 1 | N41: NO | O41: FEBRERO
K42: =IF(MAESTRO!A2="","",MAESTRO!A2) -> LA CASA DE LA CAÑA, C.A. (T. ALTERNA) | M42: 2 | O42: MARZO
K43: =IF(MAESTRO!A3="","",MAESTRO!A3) -> LA CASA DE LA CAÑA, C.A. (T. ANACO) | M43: 3 | O43: ABRIL
K44: =IF(MAESTRO!A4="","",MAESTRO!A4) -> LA CASA DE LA CAÑA, C.A. (T. CUMANÁ) | M44: 4 | O44: MAYO
K45: =IF(MAESTRO!A5="","",MAESTRO!A5) -> LA CASA DE LA CAÑA, C.A. (T. MATURÍN I) | M45: 5 | O45: JUNIO
...

Sheet ANTONIO
C1: CHECK LIST DE EXISTENCIA DE EQUIPOS EN TIENDAS | I1: Código: | J1: FO-MIS-03 | L1: Operadora Lecheria 2025, C.A San Bernandino
I2: Revisión: | J2: 07 | K2: 42720 | L2: Operadora Lecheria 2025, C.A Drop Shop El Paraiso
I3: Fecha: | J3: 42286 | L3: Operadora Lecheria 2025, C.A El Paraiso
L4: Operadora Lecheria 2025, C.A Presidente Medina
B5: SUCURSAL: | C5: Operadora Lecheria 2025, C.A San Antonio | H5: FECHA: | I5: 46157 | L5: Operadora Lecheria 2025, C.A Los Flores
L6: Operadora Lecheria 2025, C.A San Antonio
A7: EQUIPOS | L7: Operadora Lecheria 2025, C.A CCCT
A8: Nº | B8: EQUIPOS | D8: INVENTARIO IDEAL | E8: INVENTARIO REAL | F8: EQUIPOS OPERATIVOS | G8: EFECTIVIDAD | H8: OBSERVACIONES | L8: Operadora Lecheria 2025, C.A Guarenas Centro
A9: 1 | B9: CPU | D9: 2 | E9: 2 | F9: 2 | G9: =IF(D9="","",IF(D9=0,"-",IF(F9>D9,"ERROR",IF(E9>D9,"ERROR",IF(E9<D9,0,IF(E9>F9,0,IF(F9=D9,1,0))))))) -> 1 | L9: Operadora Lecheria 2025, C.A Guarenas 27 De Febrero | P9: LA CASA DE LA CAÑA, C.A. (T. ALTERNA)
A10: 2 | B10: MOUSE | D10: 2 | E10: 2 | F10: 2 | G10: =IF(D10="","",IF(D10=0,"-",IF(F10>D10,"ERROR",IF(E10>D10,"ERROR",IF(E10<D10,0,IF(E10>F10,0,IF(F10=D10,1,0))))))) -> 1 | L10: Operadora Lecheria 2025, C.A Guatire Las Rosas | P10: LA CASA DE LA CAÑA, C.A. (T. ANACO)
A11: 3 | B11: TECLADOS | D11: 2 | E11: 2 | F11: 2 | G11: =IF(D11="","",IF(D11=0,"-",IF(F11>D11,"ERROR",IF(E11>D11,"ERROR",IF(E11<D11,0,IF(E11>F11,0,IF(F11=D11,1,0))))))) -> 1 | L11: Operadora Lecheria 2025, C.A Guatire Centro | P11: LA CASA DE LA CAÑA, C.A. (T. NVA BARCELONA)
A12: 4 | B12: MONITORES | D12: 2 | E12: 2 | F12: 2 | G12: =IF(D12="","",IF(D12=0,"-",IF(F12>D12,"ERROR",IF(E12>D12,"ERROR",IF(E12<D12,0,IF(E12>F12,0,IF(F12=D12,1,0))))))) -> 1 | L12: Operadora Lecheria 2025, C.A Guatire El Palmar | P12: LA CASA DE LA CAÑA, C.A. (T. CUMANA)
A13: 5 | B13: REGULADORES | D13: 2 | E13: 2 | F13: 2 | G13: =IF(D13="","",IF(D13=0,"-",IF(F13>D13,"ERROR",IF(E13>D13,"ERROR",IF(E13<D13,0,IF(E13>F13,0,IF(F13=D13,1,0))))))) -> 1 | L13: Operadora Lecheria 2025, C.A Caucagua | P13: LA CASA DE LA CAÑA, C.A. (T. MATURIN I)
A14: 6 | B14: IMPRESORA MULTIFUNCIONAL | D14: 1 | E14: 1 | F14: 1 | G14: =IF(D14="","",IF(D14=0,"-",IF(F14>D14,"ERROR",IF(E14>D14,"ERROR",IF(E14<D14,0,IF(E14>F14,0,IF(F14=D14,1,0))))))) -> 1 | L14: Operadora Lecheria 2025, C.A Higuerote | P14: LA CASA DE LA CAÑA, C.A. (T. MATURIN II)
A15: 7 | B15: IMPRESORAS FISCALES | D15: 2 | E15: 2 | F15: 2 | G15: =IF(D15="","",IF(D15=0,"-",IF(F15>D15,"ERROR",IF(E15>D15,"ERROR",IF(E15<D15,0,IF(E15>F15,0,IF(F15=D15,1,0))))))) -> 1 | H15: SERIAL 1: | J15: Nº ULT. REPORTE Z: | L15: Operadora Lecheria 2025, C.A Las Mercedes | P15: LA CASA DE LA CAÑA, C.A. (T. FREITES)
H16: SERIAL 2: | J16: Nº ULT. REPORTE Z: | L16: Operadora Lecheria 2025, C.A San Martin | P16: LA CASA DE LA CAÑA, C.A. (T. PUENTE)
H17: SERIAL 3: | J17: Nº ULT. REPORTE Z: | L17: Operadora Lecheria 2025, C.A Baruta | P17: RELIVE, C.A. (T. CHUPARIN)
H18: SERIAL 4: | J18: Nº ULT. REPORTE Z: | L18: Operadora Lecheria 2025, C.A Nuevo Circo | P18: RELIVE, C.A. (T. TERRAZAS)
H19: SERIAL 5: | J19: Nº ULT. REPORTE Z: | L19: Operadora Lecheria 2025, C.A El Silencio | P19: RELIVE, C.A. (T. TIGRE II)
H20: SERIAL 6: | J20: Nº ULT. REPORTE Z: | L20: Operadora Lecheria 2025, C.A Drop Shop Castellana | P20: RELIVE, C.A. (T. TIGRE III)
H21: SERIAL 7: | J21: Nº ULT. REPORTE Z: | P21: RELIVE, C.A. (T. PLC)
P22: RELIVE, C.A. (T. POZUELOS)
A23: 8 | B23: ROUTER | D23: 1 | E23: 1 | F23: 1 | G23: =IF(D23="","",IF(D23=0,"-",IF(F23>D23,"ERROR",IF(E23>D23,"ERROR",IF(E23<D23,0,IF(E23>F23,0,IF(F23=D23,1,0))))))) -> 1 | P23: OPERADORA VENECIA 2021, C.A (T. VENECIA)
A24: 9 | B24: SUICHE | D24: 1 | E24: 1 | F24: 1 | G24: =IF(D24="","",IF(D24=0,"-",IF(F24>D24,"ERROR",IF(E24>D24,"ERROR",IF(E24<D24,0,IF(E24>F24,0,IF(F24=D24,1,0))))))) -> 1 | P24: OPERADORA VENECIA 2021, C.A (T. BOLIVAR PLC)
A25: 10 | B25: ESCANER DE CODIGO DE BARRAS | D25: 2 | E25: 2 | F25: 2 | G25: =IF(D25="","",IF(D25=0,"-",IF(F25>D25,"ERROR",IF(E25>D25,"ERROR",IF(E25<D25,0,IF(E25>F25,0,IF(F25=D25,1,0))))))) -> 1 | P25: OPERADORA VENECIA 2021, C.A (T. CHURCHILL)
A26: 11 | B26: VISOR DE VENTA | D26: 0 | E26: 1 | F26: 1 | G26: =IF(D26="","",IF(D26=0,"-",IF(F26>D26,"ERROR",IF(E26>D26,"ERROR",IF(E26<D26,0,IF(E26>F26,0,IF(F26=D26,1,0))))))) -> - | P26: OPERADORA VENECIA 2021, C.A (T. MANSION)
A27: 12 | B27: DVR | D27: 1 | E27: 1 | F27: 1 | G27: =IF(D27="","",IF(D27=0,"-",IF(F27>D27,"ERROR",IF(E27>D27,"ERROR",IF(E27<D27,0,IF(E27>F27,0,IF(F27=D27,1,0))))))) -> 1 | P27: OPERADORA LECHERIA 2011, C.A
A28: 13 | B28: MODEM | D28: 0 | E28: 1 | F28: 1 | G28: =IF(D28="","",IF(D28=0,"-",IF(F28>D28,"ERROR",IF(E28>D28,"ERROR",IF(E28<D28,0,IF(E28>F28,0,IF(F28=D28,1,0))))))) -> -
A29: 14 | B29: LIBROS DE IMPRESORAS FISCALES | D29: 2 | E29: 2 | F29: 2 | G29: =IF(D29="","",IF(D29=0,"-",IF(F29>D29,"ERROR",IF(E29>D29,"ERROR",IF(E29<D29,0,IF(E29>F29,0,IF(F29=D29,1,0))))))) -> 1
A30: TOTAL DE EFECTIVIDAD DE EQUIPOS | G30: =IFERROR(AVERAGE(G9:G28),"-") -> 1
A32: Realizado Por:
A33: Cargo
A35: NOTA: El check list de Existencia de Equipos en Tiendas debe ser enviado entre los 5 primeros días del mes, vía correo electrónico al grupo Sistemas, con copia al Director de Servicios de Control.
L39: HOUSE TICKET | M39: INVENTARIO | N39: CABLEADO | O39: MES
K40: TIENDAS | L40: SI | M40: 0 | N40: SI | O40: ENERO
K41: =IF(MAESTRO!A1="","",MAESTRO!A1) -> ******SUCURSALES | L41: NO | M41: 1 | N41: NO | O41: FEBRERO
K42: =IF(MAESTRO!A2="","",MAESTRO!A2) -> LA CASA DE LA CAÑA, C.A. (T. ALTERNA) | M42: 2 | O42: MARZO
K43: =IF(MAESTRO!A3="","",MAESTRO!A3) -> LA CASA DE LA CAÑA, C.A. (T. ANACO) | M43: 3 | O43: ABRIL
K44: =IF(MAESTRO!A4="","",MAESTRO!A4) -> LA CASA DE LA CAÑA, C.A. (T. CUMANÁ) | M44: 4 | O44: MAYO
K45: =IF(MAESTRO!A5="","",MAESTRO!A5) -> LA CASA DE LA CAÑA, C.A. (T. MATURÍN I) | M45: 5 | O45: JUNIO
...

Sheet CCCT
C1: CHECK LIST DE EXISTENCIA DE EQUIPOS EN TIENDAS | I1: Código: | J1: FO-MIS-03 | L1: Operadora Lecheria 2025, C.A San Bernandino
I2: Revisión: | J2: 07 | K2: 42720 | L2: Operadora Lecheria 2025, C.A Drop Shop El Paraiso
I3: Fecha: | J3: 42286 | L3: Operadora Lecheria 2025, C.A El Paraiso
L4: Operadora Lecheria 2025, C.A Presidente Medina
B5: SUCURSAL: | C5: Operadora Lecheria 2025, C.A CCCT | H5: FECHA: | I5: 46157 | L5: Operadora Lecheria 2025, C.A Los Flores
L6: Operadora Lecheria 2025, C.A San Antonio
A7: EQUIPOS | L7: Operadora Lecheria 2025, C.A CCCT
A8: Nº | B8: EQUIPOS | D8: INVENTARIO IDEAL | E8: INVENTARIO REAL | F8: EQUIPOS OPERATIVOS | G8: EFECTIVIDAD | H8: OBSERVACIONES | L8: Operadora Lecheria 2025, C.A Guarenas Centro
A9: 1 | B9: CPU | D9: 3 | E9: 3 | F9: 3 | G9: =IF(D9="","",IF(D9=0,"-",IF(F9>D9,"ERROR",IF(E9>D9,"ERROR",IF(E9<D9,0,IF(E9>F9,0,IF(F9=D9,1,0))))))) -> 1 | L9: Operadora Lecheria 2025, C.A Guarenas 27 De Febrero | R9: LA CASA DE LA CAÑA, C.A. (T. ALTERNA)
A10: 2 | B10: MOUSE | D10: 3 | E10: 3 | F10: 3 | G10: =IF(D10="","",IF(D10=0,"-",IF(F10>D10,"ERROR",IF(E10>D10,"ERROR",IF(E10<D10,0,IF(E10>F10,0,IF(F10=D10,1,0))))))) -> 1 | L10: Operadora Lecheria 2025, C.A Guatire Las Rosas | R10: LA CASA DE LA CAÑA, C.A. (T. ANACO)
A11: 3 | B11: TECLADOS | D11: 3 | E11: 3 | F11: 3 | G11: =IF(D11="","",IF(D11=0,"-",IF(F11>D11,"ERROR",IF(E11>D11,"ERROR",IF(E11<D11,0,IF(E11>F11,0,IF(F11=D11,1,0))))))) -> 1 | L11: Operadora Lecheria 2025, C.A Guatire Centro | R11: LA CASA DE LA CAÑA, C.A. (T. NVA BARCELONA)
A12: 4 | B12: MONITORES | D12: 3 | E12: 3 | F12: 3 | G12: =IF(D12="","",IF(D12=0,"-",IF(F12>D12,"ERROR",IF(E12>D12,"ERROR",IF(E12<D12,0,IF(E12>F12,0,IF(F12=D12,1,0))))))) -> 1 | L12: Operadora Lecheria 2025, C.A Guatire El Palmar | R12: LA CASA DE LA CAÑA, C.A. (T. CUMANA)
A13: 5 | B13: REGULADORES | D13: 3 | E13: 3 | F13: 3 | G13: =IF(D13="","",IF(D13=0,"-",IF(F13>D13,"ERROR",IF(E13>D13,"ERROR",IF(E13<D13,0,IF(E13>F13,0,IF(F13=D13,1,0))))))) -> 1 | L13: Operadora Lecheria 2025, C.A Caucagua | R13: LA CASA DE LA CAÑA, C.A. (T. MATURIN I)
A14: 6 | B14: IMPRESORA MULTIFUNCIONAL | D14: 1 | E14: 1 | F14: 1 | G14: =IF(D14="","",IF(D14=0,"-",IF(F14>D14,"ERROR",IF(E14>D14,"ERROR",IF(E14<D14,0,IF(E14>F14,0,IF(F14=D14,1,0))))))) -> 1 | L14: Operadora Lecheria 2025, C.A Higuerote | R14: LA CASA DE LA CAÑA, C.A. (T. MATURIN II)
A15: 7 | B15: IMPRESORAS FISCALES | D15: 3 | E15: 3 | F15: 3 | G15: =IF(D15="","",IF(D15=0,"-",IF(F15>D15,"ERROR",IF(E15>D15,"ERROR",IF(E15<D15,0,IF(E15>F15,0,IF(F15=D15,1,0))))))) -> 1 | H15: SERIAL 1: | J15: Nº ULT. REPORTE Z: | L15: Operadora Lecheria 2025, C.A Las Mercedes | R15: LA CASA DE LA CAÑA, C.A. (T. FREITES)
H16: SERIAL 2: | J16: Nº ULT. REPORTE Z: | L16: Operadora Lecheria 2025, C.A San Martin | R16: LA CASA DE LA CAÑA, C.A. (T. PUENTE)
H17: SERIAL 3: | J17: Nº ULT. REPORTE Z: | L17: Operadora Lecheria 2025, C.A Baruta | R17: RELIVE, C.A. (T. CHUPARIN)
H18: SERIAL 4: | J18: Nº ULT. REPORTE Z: | L18: Operadora Lecheria 2025, C.A Nuevo Circo | R18: RELIVE, C.A. (T. TERRAZAS)
H19: SERIAL 5: | J19: Nº ULT. REPORTE Z: | L19: Operadora Lecheria 2025, C.A El Silencio | R19: RELIVE, C.A. (T. TIGRE II)
H20: SERIAL 6: | J20: Nº ULT. REPORTE Z: | L20: Operadora Lecheria 2025, C.A Drop Shop Castellana | R20: RELIVE, C.A. (T. TIGRE III)
H21: SERIAL 7: | J21: Nº ULT. REPORTE Z: | R21: RELIVE, C.A. (T. PLC)
R22: RELIVE, C.A. (T. POZUELOS)
A23: 8 | B23: ROUTER | D23: 1 | E23: 1 | F23: 1 | G23: =IF(D23="","",IF(D23=0,"-",IF(F23>D23,"ERROR",IF(E23>D23,"ERROR",IF(E23<D23,0,IF(E23>F23,0,IF(F23=D23,1,0))))))) -> 1 | R23: OPERADORA VENECIA 2021, C.A (T. VENECIA)
A24: 9 | B24: SUICHE | D24: 1 | E24: 1 | F24: 1 | G24: =IF(D24="","",IF(D24=0,"-",IF(F24>D24,"ERROR",IF(E24>D24,"ERROR",IF(E24<D24,0,IF(E24>F24,0,IF(F24=D24,1,0))))))) -> 1 | R24: OPERADORA VENECIA 2021, C.A (T. BOLIVAR PLC)
A25: 10 | B25: ESCANER DE CODIGO DE BARRAS | D25: 3 | E25: 3 | F25: 3 | G25: =IF(D25="","",IF(D25=0,"-",IF(F25>D25,"ERROR",IF(E25>D25,"ERROR",IF(E25<D25,0,IF(E25>F25,0,IF(F25=D25,1,0))))))) -> 1 | R25: OPERADORA VENECIA 2021, C.A (T. CHURCHILL)
A26: 11 | B26: VISOR DE VENTA | D26: 0 | E26: 1 | F26: 1 | G26: =IF(D26="","",IF(D26=0,"-",IF(F26>D26,"ERROR",IF(E26>D26,"ERROR",IF(E26<D26,0,IF(E26>F26,0,IF(F26=D26,1,0))))))) -> - | R26: OPERADORA VENECIA 2021, C.A (T. MANSION)
A27: 12 | B27: DVR | D27: 1 | E27: 1 | F27: 1 | G27: =IF(D27="","",IF(D27=0,"-",IF(F27>D27,"ERROR",IF(E27>D27,"ERROR",IF(E27<D27,0,IF(E27>F27,0,IF(F27=D27,1,0))))))) -> 1 | R27: OPERADORA LECHERIA 2011, C.A
A28: 13 | B28: MODEM | D28: 0 | E28: 1 | F28: 1 | G28: =IF(D28="","",IF(D28=0,"-",IF(F28>D28,"ERROR",IF(E28>D28,"ERROR",IF(E28<D28,0,IF(E28>F28,0,IF(F28=D28,1,0))))))) -> -
A29: 14 | B29: LIBROS DE IMPRESORAS FISCALES | D29: 3 | E29: 3 | F29: 3 | G29: =IF(D29="","",IF(D29=0,"-",IF(F29>D29,"ERROR",IF(E29>D29,"ERROR",IF(E29<D29,0,IF(E29>F29,0,IF(F29=D29,1,0))))))) -> 1
A30: TOTAL DE EFECTIVIDAD DE EQUIPOS | G30: =IFERROR(AVERAGE(G9:G28),"-") -> 1
A32: Realizado Por:
A33: Cargo
A35: NOTA: El check list de Existencia de Equipos en Tiendas debe ser enviado entre los 5 primeros días del mes, vía correo electrónico al grupo Sistemas, con copia al Director de Servicios de Control.
L39: HOUSE TICKET | M39: INVENTARIO | N39: CABLEADO | O39: MES
K40: TIENDAS | L40: SI | M40: 0 | N40: SI | O40: ENERO
K41: =IF(MAESTRO!A1="","",MAESTRO!A1) -> ******SUCURSALES | L41: NO | M41: 1 | N41: NO | O41: FEBRERO
K42: =IF(MAESTRO!A2="","",MAESTRO!A2) -> LA CASA DE LA CAÑA, C.A. (T. ALTERNA) | M42: 2 | O42: MARZO
K43: =IF(MAESTRO!A3="","",MAESTRO!A3) -> LA CASA DE LA CAÑA, C.A. (T. ANACO) | M43: 3 | O43: ABRIL
K44: =IF(MAESTRO!A4="","",MAESTRO!A4) -> LA CASA DE LA CAÑA, C.A. (T. CUMANÁ) | M44: 4 | O44: MAYO
K45: =IF(MAESTRO!A5="","",MAESTRO!A5) -> LA CASA DE LA CAÑA, C.A. (T. MATURÍN I) | M45: 5 | O45: JUNIO
...

Sheet GUARENAS C
C1: CHECK LIST DE EXISTENCIA DE EQUIPOS EN TIENDAS | I1: Código: | J1: FO-MIS-03 | L1: Operadora Lecheria 2025, C.A San Bernandino
I2: Revisión: | J2: 07 | K2: 42720 | L2: Operadora Lecheria 2025, C.A Drop Shop El Paraiso
I3: Fecha: | J3: 42286 | L3: Operadora Lecheria 2025, C.A El Paraiso
L4: Operadora Lecheria 2025, C.A Presidente Medina
B5: SUCURSAL: | C5: Operadora Lecheria 2025, C.A Guarenas Centro | H5: FECHA: | I5: 46157 | L5: Operadora Lecheria 2025, C.A Los Flores
L6: Operadora Lecheria 2025, C.A San Antonio
A7: EQUIPOS | L7: Operadora Lecheria 2025, C.A CCCT
A8: Nº | B8: EQUIPOS | D8: INVENTARIO IDEAL | E8: INVENTARIO REAL | F8: EQUIPOS OPERATIVOS | G8: EFECTIVIDAD | H8: OBSERVACIONES | L8: Operadora Lecheria 2025, C.A Guarenas Centro
A9: 1 | B9: CPU | D9: 2 | E9: 2 | F9: 2 | G9: =IF(D9="","",IF(D9=0,"-",IF(F9>D9,"ERROR",IF(E9>D9,"ERROR",IF(E9<D9,0,IF(E9>F9,0,IF(F9=D9,1,0))))))) -> 1 | L9: Operadora Lecheria 2025, C.A Guarenas 27 De Febrero
A10: 2 | B10: MOUSE | D10: 2 | E10: 2 | F10: 2 | G10: =IF(D10="","",IF(D10=0,"-",IF(F10>D10,"ERROR",IF(E10>D10,"ERROR",IF(E10<D10,0,IF(E10>F10,0,IF(F10=D10,1,0))))))) -> 1 | L10: Operadora Lecheria 2025, C.A Guatire Las Rosas | Q10: LA CASA DE LA CAÑA, C.A. (T. ALTERNA)
A11: 3 | B11: TECLADOS | D11: 2 | E11: 2 | F11: 2 | G11: =IF(D11="","",IF(D11=0,"-",IF(F11>D11,"ERROR",IF(E11>D11,"ERROR",IF(E11<D11,0,IF(E11>F11,0,IF(F11=D11,1,0))))))) -> 1 | L11: Operadora Lecheria 2025, C.A Guatire Centro | Q11: LA CASA DE LA CAÑA, C.A. (T. ANACO)
A12: 4 | B12: MONITORES | D12: 2 | E12: 2 | F12: 2 | G12: =IF(D12="","",IF(D12=0,"-",IF(F12>D12,"ERROR",IF(E12>D12,"ERROR",IF(E12<D12,0,IF(E12>F12,0,IF(F12=D12,1,0))))))) -> 1 | L12: Operadora Lecheria 2025, C.A Guatire El Palmar | Q12: LA CASA DE LA CAÑA, C.A. (T. NVA BARCELONA)
A13: 5 | B13: REGULADORES | D13: 2 | E13: 2 | F13: 2 | G13: =IF(D13="","",IF(D13=0,"-",IF(F13>D13,"ERROR",IF(E13>D13,"ERROR",IF(E13<D13,0,IF(E13>F13,0,IF(F13=D13,1,0))))))) -> 1 | L13: Operadora Lecheria 2025, C.A Caucagua | Q13: LA CASA DE LA CAÑA, C.A. (T. CUMANA)
A14: 6 | B14: IMPRESORA MULTIFUNCIONAL | D14: 1 | E14: 1 | F14: 1 | G14: =IF(D14="","",IF(D14=0,"-",IF(F14>D14,"ERROR",IF(E14>D14,"ERROR",IF(E14<D14,0,IF(E14>F14,0,IF(F14=D14,1,0))))))) -> 1 | L14: Operadora Lecheria 2025, C.A Higuerote | Q14: LA CASA DE LA CAÑA, C.A. (T. MATURIN I)
A15: 7 | B15: IMPRESORAS FISCALES | D15: 2 | E15: 2 | F15: 2 | G15: =IF(D15="","",IF(D15=0,"-",IF(F15>D15,"ERROR",IF(E15>D15,"ERROR",IF(E15<D15,0,IF(E15>F15,0,IF(F15=D15,1,0))))))) -> 1 | H15: SERIAL 1: | J15: Nº ULT. REPORTE Z: | L15: Operadora Lecheria 2025, C.A Las Mercedes | Q15: LA CASA DE LA CAÑA, C.A. (T. MATURIN II)
H16: SERIAL 2: | J16: Nº ULT. REPORTE Z: | L16: Operadora Lecheria 2025, C.A San Martin | Q16: LA CASA DE LA CAÑA, C.A. (T. FREITES)
H17: SERIAL 3: | J17: Nº ULT. REPORTE Z: | L17: Operadora Lecheria 2025, C.A Baruta | Q17: LA CASA DE LA CAÑA, C.A. (T. PUENTE)
H18: SERIAL 4: | J18: Nº ULT. REPORTE Z: | L18: Operadora Lecheria 2025, C.A Nuevo Circo | Q18: RELIVE, C.A. (T. CHUPARIN)
H19: SERIAL 5: | J19: Nº ULT. REPORTE Z: | L19: Operadora Lecheria 2025, C.A El Silencio | Q19: RELIVE, C.A. (T. TERRAZAS)
H20: SERIAL 6: | J20: Nº ULT. REPORTE Z: | L20: Operadora Lecheria 2025, C.A Drop Shop Castellana | Q20: RELIVE, C.A. (T. TIGRE II)
H21: SERIAL 7: | J21: Nº ULT. REPORTE Z: | Q21: RELIVE, C.A. (T. TIGRE III)
Q22: RELIVE, C.A. (T. PLC)
A23: 8 | B23: ROUTER | D23: 1 | E23: 1 | F23: 1 | G23: =IF(D23="","",IF(D23=0,"-",IF(F23>D23,"ERROR",IF(E23>D23,"ERROR",IF(E23<D23,0,IF(E23>F23,0,IF(F23=D23,1,0))))))) -> 1 | Q23: RELIVE, C.A. (T. POZUELOS)
A24: 9 | B24: SUICHE | D24: 1 | E24: 1 | F24: 1 | G24: =IF(D24="","",IF(D24=0,"-",IF(F24>D24,"ERROR",IF(E24>D24,"ERROR",IF(E24<D24,0,IF(E24>F24,0,IF(F24=D24,1,0))))))) -> 1 | Q24: OPERADORA VENECIA 2021, C.A (T. VENECIA)
A25: 10 | B25: ESCANER DE CODIGO DE BARRAS | D25: 3 | E25: 3 | F25: 3 | G25: =IF(D25="","",IF(D25=0,"-",IF(F25>D25,"ERROR",IF(E25>D25,"ERROR",IF(E25<D25,0,IF(E25>F25,0,IF(F25=D25,1,0))))))) -> 1 | Q25: OPERADORA VENECIA 2021, C.A (T. BOLIVAR PLC)
A26: 11 | B26: VISOR DE VENTA | D26: 0 | E26: 1 | F26: 1 | G26: =IF(D26="","",IF(D26=0,"-",IF(F26>D26,"ERROR",IF(E26>D26,"ERROR",IF(E26<D26,0,IF(E26>F26,0,IF(F26=D26,1,0))))))) -> - | Q26: OPERADORA VENECIA 2021, C.A (T. CHURCHILL)
A27: 12 | B27: DVR | D27: 1 | E27: 1 | F27: 1 | G27: =IF(D27="","",IF(D27=0,"-",IF(F27>D27,"ERROR",IF(E27>D27,"ERROR",IF(E27<D27,0,IF(E27>F27,0,IF(F27=D27,1,0))))))) -> 1 | Q27: OPERADORA VENECIA 2021, C.A (T. MANSION)
A28: 13 | B28: MODEM | D28: 0 | E28: 1 | F28: 1 | G28: =IF(D28="","",IF(D28=0,"-",IF(F28>D28,"ERROR",IF(E28>D28,"ERROR",IF(E28<D28,0,IF(E28>F28,0,IF(F28=D28,1,0))))))) -> - | Q28: OPERADORA LECHERIA 2011, C.A
A29: 14 | B29: LIBROS DE IMPRESORAS FISCALES | D29: 2 | E29: 2 | F29: 2 | G29: =IF(D29="","",IF(D29=0,"-",IF(F29>D29,"ERROR",IF(E29>D29,"ERROR",IF(E29<D29,0,IF(E29>F29,0,IF(F29=D29,1,0))))))) -> 1
A30: TOTAL DE EFECTIVIDAD DE EQUIPOS | G30: =IFERROR(AVERAGE(G9:G28),"-") -> 1
A32: Realizado Por:
A33: Cargo
A35: NOTA: El check list de Existencia de Equipos en Tiendas debe ser enviado entre los 5 primeros días del mes, vía correo electrónico al grupo Sistemas, con copia al Director de Servicios de Control.
L39: HOUSE TICKET | M39: INVENTARIO | N39: CABLEADO | O39: MES
K40: TIENDAS | L40: SI | M40: 0 | N40: SI | O40: ENERO
K41: =IF(MAESTRO!A1="","",MAESTRO!A1) -> ******SUCURSALES | L41: NO | M41: 1 | N41: NO | O41: FEBRERO
K42: =IF(MAESTRO!A2="","",MAESTRO!A2) -> LA CASA DE LA CAÑA, C.A. (T. ALTERNA) | M42: 2 | O42: MARZO
K43: =IF(MAESTRO!A3="","",MAESTRO!A3) -> LA CASA DE LA CAÑA, C.A. (T. ANACO) | M43: 3 | O43: ABRIL
K44: =IF(MAESTRO!A4="","",MAESTRO!A4) -> LA CASA DE LA CAÑA, C.A. (T. CUMANÁ) | M44: 4 | O44: MAYO
K45: =IF(MAESTRO!A5="","",MAESTRO!A5) -> LA CASA DE LA CAÑA, C.A. (T. MATURÍN I) | M45: 5 | O45: JUNIO
...

Sheet GUARENAS 27
C1: CHECK LIST DE EXISTENCIA DE EQUIPOS EN TIENDAS | I1: Código: | J1: FO-MIS-03 | L1: Operadora Lecheria 2025, C.A San Bernandino
I2: Revisión: | J2: 07 | K2: 42720 | L2: Operadora Lecheria 2025, C.A Drop Shop El Paraiso
I3: Fecha: | J3: 42286 | L3: Operadora Lecheria 2025, C.A El Paraiso
L4: Operadora Lecheria 2025, C.A Presidente Medina
B5: SUCURSAL: | C5: Operadora Lecheria 2025, C.A Guarenas 27 De Febrero | H5: FECHA: | I5: 46157 | L5: Operadora Lecheria 2025, C.A Los Flores
L6: Operadora Lecheria 2025, C.A San Antonio
A7: EQUIPOS | L7: Operadora Lecheria 2025, C.A CCCT
A8: Nº | B8: EQUIPOS | D8: INVENTARIO IDEAL | E8: INVENTARIO REAL | F8: EQUIPOS OPERATIVOS | G8: EFECTIVIDAD | H8: OBSERVACIONES | L8: Operadora Lecheria 2025, C.A Guarenas Centro
A9: 1 | B9: CPU | D9: 2 | E9: 2 | F9: 2 | G9: =IF(D9="","",IF(D9=0,"-",IF(F9>D9,"ERROR",IF(E9>D9,"ERROR",IF(E9<D9,0,IF(E9>F9,0,IF(F9=D9,1,0))))))) -> 1 | L9: Operadora Lecheria 2025, C.A Guarenas 27 De Febrero | P9: LA CASA DE LA CAÑA, C.A. (T. ALTERNA)
A10: 2 | B10: MOUSE | D10: 2 | E10: 2 | F10: 2 | G10: =IF(D10="","",IF(D10=0,"-",IF(F10>D10,"ERROR",IF(E10>D10,"ERROR",IF(E10<D10,0,IF(E10>F10,0,IF(F10=D10,1,0))))))) -> 1 | L10: Operadora Lecheria 2025, C.A Guatire Las Rosas | P10: LA CASA DE LA CAÑA, C.A. (T. ANACO)
A11: 3 | B11: TECLADOS | D11: 2 | E11: 2 | F11: 2 | G11: =IF(D11="","",IF(D11=0,"-",IF(F11>D11,"ERROR",IF(E11>D11,"ERROR",IF(E11<D11,0,IF(E11>F11,0,IF(F11=D11,1,0))))))) -> 1 | L11: Operadora Lecheria 2025, C.A Guatire Centro | P11: LA CASA DE LA CAÑA, C.A. (T. NVA BARCELONA)
A12: 4 | B12: MONITORES | D12: 2 | E12: 2 | F12: 2 | G12: =IF(D12="","",IF(D12=0,"-",IF(F12>D12,"ERROR",IF(E12>D12,"ERROR",IF(E12<D12,0,IF(E12>F12,0,IF(F12=D12,1,0))))))) -> 1 | L12: Operadora Lecheria 2025, C.A Guatire El Palmar | P12: LA CASA DE LA CAÑA, C.A. (T. CUMANA)
A13: 5 | B13: REGULADORES | D13: 2 | E13: 2 | F13: 2 | G13: =IF(D13="","",IF(D13=0,"-",IF(F13>D13,"ERROR",IF(E13>D13,"ERROR",IF(E13<D13,0,IF(E13>F13,0,IF(F13=D13,1,0))))))) -> 1 | L13: Operadora Lecheria 2025, C.A Caucagua | P13: LA CASA DE LA CAÑA, C.A. (T. MATURIN I)
A14: 6 | B14: IMPRESORA MULTIFUNCIONAL | D14: 1 | E14: 1 | F14: 1 | G14: =IF(D14="","",IF(D14=0,"-",IF(F14>D14,"ERROR",IF(E14>D14,"ERROR",IF(E14<D14,0,IF(E14>F14,0,IF(F14=D14,1,0))))))) -> 1 | L14: Operadora Lecheria 2025, C.A Higuerote | P14: LA CASA DE LA CAÑA, C.A. (T. MATURIN II)
A15: 7 | B15: IMPRESORAS FISCALES | D15: 2 | E15: 2 | F15: 2 | G15: =IF(D15="","",IF(D15=0,"-",IF(F15>D15,"ERROR",IF(E15>D15,"ERROR",IF(E15<D15,0,IF(E15>F15,0,IF(F15=D15,1,0))))))) -> 1 | H15: SERIAL 1: | J15: Nº ULT. REPORTE Z: | L15: Operadora Lecheria 2025, C.A Las Mercedes | P15: LA CASA DE LA CAÑA, C.A. (T. FREITES)
H16: SERIAL 2: | J16: Nº ULT. REPORTE Z: | L16: Operadora Lecheria 2025, C.A San Martin | P16: LA CASA DE LA CAÑA, C.A. (T. PUENTE)
H17: SERIAL 3: | J17: Nº ULT. REPORTE Z: | L17: Operadora Lecheria 2025, C.A Baruta | P17: RELIVE, C.A. (T. CHUPARIN)
H18: SERIAL 4: | J18: Nº ULT. REPORTE Z: | L18: Operadora Lecheria 2025, C.A Nuevo Circo | P18: RELIVE, C.A. (T. TERRAZAS)
H19: SERIAL 5: | J19: Nº ULT. REPORTE Z: | L19: Operadora Lecheria 2025, C.A El Silencio | P19: RELIVE, C.A. (T. TIGRE II)
H20: SERIAL 6: | J20: Nº ULT. REPORTE Z: | L20: Operadora Lecheria 2025, C.A Drop Shop Castellana | P20: RELIVE, C.A. (T. TIGRE III)
H21: SERIAL 7: | J21: Nº ULT. REPORTE Z: | P21: RELIVE, C.A. (T. PLC)
P22: RELIVE, C.A. (T. POZUELOS)
A23: 8 | B23: ROUTER | D23: 1 | E23: 1 | F23: 1 | G23: =IF(D23="","",IF(D23=0,"-",IF(F23>D23,"ERROR",IF(E23>D23,"ERROR",IF(E23<D23,0,IF(E23>F23,0,IF(F23=D23,1,0))))))) -> 1 | P23: OPERADORA VENECIA 2021, C.A (T. VENECIA)
A24: 9 | B24: SUICHE | D24: 1 | E24: 1 | F24: 1 | G24: =IF(D24="","",IF(D24=0,"-",IF(F24>D24,"ERROR",IF(E24>D24,"ERROR",IF(E24<D24,0,IF(E24>F24,0,IF(F24=D24,1,0))))))) -> 1 | P24: OPERADORA VENECIA 2021, C.A (T. BOLIVAR PLC)
A25: 10 | B25: ESCANER DE CODIGO DE BARRAS | D25: 2 | E25: 2 | F25: 2 | G25: =IF(D25="","",IF(D25=0,"-",IF(F25>D25,"ERROR",IF(E25>D25,"ERROR",IF(E25<D25,0,IF(E25>F25,0,IF(F25=D25,1,0))))))) -> 1 | P25: OPERADORA VENECIA 2021, C.A (T. CHURCHILL)
A26: 11 | B26: VISOR DE VENTA | D26: 0 | E26: 1 | F26: 1 | G26: =IF(D26="","",IF(D26=0,"-",IF(F26>D26,"ERROR",IF(E26>D26,"ERROR",IF(E26<D26,0,IF(E26>F26,0,IF(F26=D26,1,0))))))) -> - | P26: OPERADORA VENECIA 2021, C.A (T. MANSION)
A27: 12 | B27: DVR | D27: 1 | E27: 1 | F27: 1 | G27: =IF(D27="","",IF(D27=0,"-",IF(F27>D27,"ERROR",IF(E27>D27,"ERROR",IF(E27<D27,0,IF(E27>F27,0,IF(F27=D27,1,0))))))) -> 1 | P27: OPERADORA LECHERIA 2011, C.A
A28: 13 | B28: MODEM | D28: 0 | E28: 1 | F28: 1 | G28: =IF(D28="","",IF(D28=0,"-",IF(F28>D28,"ERROR",IF(E28>D28,"ERROR",IF(E28<D28,0,IF(E28>F28,0,IF(F28=D28,1,0))))))) -> -
A29: 14 | B29: LIBROS DE IMPRESORAS FISCALES | D29: 2 | E29: 2 | F29: 2 | G29: =IF(D29="","",IF(D29=0,"-",IF(F29>D29,"ERROR",IF(E29>D29,"ERROR",IF(E29<D29,0,IF(E29>F29,0,IF(F29=D29,1,0))))))) -> 1
A30: TOTAL DE EFECTIVIDAD DE EQUIPOS | G30: =IFERROR(AVERAGE(G9:G28),"-") -> 1
A32: Realizado Por:
A33: Cargo
A35: NOTA: El check list de Existencia de Equipos en Tiendas debe ser enviado entre los 5 primeros días del mes, vía correo electrónico al grupo Sistemas, con copia al Director de Servicios de Control.
L39: HOUSE TICKET | M39: INVENTARIO | N39: CABLEADO | O39: MES
K40: TIENDAS | L40: SI | M40: 0 | N40: SI | O40: ENERO
K41: =IF(MAESTRO!A1="","",MAESTRO!A1) -> ******SUCURSALES | L41: NO | M41: 1 | N41: NO | O41: FEBRERO
K42: =IF(MAESTRO!A2="","",MAESTRO!A2) -> LA CASA DE LA CAÑA, C.A. (T. ALTERNA) | M42: 2 | O42: MARZO
K43: =IF(MAESTRO!A3="","",MAESTRO!A3) -> LA CASA DE LA CAÑA, C.A. (T. ANACO) | M43: 3 | O43: ABRIL
K44: =IF(MAESTRO!A4="","",MAESTRO!A4) -> LA CASA DE LA CAÑA, C.A. (T. CUMANÁ) | M44: 4 | O44: MAYO
K45: =IF(MAESTRO!A5="","",MAESTRO!A5) -> LA CASA DE LA CAÑA, C.A. (T. MATURÍN I) | M45: 5 | O45: JUNIO
...

Sheet GUATIRE R
C1: CHECK LIST DE EXISTENCIA DE EQUIPOS EN TIENDAS | I1: Código: | J1: FO-MIS-03 | L1: Operadora Lecheria 2025, C.A San Bernandino
I2: Revisión: | J2: 07 | K2: 42720 | L2: Operadora Lecheria 2025, C.A Drop Shop El Paraiso
I3: Fecha: | J3: 42286 | L3: Operadora Lecheria 2025, C.A El Paraiso
L4: Operadora Lecheria 2025, C.A Presidente Medina
B5: SUCURSAL: | C5: Operadora Lecheria 2025, C.A Guatire Las Rosas | H5: FECHA: | I5: 46157 | L5: Operadora Lecheria 2025, C.A Los Flores
L6: Operadora Lecheria 2025, C.A San Antonio
A7: EQUIPOS | L7: Operadora Lecheria 2025, C.A CCCT
A8: Nº | B8: EQUIPOS | D8: INVENTARIO IDEAL | E8: INVENTARIO REAL | F8: EQUIPOS OPERATIVOS | G8: EFECTIVIDAD | H8: OBSERVACIONES | L8: Operadora Lecheria 2025, C.A Guarenas Centro
A9: 1 | B9: CPU | D9: 2 | E9: 2 | F9: 2 | G9: =IF(D9="","",IF(D9=0,"-",IF(F9>D9,"ERROR",IF(E9>D9,"ERROR",IF(E9<D9,0,IF(E9>F9,0,IF(F9=D9,1,0))))))) -> 1 | L9: Operadora Lecheria 2025, C.A Guarenas 27 De Febrero | P9: LA CASA DE LA CAÑA, C.A. (T. ALTERNA)
A10: 2 | B10: MOUSE | D10: 2 | E10: 2 | F10: 2 | G10: =IF(D10="","",IF(D10=0,"-",IF(F10>D10,"ERROR",IF(E10>D10,"ERROR",IF(E10<D10,0,IF(E10>F10,0,IF(F10=D10,1,0))))))) -> 1 | L10: Operadora Lecheria 2025, C.A Guatire Las Rosas | P10: LA CASA DE LA CAÑA, C.A. (T. ANACO)
A11: 3 | B11: TECLADOS | D11: 2 | E11: 2 | F11: 2 | G11: =IF(D11="","",IF(D11=0,"-",IF(F11>D11,"ERROR",IF(E11>D11,"ERROR",IF(E11<D11,0,IF(E11>F11,0,IF(F11=D11,1,0))))))) -> 1 | L11: Operadora Lecheria 2025, C.A Guatire Centro | P11: LA CASA DE LA CAÑA, C.A. (T. NVA BARCELONA)
A12: 4 | B12: MONITORES | D12: 2 | E12: 2 | F12: 2 | G12: =IF(D12="","",IF(D12=0,"-",IF(F12>D12,"ERROR",IF(E12>D12,"ERROR",IF(E12<D12,0,IF(E12>F12,0,IF(F12=D12,1,0))))))) -> 1 | L12: Operadora Lecheria 2025, C.A Guatire El Palmar | P12: LA CASA DE LA CAÑA, C.A. (T. CUMANA)
A13: 5 | B13: REGULADORES | D13: 2 | E13: 2 | F13: 2 | G13: =IF(D13="","",IF(D13=0,"-",IF(F13>D13,"ERROR",IF(E13>D13,"ERROR",IF(E13<D13,0,IF(E13>F13,0,IF(F13=D13,1,0))))))) -> 1 | L13: Operadora Lecheria 2025, C.A Caucagua | P13: LA CASA DE LA CAÑA, C.A. (T. MATURIN I)
A14: 6 | B14: IMPRESORA MULTIFUNCIONAL | D14: 1 | E14: 1 | F14: 1 | G14: =IF(D14="","",IF(D14=0,"-",IF(F14>D14,"ERROR",IF(E14>D14,"ERROR",IF(E14<D14,0,IF(E14>F14,0,IF(F14=D14,1,0))))))) -> 1 | L14: Operadora Lecheria 2025, C.A Higuerote | P14: LA CASA DE LA CAÑA, C.A. (T. MATURIN II)
A15: 7 | B15: IMPRESORAS FISCALES | D15: 2 | E15: 2 | F15: 2 | G15: =IF(D15="","",IF(D15=0,"-",IF(F15>D15,"ERROR",IF(E15>D15,"ERROR",IF(E15<D15,0,IF(E15>F15,0,IF(F15=D15,1,0))))))) -> 1 | H15: SERIAL 1: | J15: Nº ULT. REPORTE Z: | L15: Operadora Lecheria 2025, C.A Las Mercedes | P15: LA CASA DE LA CAÑA, C.A. (T. FREITES)
H16: SERIAL 2: | J16: Nº ULT. REPORTE Z: | L16: Operadora Lecheria 2025, C.A San Martin | P16: LA CASA DE LA CAÑA, C.A. (T. PUENTE)
H17: SERIAL 3: | J17: Nº ULT. REPORTE Z: | L17: Operadora Lecheria 2025, C.A Baruta | P17: RELIVE, C.A. (T. CHUPARIN)
H18: SERIAL 4: | J18: Nº ULT. REPORTE Z: | L18: Operadora Lecheria 2025, C.A Nuevo Circo | P18: RELIVE, C.A. (T. TERRAZAS)
H19: SERIAL 5: | J19: Nº ULT. REPORTE Z: | L19: Operadora Lecheria 2025, C.A El Silencio | P19: RELIVE, C.A. (T. TIGRE II)
H20: SERIAL 6: | J20: Nº ULT. REPORTE Z: | L20: Operadora Lecheria 2025, C.A Drop Shop Castellana | P20: RELIVE, C.A. (T. TIGRE III)
H21: SERIAL 7: | J21: Nº ULT. REPORTE Z: | P21: RELIVE, C.A. (T. PLC)
P22: RELIVE, C.A. (T. POZUELOS)
A23: 8 | B23: ROUTER | D23: 1 | E23: 1 | F23: 1 | G23: =IF(D23="","",IF(D23=0,"-",IF(F23>D23,"ERROR",IF(E23>D23,"ERROR",IF(E23<D23,0,IF(E23>F23,0,IF(F23=D23,1,0))))))) -> 1 | P23: OPERADORA VENECIA 2021, C.A (T. VENECIA)
A24: 9 | B24: SUICHE | D24: 1 | E24: 1 | F24: 1 | G24: =IF(D24="","",IF(D24=0,"-",IF(F24>D24,"ERROR",IF(E24>D24,"ERROR",IF(E24<D24,0,IF(E24>F24,0,IF(F24=D24,1,0))))))) -> 1 | P24: OPERADORA VENECIA 2021, C.A (T. BOLIVAR PLC)
A25: 10 | B25: ESCANER DE CODIGO DE BARRAS | D25: 2 | E25: 2 | F25: 2 | G25: =IF(D25="","",IF(D25=0,"-",IF(F25>D25,"ERROR",IF(E25>D25,"ERROR",IF(E25<D25,0,IF(E25>F25,0,IF(F25=D25,1,0))))))) -> 1 | H25: } | P25: OPERADORA VENECIA 2021, C.A (T. CHURCHILL)
A26: 11 | B26: VISOR DE VENTA | D26: 0 | E26: 1 | F26: 1 | G26: =IF(D26="","",IF(D26=0,"-",IF(F26>D26,"ERROR",IF(E26>D26,"ERROR",IF(E26<D26,0,IF(E26>F26,0,IF(F26=D26,1,0))))))) -> - | P26: OPERADORA VENECIA 2021, C.A (T. MANSION)
A27: 12 | B27: DVR | D27: 1 | E27: 1 | F27: 1 | G27: =IF(D27="","",IF(D27=0,"-",IF(F27>D27,"ERROR",IF(E27>D27,"ERROR",IF(E27<D27,0,IF(E27>F27,0,IF(F27=D27,1,0))))))) -> 1 | P27: OPERADORA LECHERIA 2011, C.A
A28: 13 | B28: MODEM | D28: 0 | E28: 1 | F28: 1 | G28: =IF(D28="","",IF(D28=0,"-",IF(F28>D28,"ERROR",IF(E28>D28,"ERROR",IF(E28<D28,0,IF(E28>F28,0,IF(F28=D28,1,0))))))) -> -
A29: 14 | B29: LIBROS DE IMPRESORAS FISCALES | D29: 2 | E29: 2 | F29: 2 | G29: =IF(D29="","",IF(D29=0,"-",IF(F29>D29,"ERROR",IF(E29>D29,"ERROR",IF(E29<D29,0,IF(E29>F29,0,IF(F29=D29,1,0))))))) -> 1
A30: TOTAL DE EFECTIVIDAD DE EQUIPOS | G30: =IFERROR(AVERAGE(G9:G28),"-") -> 1
A32: Realizado Por:
A33: Cargo
A35: NOTA: El check list de Existencia de Equipos en Tiendas debe ser enviado entre los 5 primeros días del mes, vía correo electrónico al grupo Sistemas, con copia al Director de Servicios de Control.
L39: HOUSE TICKET | M39: INVENTARIO | N39: CABLEADO | O39: MES
K40: TIENDAS | L40: SI | M40: 0 | N40: SI | O40: ENERO
K41: =IF(MAESTRO!A1="","",MAESTRO!A1) -> ******SUCURSALES | L41: NO | M41: 1 | N41: NO | O41: FEBRERO
K42: =IF(MAESTRO!A2="","",MAESTRO!A2) -> LA CASA DE LA CAÑA, C.A. (T. ALTERNA) | M42: 2 | O42: MARZO
K43: =IF(MAESTRO!A3="","",MAESTRO!A3) -> LA CASA DE LA CAÑA, C.A. (T. ANACO) | M43: 3 | O43: ABRIL
K44: =IF(MAESTRO!A4="","",MAESTRO!A4) -> LA CASA DE LA CAÑA, C.A. (T. CUMANÁ) | M44: 4 | O44: MAYO
K45: =IF(MAESTRO!A5="","",MAESTRO!A5) -> LA CASA DE LA CAÑA, C.A. (T. MATURÍN I) | M45: 5 | O45: JUNIO
...

Sheet GUATIRE C
C1: CHECK LIST DE EXISTENCIA DE EQUIPOS EN TIENDAS | I1: Código: | J1: FO-MIS-03 | L1: Operadora Lecheria 2025, C.A San Bernandino
I2: Revisión: | J2: 07 | K2: 42720 | L2: Operadora Lecheria 2025, C.A Drop Shop El Paraiso
I3: Fecha: | J3: 42286 | L3: Operadora Lecheria 2025, C.A El Paraiso
L4: Operadora Lecheria 2025, C.A Presidente Medina
B5: SUCURSAL: | C5: Operadora Lecheria 2025, C.A Guatire Centro | H5: FECHA: | I5: 46157 | L5: Operadora Lecheria 2025, C.A Los Flores
L6: Operadora Lecheria 2025, C.A San Antonio
A7: EQUIPOS | L7: Operadora Lecheria 2025, C.A CCCT
A8: Nº | B8: EQUIPOS | D8: INVENTARIO IDEAL | E8: INVENTARIO REAL | F8: EQUIPOS OPERATIVOS | G8: EFECTIVIDAD | H8: OBSERVACIONES | L8: Operadora Lecheria 2025, C.A Guarenas Centro
A9: 1 | B9: CPU | D9: 2 | E9: 2 | F9: 2 | G9: =IF(D9="","",IF(D9=0,"-",IF(F9>D9,"ERROR",IF(E9>D9,"ERROR",IF(E9<D9,0,IF(E9>F9,0,IF(F9=D9,1,0))))))) -> 1 | L9: Operadora Lecheria 2025, C.A Guarenas 27 De Febrero | Q9: LA CASA DE LA CAÑA, C.A. (T. ALTERNA)
